Workbook
Name 收支类别: 资金账户!$K$3:$W$3

Sheet 档案
A1: 表号 | B1: 资金户名 | C1: 公司名称 | E1: 首行 | F1: 行数 | G1: 余额
A2: 1 | B2: 华夏银行汉正街支行186346 | C2: 武汉开明 | E2: =IF(F2=0,MATCH(单日流水!$G$2,INDIRECT("'"&A2&"'!A:A"),1),MATCH(单日流水!$G$2,INDIRECT("'"&A2&"'!A:A"),0)-1) -> 1 | F2: =COUNTIF(INDIRECT("'"&A2&"'!A:A"),单日流水!$G$2) -> 0 | G2: {=INDEX(INDIRECT("'"&A2&"'!f:f"),E2,1)} -> 0
A3: 2 | B3: 浦发银行光谷支行004954 | C3: 武汉开明 | E3: =IF(F3=0,MATCH(单日流水!$G$2,INDIRECT("'"&A3&"'!A:A"),1),MATCH(单日流水!$G$2,INDIRECT("'"&A3&"'!A:A"),0)-1) -> #N/A | F3: =COUNTIF(INDIRECT("'"&A3&"'!A:A"),单日流水!$G$2) -> 0 | G3: {=INDEX(INDIRECT("'"&A3&"'!f:f"),E3,1)} -> #N/A
A4: 3 | B4: 汉口梅苑支行149501 | C4: 武汉开明 | E4: =IF(F4=0,MATCH(单日流水!$G$2,INDIRECT("'"&A4&"'!A:A"),1),MATCH(单日流水!$G$2,INDIRECT("'"&A4&"'!A:A"),0)-1) -> 1 | F4: =COUNTIF(INDIRECT("'"&A4&"'!A:A"),单日流水!$G$2) -> 0 | G4: {=INDEX(INDIRECT("'"&A4&"'!f:f"),E4,1)} -> 0
A5: 4 | B5: 光大洪山支行97500 | C5: 武汉开明 | E5: =IF(F5=0,MATCH(单日流水!$G$2,INDIRECT("'"&A5&"'!A:A"),1),MATCH(单日流水!$G$2,INDIRECT("'"&A5&"'!A:A"),0)-1) -> 1 | F5: =COUNTIF(INDIRECT("'"&A5&"'!A:A"),单日流水!$G$2) -> 0 | G5: {=INDEX(INDIRECT("'"&A5&"'!f:f"),E5,1)} -> 0
A6: 5 | B6: 建设豪威银行500746（扣ETC) | C6: 武汉开明 | E6: =IF(F6=0,MATCH(单日流水!$G$2,INDIRECT("'"&A6&"'!A:A"),1),MATCH(单日流水!$G$2,INDIRECT("'"&A6&"'!A:A"),0)-1) -> 1 | F6: =COUNTIF(INDIRECT("'"&A6&"'!A:A"),单日流水!$G$2) -> 0 | G6: {=INDEX(INDIRECT("'"&A6&"'!f:f"),E6,1)} -> 0
A7: 6 | B7: 交通银行洪山支行4632877 | C7: 武汉开明 | E7: =IF(F7=0,MATCH(单日流水!$G$2,INDIRECT("'"&A7&"'!A:A"),1),MATCH(单日流水!$G$2,INDIRECT("'"&A7&"'!A:A"),0)-1) -> 1 | F7: =COUNTIF(INDIRECT("'"&A7&"'!A:A"),单日流水!$G$2) -> 0 | G7: {=INDEX(INDIRECT("'"&A7&"'!f:f"),E7,1)} -> 0
A8: 7 | B8: 邮政储蓄凤凰支行096669 | C8: 武汉开明 | E8: =IF(F8=0,MATCH(单日流水!$G$2,INDIRECT("'"&A8&"'!A:A"),1),MATCH(单日流水!$G$2,INDIRECT("'"&A8&"'!A:A"),0)-1) -> 1 | F8: =COUNTIF(INDIRECT("'"&A8&"'!A:A"),单日流水!$G$2) -> 0 | G8: {=INDEX(INDIRECT("'"&A8&"'!f:f"),E8,1)} -> 0
A9: 8 | B9: 宁波银行余姚支行营业部825161 | C9: 武汉开明 | E9: =IF(F9=0,MATCH(单日流水!$G$2,INDIRECT("'"&A9&"'!A:A"),1),MATCH(单日流水!$G$2,INDIRECT("'"&A9&"'!A:A"),0)-1) -> #N/A | F9: =COUNTIF(INDIRECT("'"&A9&"'!A:A"),单日流水!$G$2) -> 0 | G9: {=INDEX(INDIRECT("'"&A9&"'!f:f"),E9,1)} -> #N/A
A10: 9 | B10: 农商行豹澥支行310028 | C10: 武汉开明 | E10: =IF(F10=0,MATCH(单日流水!$G$2,INDIRECT("'"&A10&"'!A:A"),1),MATCH(单日流水!$G$2,INDIRECT("'"&A10&"'!A:A"),0)-1) -> 1 | F10: =COUNTIF(INDIRECT("'"&A10&"'!A:A"),单日流水!$G$2) -> 0 | G10: {=INDEX(INDIRECT("'"&A10&"'!f:f"),E10,1)} -> 0
A11: 10 | B11: 工行武汉瀚城支行004604 | C11: 武汉开明 | E11: =IF(F11=0,MATCH(单日流水!$G$2,INDIRECT("'"&A11&"'!A:A"),1),MATCH(单日流水!$G$2,INDIRECT("'"&A11&"'!A:A"),0)-1) -> 1 | F11: =COUNTIF(INDIRECT("'"&A11&"'!A:A"),单日流水!$G$2) -> 0 | G11: {=INDEX(INDIRECT("'"&A11&"'!f:f"),E11,1)} -> 0
A12: 11 | B12: 青海农商行农民工工资保证金954442 | C12: 武汉开明 | E12: =IF(F12=0,MATCH(单日流水!$G$2,INDIRECT("'"&A12&"'!A:A"),1),MATCH(单日流水!$G$2,INDIRECT("'"&A12&"'!A:A"),0)-1) -> #N/A | F12: =COUNTIF(INDIRECT("'"&A12&"'!A:A"),单日流水!$G$2) -> 0 | G12: {=INDEX(INDIRECT("'"&A12&"'!f:f"),E12,1)} -> #N/A
A13: 12 | B13: 中国银行鹦鹉大道支行 | C13: 武汉开明 | E13: =IF(F13=0,MATCH(单日流水!$G$2,INDIRECT("'"&A13&"'!A:A"),1),MATCH(单日流水!$G$2,INDIRECT("'"&A13&"'!A:A"),0)-1) -> #N/A | F13: =COUNTIF(INDIRECT("'"&A13&"'!A:A"),单日流水!$G$2) -> 0 | G13: {=INDEX(INDIRECT("'"&A13&"'!f:f"),E13,1)} -> #N/A
... A22: 21 | B22: 汉口银行光谷分行454891 | C22: 武汉彤烨 | E22: =IF(F22=0,MATCH(单日流水!$G$2,INDIRECT("'"&A22&"'!A:A"),1),MATCH(单日流水!$G$2,INDIRECT("'"&A22&"'!A:A"),0)-1) -> 1 | F22: =COUNTIF(INDIRECT("'"&A22&"'!A:A"),单日流水!$G$2) -> 0 | G22: {=INDEX(INDIRECT("'"&A22&"'!f:f"),E22,1)} -> 0
A23: 22 | C23: 武汉彤烨 | E23: =IF(F23=0,MATCH(单日流水!$G$2,INDIRECT("'"&A23&"'!A:A"),1),MATCH(单日流水!$G$2,INDIRECT("'"&A23&"'!A:A"),0)-1) -> 3 | F23: =COUNTIF(INDIRECT("'"&A23&"'!A:A"),单日流水!$G$2) -> 0 | G23: {=INDEX(INDIRECT("'"&A23&"'!f:f"),E23,1)} -> 0
A24: 23 | C24: 武汉彤烨 | E24: =IF(F24=0,MATCH(单日流水!$G$2,INDIRECT("'"&A24&"'!A:A"),1),MATCH(单日流水!$G$2,INDIRECT("'"&A24&"'!A:A"),0)-1) -> 3 | F24: =COUNTIF(INDIRECT("'"&A24&"'!A:A"),单日流水!$G$2) -> 0 | G24: {=INDEX(INDIRECT("'"&A24&"'!f:f"),E24,1)} -> 0
A25: 24 | C25: 武汉彤烨 | E25: =IF(F25=0,MATCH(单日流水!$G$2,INDIRECT("'"&A25&"'!A:A"),1),MATCH(单日流水!$G$2,INDIRECT("'"&A25&"'!A:A"),0)-1) -> 3 | F25: =COUNTIF(INDIRECT("'"&A25&"'!A:A"),单日流水!$G$2) -> 0 | G25: {=INDEX(INDIRECT("'"&A25&"'!f:f"),E25,1)} -> 0
A26: 25 | B26: 电子承兑汇票 | C26: 武汉彤烨 | E26: =IF(F26=0,MATCH(单日流水!$G$2,INDIRECT("'"&A26&"'!A:A"),1),MATCH(单日流水!$G$2,INDIRECT("'"&A26&"'!A:A"),0)-1) -> 1 | F26: =COUNTIF(INDIRECT("'"&A26&"'!A:A"),单日流水!$G$2) -> 0 | G26: {=INDEX(INDIRECT("'"&A26&"'!f:f"),E26,1)} -> 0
A27: 26 | B27: 库存现金 | C27: 武汉彤烨 | E27: =IF(F27=0,MATCH(单日流水!$G$2,INDIRECT("'"&A27&"'!A:A"),1),MATCH(单日流水!$G$2,INDIRECT("'"&A27&"'!A:A"),0)-1) -> 3 | F27: =COUNTIF(INDIRECT("'"&A27&"'!A:A"),单日流水!$G$2) -> 0 | G27: {=INDEX(INDIRECT("'"&A27&"'!f:f"),E27,1)} -> 0
A28: 27 | B28: 邮政凤凰路支行 | C28: 湖北开明 | E28: =IF(F28=0,MATCH(单日流水!$G$2,INDIRECT("'"&A28&"'!A:A"),1),MATCH(单日流水!$G$2,INDIRECT("'"&A28&"'!A:A"),0)-1) -> 1 | F28: =COUNTIF(INDIRECT("'"&A28&"'!A:A"),单日流水!$G$2) -> 0 | G28: {=INDEX(INDIRECT("'"&A28&"'!f:f"),E28,1)} -> 0
A29: 28 | B29: 农商行开发区支行604928 | C29: 湖北开明 | E29: =IF(F29=0,MATCH(单日流水!$G$2,INDIRECT("'"&A29&"'!A:A"),1),MATCH(单日流水!$G$2,INDIRECT("'"&A29&"'!A:A"),0)-1) -> 1 | F29: =COUNTIF(INDIRECT("'"&A29&"'!A:A"),单日流水!$G$2) -> 0 | G29: {=INDEX(INDIRECT("'"&A29&"'!f:f"),E29,1)} -> 0
A30: 29 | B30: 工行西山支行004096 | C30: 湖北开明 | E30: =IF(F30=0,MATCH(单日流水!$G$2,INDIRECT("'"&A30&"'!A:A"),1),MATCH(单日流水!$G$2,INDIRECT("'"&A30&"'!A:A"),0)-1) -> 1 | F30: =COUNTIF(INDIRECT("'"&A30&"'!A:A"),单日流水!$G$2) -> 0 | G30: {=INDEX(INDIRECT("'"&A30&"'!f:f"),E30,1)} -> 0
A31: 30 | B31: 工行虹桥支行54786 | C31: 湖北开明 | E31: =IF(F31=0,MATCH(单日流水!$G$2,INDIRECT("'"&A31&"'!A:A"),1),MATCH(单日流水!$G$2,INDIRECT("'"&A31&"'!A:A"),0)-1) -> 1 | F31: =COUNTIF(INDIRECT("'"&A31&"'!A:A"),单日流水!$G$2) -> 0 | G31: {=INDEX(INDIRECT("'"&A31&"'!f:f"),E31,1)} -> 0
A32: 31 | B32: 中国银行鄂州分行0592794 | C32: 湖北开明 | E32: =IF(F32=0,MATCH(单日流水!$G$2,INDIRECT("'"&A32&"'!A:A"),1),MATCH(单日流水!$G$2,INDIRECT("'"&A32&"'!A:A"),0)-1) -> 1 | F32: =COUNTIF(INDIRECT("'"&A32&"'!A:A"),单日流水!$G$2) -> 0 | G32: {=INDEX(INDIRECT("'"&A32&"'!f:f"),E32,1)} -> 0
A33: 32 | C33: 湖北开明 | E33: =IF(F33=0,MATCH(单日流水!$G$2,INDIRECT("'"&A33&"'!A:A"),1),MATCH(单日流水!$G$2,INDIRECT("'"&A33&"'!A:A"),0)-1) -> 3 | F33: =COUNTIF(INDIRECT("'"&A33&"'!A:A"),单日流水!$G$2) -> 0 | G33: {=INDEX(INDIRECT("'"&A33&"'!f:f"),E33,1)} -> 0
A34: 33 | C34: 湖北开明 | E34: =IF(F34=0,MATCH(单日流水!$G$2,INDIRECT("'"&A34&"'!A:A"),1),MATCH(单日流水!$G$2,INDIRECT("'"&A34&"'!A:A"),0)-1) -> 3 | F34: =COUNTIF(INDIRECT("'"&A34&"'!A:A"),单日流水!$G$2) -> 0 | G34: {=INDEX(INDIRECT("'"&A34&"'!f:f"),E34,1)} -> 0
A35: 34 | C35: 湖北开明 | E35: =IF(F35=0,MATCH(单日流水!$G$2,INDIRECT("'"&A35&"'!A:A"),1),MATCH(单日流水!$G$2,INDIRECT("'"&A35&"'!A:A"),0)-1) -> 3 | F35: =COUNTIF(INDIRECT("'"&A35&"'!A:A"),单日流水!$G$2) -> 0 | G35: {=INDEX(INDIRECT("'"&A35&"'!f:f"),E35,1)} -> 0
A36: 35 | C36: 湖北开明 | E36: =IF(F36=0,MATCH(单日流水!$G$2,INDIRECT("'"&A36&"'!A:A"),1),MATCH(单日流水!$G$2,INDIRECT("'"&A36&"'!A:A"),0)-1) -> 3 | F36: =COUNTIF(INDIRECT("'"&A36&"'!A:A"),单日流水!$G$2) -> 0 | G36: {=INDEX(INDIRECT("'"&A36&"'!f:f"),E36,1)} -> 0
A37: 36 | B37: 电子承兑汇票 | C37: 湖北开明 | E37: =IF(F37=0,MATCH(单日流水!$G$2,INDIRECT("'"&A37&"'!A:A"),1),MATCH(单日流水!$G$2,INDIRECT("'"&A37&"'!A:A"),0)-1) -> 1 | F37: =COUNTIF(INDIRECT("'"&A37&"'!A:A"),单日流水!$G$2) -> 0 | G37: {=INDEX(INDIRECT("'"&A37&"'!f:f"),E37,1)} -> 0
A38: 37 | B38: 库存现金 | C38: 湖北开明 | E38: =IF(F38=0,MATCH(单日流水!$G$2,INDIRECT("'"&A38&"'!A:A"),1),MATCH(单日流水!$G$2,INDIRECT("'"&A38&"'!A:A"),0)-1) -> 3 | F38: =COUNTIF(INDIRECT("'"&A38&"'!A:A"),单日流水!$G$2) -> 0 | G38: {=INDEX(INDIRECT("'"&A38&"'!f:f"),E38,1)} -> 0
A39: 38 | B39: 浦发银行光谷支行01894 | C39: 武汉信茂 | E39: =IF(F39=0,MATCH(单日流水!$G$2,INDIRECT("'"&A39&"'!A:A"),1),MATCH(单日流水!$G$2,INDIRECT("'"&A39&"'!A:A"),0)-1) -> 1 | F39: =COUNTIF(INDIRECT("'"&A39&"'!A:A"),单日流水!$G$2) -> 0 | G39: {=INDEX(INDIRECT("'"&A39&"'!f:f"),E39,1)} -> 0
A40: 39 | C40: 武汉信茂 | E40: =IF(F40=0,MATCH(单日流水!$G$2,INDIRECT("'"&A40&"'!A:A"),1),MATCH(单日流水!$G$2,INDIRECT("'"&A40&"'!A:A"),0)-1) -> 3 | F40: =COUNTIF(INDIRECT("'"&A40&"'!A:A"),单日流水!$G$2) -> 0 | G40: {=INDEX(INDIRECT("'"&A40&"'!f:f"),E40,1)} -> 0
A41: 40 | C41: 武汉信茂 | E41: =IF(F41=0,MATCH(单日流水!$G$2,INDIRECT("'"&A41&"'!A:A"),1),MATCH(单日流水!$G$2,INDIRECT("'"&A41&"'!A:A"),0)-1) -> 3 | F41: =COUNTIF(INDIRECT("'"&A41&"'!A:A"),单日流水!$G$2) -> 0 | G41: {=INDEX(INDIRECT("'"&A41&"'!f:f"),E41,1)} -> 0
A42: 41 | C42: 武汉信茂 | E42: =IF(F42=0,MATCH(单日流水!$G$2,INDIRECT("'"&A42&"'!A:A"),1),MATCH(单日流水!$G$2,INDIRECT("'"&A42&"'!A:A"),0)-1) -> 3 | F42: =COUNTIF(INDIRECT("'"&A42&"'!A:A"),单日流水!$G$2) -> 0 | G42: {=INDEX(INDIRECT("'"&A42&"'!f:f"),E42,1)} -> 0
A43: 42 | B43: 电子承兑汇票 | C43: 武汉信茂 | E43: =IF(F43=0,MATCH(单日流水!$G$2,INDIRECT("'"&A43&"'!A:A"),1),MATCH(单日流水!$G$2,INDIRECT("'"&A43&"'!A:A"),0)-1) -> 1 | F43: =COUNTIF(INDIRECT("'"&A43&"'!A:A"),单日流水!$G$2) -> 0 | G43: {=INDEX(INDIRECT("'"&A43&"'!f:f"),E43,1)} -> 0
A44: 43 | B44: 库存现金 | C44: 武汉信茂 | E44: =IF(F44=0,MATCH(单日流水!$G$2,INDIRECT("'"&A44&"'!A:A"),1),MATCH(单日流水!$G$2,INDIRECT("'"&A44&"'!A:A"),0)-1) -> 3 | F44: =COUNTIF(INDIRECT("'"&A44&"'!A:A"),单日流水!$G$2) -> 0 | G44: {=INDEX(INDIRECT("'"&A44&"'!f:f"),E44,1)} -> 0
A45: 44 | B45: 王先梅 邮储银行4262 | C45: 个体户 | E45: =IF(F45=0,MATCH(单日流水!$G$2,INDIRECT("'"&A45&"'!A:A"),1),MATCH(单日流水!$G$2,INDIRECT("'"&A45&"'!A:A"),0)-1) -> 1 | F45: =COUNTIF(INDIRECT("'"&A45&"'!A:A"),单日流水!$G$2) -> 0 | G45: {=INDEX(INDIRECT("'"&A45&"'!f:f"),E45,1)} -> 0
A46: 45 | B46: 林家祥 邮储银行7677 | C46: 个体户 | E46: =IF(F46=0,MATCH(单日流水!$G$2,INDIRECT("'"&A46&"'!A:A"),1),MATCH(单日流水!$G$2,INDIRECT("'"&A46&"'!A:A"),0)-1) -> 1 | F46: =COUNTIF(INDIRECT("'"&A46&"'!A:A"),单日流水!$G$2) -> 0 | G46: {=INDEX(INDIRECT("'"&A46&"'!f:f"),E46,1)} -> 0
A47: 46 | B47: 湖北岚丹农民工发放账户01679 | C47: 湖北岚丹 | E47: =IF(F47=0,MATCH(单日流水!$G$2,INDIRECT("'"&A47&"'!A:A"),1),MATCH(单日流水!$G$2,INDIRECT("'"&A47&"'!A:A"),0)-1) -> 1 | F47: =COUNTIF(INDIRECT("'"&A47&"'!A:A"),单日流水!$G$2) -> 0 | G47: {=INDEX(INDIRECT("'"&A47&"'!f:f"),E47,1)} -> 0
A48: 47 | B48: 岚丹电子承兑汇票 | C48: 湖北岚丹 | E48: =IF(F48=0,MATCH(单日流水!$G$2,INDIRECT("'"&A48&"'!A:A"),1),MATCH(单日流水!$G$2,INDIRECT("'"&A48&"'!A:A"),0)-1) -> 1 | F48: =COUNTIF(INDIRECT("'"&A48&"'!A:A"),单日流水!$G$2) -> 0 | G48: {=INDEX(INDIRECT("'"&A48&"'!f:f"),E48,1)} -> 0
...

Sheet 资金账户
F1: 资金账户明细表
E2: 报告日期： | F2: 45980 | J2: 单位：元
A3: 首行 | B3: 行数 | D3: 项目 | F3: 资金户名 | G3: 昨日余额 | H3: 收款小计 | I3: 付款小计 | J3: 本日余额 | K3: 营业回款 | L3: 投标保证金回款 | M3: 借款到账 | N3: 其他收款 | O3: 他行转入或存现 | P3: 付货款 | Q3: 付投标保证金 | R3: 付日常费用 | S3: 还借款及利息 | T3: 其他付款 | U3: 转出他行或提现 | V3: 项目成本 | W3: 外协成本
A4: =IF(B4=0,MATCH($F$2,INDIRECT("'"&C4&"'!A:A"),1),MATCH($F$2,INDIRECT("'"&C4&"'!A:A"),0)) -> 158 | B4: =COUNTIF(INDIRECT("'"&C4&"'!A:A"),$F$2) -> 2 | C4: 1 | D4: 武汉开明 | E4: 银行存款 | F4: =VLOOKUP(C4,档案!A:B,2,FALSE) -> 华夏银行汉正街支行186346 | G4: =IF(B4=0,INDEX(INDIRECT("'"&$C4&"'!$F:$F"),$A4,1),INDEX(INDIRECT("'"&$C4&"'!$F:$F"),$A4-1,1)) -> 20039.02 | H4: =SUM(K4:O4) -> 0 | I4: =SUM(P4:W4) -> 3.5 | J4: =G4+H4-I4 -> 20035.52 | K4: =SUMIFS(INDIRECT("'"&$C4&"'!$D:$D"),INDIRECT("'"&$C4&"'!$C:$C"),K$3,INDIRECT("'"&$C4&"'!$A:$A"),$F$2) -> 0 | L4: =SUMIFS(INDIRECT("'"&$C4&"'!$D:$D"),INDIRECT("'"&$C4&"'!$C:$C"),L$3,INDIRECT("'"&$C4&"'!$A:$A"),$F$2) -> 0 | M4: =SUMIFS(INDIRECT("'"&$C4&"'!$D:$D"),INDIRECT("'"&$C4&"'!$C:$C"),M$3,INDIRECT("'"&$C4&"'!$A:$A"),$F$2) -> 0 | N4: =SUMIFS(INDIRECT("'"&$C4&"'!$D:$D"),INDIRECT("'"&$C4&"'!$C:$C"),N$3,INDIRECT("'"&$C4&"'!$A:$A"),$F$2) -> 0 | O4: =SUMIFS(INDIRECT("'"&$C4&"'!$D:$D"),INDIRECT("'"&$C4&"'!$C:$C"),O$3,INDIRECT("'"&$C4&"'!$A:$A"),$F$2) -> 0 | P4: =SUMIFS(INDIRECT("'"&$C4&"'!$e:$e"),INDIRECT("'"&$C4&"'!$C:$C"),P$3,INDIRECT("'"&$C4&"'!$A:$A"),$F$2) -> 0 | Q4: =SUMIFS(INDIRECT("'"&$C4&"'!$e:$e"),INDIRECT("'"&$C4&"'!$C:$C"),Q$3,INDIRECT("'"&$C4&"'!$A:$A"),$F$2) -> 0 | R4: =SUMIFS(INDIRECT("'"&$C4&"'!$e:$e"),INDIRECT("'"&$C4&"'!$C:$C"),R$3,INDIRECT("'"&$C4&"'!$A:$A"),$F$2) -> 1.5 | S4: =SUMIFS(INDIRECT("'"&$C4&"'!$e:$e"),INDIRECT("'"&$C4&"'!$C:$C"),S$3,INDIRECT("'"&$C4&"'!$A:$A"),$F$2) -> 0 | T4: =SUMIFS(INDIRECT("'"&$C4&"'!$e:$e"),INDIRECT("'"&$C4&"'!$C:$C"),T$3,INDIRECT("'"&$C4&"'!$A:$A"),$F$2) -> 0 | U4: =SUMIFS(INDIRECT("'"&$C4&"'!$e:$e"),INDIRECT("'"&$C4&"'!$C:$C"),U$3,INDIRECT("'"&$C4&"'!$A:$A"),$F$2) -> 2 | V4: =SUMIFS(INDIRECT("'"&$C4&"'!$e:$e"),INDIRECT("'"&$C4&"'!$C:$C"),V$3,INDIRECT("'"&$C4&"'!$A:$A"),$F$2) -> 0 | W4: =SUMIFS(INDIRECT("'"&$C4&"'!$e:$e"),INDIRECT("'"&$C4&"'!$C:$C"),W$3,INDIRECT("'"&$C4&"'!$A:$A"),$F$2) -> 0
A5: =IF(B5=0,MATCH($F$2,INDIRECT("'"&C5&"'!A:A"),1),MATCH($F$2,INDIRECT("'"&C5&"'!A:A"),0)) -> 741 | B5: =COUNTIF(INDIRECT("'"&C5&"'!A:A"),$F$2) -> 1 | C5: 2 | F5: =VLOOKUP(C5,档案!A:B,2,FALSE) -> 浦发银行光谷支行004954 | G5: =IF(B5=0,INDEX(INDIRECT("'"&$C5&"'!$F:$F"),$A5,1),INDEX(INDIRECT("'"&$C5&"'!$F:$F"),$A5-1,1)) -> 67375.91 | H5: =SUM(K5:O5) -> 40000 | I5: =SUM(P5:W5) -> 0 | J5: =G5+H5-I5 -> 107375.91 | K5: =SUMIFS(INDIRECT("'"&$C5&"'!$D:$D"),INDIRECT("'"&$C5&"'!$C:$C"),K$3,INDIRECT("'"&$C5&"'!$A:$A"),$F$2) -> 0 | L5: =SUMIFS(INDIRECT("'"&$C5&"'!$D:$D"),INDIRECT("'"&$C5&"'!$C:$C"),L$3,INDIRECT("'"&$C5&"'!$A:$A"),$F$2) -> 0 | M5: =SUMIFS(INDIRECT("'"&$C5&"'!$D:$D"),INDIRECT("'"&$C5&"'!$C:$C"),M$3,INDIRECT("'"&$C5&"'!$A:$A"),$F$2) -> 0 | N5: =SUMIFS(INDIRECT("'"&$C5&"'!$D:$D"),INDIRECT("'"&$C5&"'!$C:$C"),N$3,INDIRECT("'"&$C5&"'!$A:$A"),$F$2) -> 40000 | O5: =SUMIFS(INDIRECT("'"&$C5&"'!$D:$D"),INDIRECT("'"&$C5&"'!$C:$C"),O$3,INDIRECT("'"&$C5&"'!$A:$A"),$F$2) -> 0 | P5: =SUMIFS(INDIRECT("'"&$C5&"'!$e:$e"),INDIRECT("'"&$C5&"'!$C:$C"),P$3,INDIRECT("'"&$C5&"'!$A:$A"),$F$2) -> 0 | Q5: =SUMIFS(INDIRECT("'"&$C5&"'!$e:$e"),INDIRECT("'"&$C5&"'!$C:$C"),Q$3,INDIRECT("'"&$C5&"'!$A:$A"),$F$2) -> 0 | R5: =SUMIFS(INDIRECT("'"&$C5&"'!$e:$e"),INDIRECT("'"&$C5&"'!$C:$C"),R$3,INDIRECT("'"&$C5&"'!$A:$A"),$F$2) -> 0 | S5: =SUMIFS(INDIRECT("'"&$C5&"'!$e:$e"),INDIRECT("'"&$C5&"'!$C:$C"),S$3,INDIRECT("'"&$C5&"'!$A:$A"),$F$2) -> 0 | T5: =SUMIFS(INDIRECT("'"&$C5&"'!$e:$e"),INDIRECT("'"&$C5&"'!$C:$C"),T$3,INDIRECT("'"&$C5&"'!$A:$A"),$F$2) -> 0 | U5: =SUMIFS(INDIRECT("'"&$C5&"'!$e:$e"),INDIRECT("'"&$C5&"'!$C:$C"),U$3,INDIRECT("'"&$C5&"'!$A:$A"),$F$2) -> 0 | V5: =SUMIFS(INDIRECT("'"&$C5&"'!$e:$e"),INDIRECT("'"&$C5&"'!$C:$C"),V$3,INDIRECT("'"&$C5&"'!$A:$A"),$F$2) -> 0 | W5: =SUMIFS(INDIRECT("'"&$C5&"'!$e:$e"),INDIRECT("'"&$C5&"'!$C:$C"),W$3,INDIRECT("'"&$C5&"'!$A:$A"),$F$2) -> 0
A6: =IF(B6=0,MATCH($F$2,INDIRECT("'"&C6&"'!A:A"),1),MATCH($F$2,INDIRECT("'"&C6&"'!A:A"),0)) -> 39 | B6: =COUNTIF(INDIRECT("'"&C6&"'!A:A"),$F$2) -> 0 | C6: 3 | F6: =VLOOKUP(C6,档案!A:B,2,FALSE) -> 汉口梅苑支行149501 | G6: =IF(B6=0,INDEX(INDIRECT("'"&$C6&"'!$F:$F"),$A6,1),INDEX(INDIRECT("'"&$C6&"'!$F:$F"),$A6-1,1)) -> 9043.78 | H6: =SUM(K6:O6) -> 0 | I6: =SUM(P6:W6) -> 0 | J6: =G6+H6-I6 -> 9043.78 | K6: =SUMIFS(INDIRECT("'"&$C6&"'!$D:$D"),INDIRECT("'"&$C6&"'!$C:$C"),K$3,INDIRECT("'"&$C6&"'!$A:$A"),$F$2) -> 0 | L6: =SUMIFS(INDIRECT("'"&$C6&"'!$D:$D"),INDIRECT("'"&$C6&"'!$C:$C"),L$3,INDIRECT("'"&$C6&"'!$A:$A"),$F$2) -> 0 | M6: =SUMIFS(INDIRECT("'"&$C6&"'!$D:$D"),INDIRECT("'"&$C6&"'!$C:$C"),M$3,INDIRECT("'"&$C6&"'!$A:$A"),$F$2) -> 0 | N6: =SUMIFS(INDIRECT("'"&$C6&"'!$D:$D"),INDIRECT("'"&$C6&"'!$C:$C"),N$3,INDIRECT("'"&$C6&"'!$A:$A"),$F$2) -> 0 | O6: =SUMIFS(INDIRECT("'"&$C6&"'!$D:$D"),INDIRECT("'"&$C6&"'!$C:$C"),O$3,INDIRECT("'"&$C6&"'!$A:$A"),$F$2) -> 0 | P6: =SUMIFS(INDIRECT("'"&$C6&"'!$e:$e"),INDIRECT("'"&$C6&"'!$C:$C"),P$3,INDIRECT("'"&$C6&"'!$A:$A"),$F$2) -> 0 | Q6: =SUMIFS(INDIRECT("'"&$C6&"'!$e:$e"),INDIRECT("'"&$C6&"'!$C:$C"),Q$3,INDIRECT("'"&$C6&"'!$A:$A"),$F$2) -> 0 | R6: =SUMIFS(INDIRECT("'"&$C6&"'!$e:$e"),INDIRECT("'"&$C6&"'!$C:$C"),R$3,INDIRECT("'"&$C6&"'!$A:$A"),$F$2) -> 0 | S6: =SUMIFS(INDIRECT("'"&$C6&"'!$e:$e"),INDIRECT("'"&$C6&"'!$C:$C"),S$3,INDIRECT("'"&$C6&"'!$A:$A"),$F$2) -> 0 | T6: =SUMIFS(INDIRECT("'"&$C6&"'!$e:$e"),INDIRECT("'"&$C6&"'!$C:$C"),T$3,INDIRECT("'"&$C6&"'!$A:$A"),$F$2) -> 0 | U6: =SUMIFS(INDIRECT("'"&$C6&"'!$e:$e"),INDIRECT("'"&$C6&"'!$C:$C"),U$3,INDIRECT("'"&$C6&"'!$A:$A"),$F$2) -> 0 | V6: =SUMIFS(INDIRECT("'"&$C6&"'!$e:$e"),INDIRECT("'"&$C6&"'!$C:$C"),V$3,INDIRECT("'"&$C6&"'!$A:$A"),$F$2) -> 0 | W6: =SUMIFS(INDIRECT("'"&$C6&"'!$e:$e"),INDIRECT("'"&$C6&"'!$C:$C"),W$3,INDIRECT("'"&$C6&"'!$A:$A"),$F$2) -> 0
A7: =IF(B7=0,MATCH($F$2,INDIRECT("'"&C7&"'!A:A"),1),MATCH($F$2,INDIRECT("'"&C7&"'!A:A"),0)) -> 44 | B7: =COUNTIF(INDIRECT("'"&C7&"'!A:A"),$F$2) -> 0 | C7: 4 | F7: =VLOOKUP(C7,档案!A:B,2,FALSE) -> 光大洪山支行97500 | G7: =IF(B7=0,INDEX(INDIRECT("'"&$C7&"'!$F:$F"),$A7,1),INDEX(INDIRECT("'"&$C7&"'!$F:$F"),$A7-1,1)) -> 3475.81 | H7: =SUM(K7:O7) -> 0 | I7: =SUM(P7:W7) -> 0 | J7: =G7+H7-I7 -> 3475.81 | K7: =SUMIFS(INDIRECT("'"&$C7&"'!$D:$D"),INDIRECT("'"&$C7&"'!$C:$C"),K$3,INDIRECT("'"&$C7&"'!$A:$A"),$F$2) -> 0 | L7: =SUMIFS(INDIRECT("'"&$C7&"'!$D:$D"),INDIRECT("'"&$C7&"'!$C:$C"),L$3,INDIRECT("'"&$C7&"'!$A:$A"),$F$2) -> 0 | M7: =SUMIFS(INDIRECT("'"&$C7&"'!$D:$D"),INDIRECT("'"&$C7&"'!$C:$C"),M$3,INDIRECT("'"&$C7&"'!$A:$A"),$F$2) -> 0 | N7: =SUMIFS(INDIRECT("'"&$C7&"'!$D:$D"),INDIRECT("'"&$C7&"'!$C:$C"),N$3,INDIRECT("'"&$C7&"'!$A:$A"),$F$2) -> 0 | O7: =SUMIFS(INDIRECT("'"&$C7&"'!$D:$D"),INDIRECT("'"&$C7&"'!$C:$C"),O$3,INDIRECT("'"&$C7&"'!$A:$A"),$F$2) -> 0 | P7: =SUMIFS(INDIRECT("'"&$C7&"'!$e:$e"),INDIRECT("'"&$C7&"'!$C:$C"),P$3,INDIRECT("'"&$C7&"'!$A:$A"),$F$2) -> 0 | Q7: =SUMIFS(INDIRECT("'"&$C7&"'!$e:$e"),INDIRECT("'"&$C7&"'!$C:$C"),Q$3,INDIRECT("'"&$C7&"'!$A:$A"),$F$2) -> 0 | R7: =SUMIFS(INDIRECT("'"&$C7&"'!$e:$e"),INDIRECT("'"&$C7&"'!$C:$C"),R$3,INDIRECT("'"&$C7&"'!$A:$A"),$F$2) -> 0 | S7: =SUMIFS(INDIRECT("'"&$C7&"'!$e:$e"),INDIRECT("'"&$C7&"'!$C:$C"),S$3,INDIRECT("'"&$C7&"'!$A:$A"),$F$2) -> 0 | T7: =SUMIFS(INDIRECT("'"&$C7&"'!$e:$e"),INDIRECT("'"&$C7&"'!$C:$C"),T$3,INDIRECT("'"&$C7&"'!$A:$A"),$F$2) -> 0 | U7: =SUMIFS(INDIRECT("'"&$C7&"'!$e:$e"),INDIRECT("'"&$C7&"'!$C:$C"),U$3,INDIRECT("'"&$C7&"'!$A:$A"),$F$2) -> 0 | V7: =SUMIFS(INDIRECT("'"&$C7&"'!$e:$e"),INDIRECT("'"&$C7&"'!$C:$C"),V$3,INDIRECT("'"&$C7&"'!$A:$A"),$F$2) -> 0 | W7: =SUMIFS(INDIRECT("'"&$C7&"'!$e:$e"),INDIRECT("'"&$C7&"'!$C:$C"),W$3,INDIRECT("'"&$C7&"'!$A:$A"),$F$2) -> 0
A8: =IF(B8=0,MATCH($F$2,INDIRECT("'"&C8&"'!A:A"),1),MATCH($F$2,INDIRECT("'"&C8&"'!A:A"),0)) -> 308 | B8: =COUNTIF(INDIRECT("'"&C8&"'!A:A"),$F$2) -> 0 | C8: 5 | F8: =VLOOKUP(C8,档案!A:B,2,FALSE) -> 建设豪威银行500746（扣ETC) | G8: =IF(B8=0,INDEX(INDIRECT("'"&$C8&"'!$F:$F"),$A8,1),INDEX(INDIRECT("'"&$C8&"'!$F:$F"),$A8-1,1)) -> 12872.36 | H8: =SUM(K8:O8) -> 0 | I8: =SUM(P8:W8) -> 0 | J8: =G8+H8-I8 -> 12872.36 | K8: =SUMIFS(INDIRECT("'"&$C8&"'!$D:$D"),INDIRECT("'"&$C8&"'!$C:$C"),K$3,INDIRECT("'"&$C8&"'!$A:$A"),$F$2) -> 0 | L8: =SUMIFS(INDIRECT("'"&$C8&"'!$D:$D"),INDIRECT("'"&$C8&"'!$C:$C"),L$3,INDIRECT("'"&$C8&"'!$A:$A"),$F$2) -> 0 | M8: =SUMIFS(INDIRECT("'"&$C8&"'!$D:$D"),INDIRECT("'"&$C8&"'!$C:$C"),M$3,INDIRECT("'"&$C8&"'!$A:$A"),$F$2) -> 0 | N8: =SUMIFS(INDIRECT("'"&$C8&"'!$D:$D"),INDIRECT("'"&$C8&"'!$C:$C"),N$3,INDIRECT("'"&$C8&"'!$A:$A"),$F$2) -> 0 | O8: =SUMIFS(INDIRECT("'"&$C8&"'!$D:$D"),INDIRECT("'"&$C8&"'!$C:$C"),O$3,INDIRECT("'"&$C8&"'!$A:$A"),$F$2) -> 0 | P8: =SUMIFS(INDIRECT("'"&$C8&"'!$e:$e"),INDIRECT("'"&$C8&"'!$C:$C"),P$3,INDIRECT("'"&$C8&"'!$A:$A"),$F$2) -> 0 | Q8: =SUMIFS(INDIRECT("'"&$C8&"'!$e:$e"),INDIRECT("'"&$C8&"'!$C:$C"),Q$3,INDIRECT("'"&$C8&"'!$A:$A"),$F$2) -> 0 | R8: =SUMIFS(INDIRECT("'"&$C8&"'!$e:$e"),INDIRECT("'"&$C8&"'!$C:$C"),R$3,INDIRECT("'"&$C8&"'!$A:$A"),$F$2) -> 0 | S8: =SUMIFS(INDIRECT("'"&$C8&"'!$e:$e"),INDIRECT("'"&$C8&"'!$C:$C"),S$3,INDIRECT("'"&$C8&"'!$A:$A"),$F$2) -> 0 | T8: =SUMIFS(INDIRECT("'"&$C8&"'!$e:$e"),INDIRECT("'"&$C8&"'!$C:$C"),T$3,INDIRECT("'"&$C8&"'!$A:$A"),$F$2) -> 0 | U8: =SUMIFS(INDIRECT("'"&$C8&"'!$e:$e"),INDIRECT("'"&$C8&"'!$C:$C"),U$3,INDIRECT("'"&$C8&"'!$A:$A"),$F$2) -> 0 | V8: =SUMIFS(INDIRECT("'"&$C8&"'!$e:$e"),INDIRECT("'"&$C8&"'!$C:$C"),V$3,INDIRECT("'"&$C8&"'!$A:$A"),$F$2) -> 0 | W8: =SUMIFS(INDIRECT("'"&$C8&"'!$e:$e"),INDIRECT("'"&$C8&"'!$C:$C"),W$3,INDIRECT("'"&$C8&"'!$A:$A"),$F$2) -> 0
A9: =IF(B9=0,MATCH($F$2,INDIRECT("'"&C9&"'!A:A"),1),MATCH($F$2,INDIRECT("'"&C9&"'!A:A"),0)) -> 28 | B9: =COUNTIF(INDIRECT("'"&C9&"'!A:A"),$F$2) -> 0 | C9: 6 | F9: =VLOOKUP(C9,档案!A:B,2,FALSE) -> 交通银行洪山支行4632877 | G9: =IF(B9=0,INDEX(INDIRECT("'"&$C9&"'!$F:$F"),$A9,1),INDEX(INDIRECT("'"&$C9&"'!$F:$F"),$A9-1,1)) -> 13229.22 | H9: =SUM(K9:O9) -> 0 | I9: =SUM(P9:W9) -> 0 | J9: =G9+H9-I9 -> 13229.22 | K9: =SUMIFS(INDIRECT("'"&$C9&"'!$D:$D"),INDIRECT("'"&$C9&"'!$C:$C"),K$3,INDIRECT("'"&$C9&"'!$A:$A"),$F$2) -> 0 | L9: =SUMIFS(INDIRECT("'"&$C9&"'!$D:$D"),INDIRECT("'"&$C9&"'!$C:$C"),L$3,INDIRECT("'"&$C9&"'!$A:$A"),$F$2) -> 0 | M9: =SUMIFS(INDIRECT("'"&$C9&"'!$D:$D"),INDIRECT("'"&$C9&"'!$C:$C"),M$3,INDIRECT("'"&$C9&"'!$A:$A"),$F$2) -> 0 | N9: =SUMIFS(INDIRECT("'"&$C9&"'!$D:$D"),INDIRECT("'"&$C9&"'!$C:$C"),N$3,INDIRECT("'"&$C9&"'!$A:$A"),$F$2) -> 0 | O9: =SUMIFS(INDIRECT("'"&$C9&"'!$D:$D"),INDIRECT("'"&$C9&"'!$C:$C"),O$3,INDIRECT("'"&$C9&"'!$A:$A"),$F$2) -> 0 | P9: =SUMIFS(INDIRECT("'"&$C9&"'!$e:$e"),INDIRECT("'"&$C9&"'!$C:$C"),P$3,INDIRECT("'"&$C9&"'!$A:$A"),$F$2) -> 0 | Q9: =SUMIFS(INDIRECT("'"&$C9&"'!$e:$e"),INDIRECT("'"&$C9&"'!$C:$C"),Q$3,INDIRECT("'"&$C9&"'!$A:$A"),$F$2) -> 0 | R9: =SUMIFS(INDIRECT("'"&$C9&"'!$e:$e"),INDIRECT("'"&$C9&"'!$C:$C"),R$3,INDIRECT("'"&$C9&"'!$A:$A"),$F$2) -> 0 | S9: =SUMIFS(INDIRECT("'"&$C9&"'!$e:$e"),INDIRECT("'"&$C9&"'!$C:$C"),S$3,INDIRECT("'"&$C9&"'!$A:$A"),$F$2) -> 0 | T9: =SUMIFS(INDIRECT("'"&$C9&"'!$e:$e"),INDIRECT("'"&$C9&"'!$C:$C"),T$3,INDIRECT("'"&$C9&"'!$A:$A"),$F$2) -> 0 | U9: =SUMIFS(INDIRECT("'"&$C9&"'!$e:$e"),INDIRECT("'"&$C9&"'!$C:$C"),U$3,INDIRECT("'"&$C9&"'!$A:$A"),$F$2) -> 0 | V9: =SUMIFS(INDIRECT("'"&$C9&"'!$e:$e"),INDIRECT("'"&$C9&"'!$C:$C"),V$3,INDIRECT("'"&$C9&"'!$A:$A"),$F$2) -> 0 | W9: =SUMIFS(INDIRECT("'"&$C9&"'!$e:$e"),INDIRECT("'"&$C9&"'!$C:$C"),W$3,INDIRECT("'"&$C9&"'!$A:$A"),$F$2) -> 0
A10: =IF(B10=0,MATCH($F$2,INDIRECT("'"&C10&"'!A:A"),1),MATCH($F$2,INDIRECT("'"&C10&"'!A:A"),0)) -> 8 | B10: =COUNTIF(INDIRECT("'"&C10&"'!A:A"),$F$2) -> 0 | C10: 7 | F10: =VLOOKUP(C10,档案!A:B,2,FALSE) -> 邮政储蓄凤凰支行096669 | G10: =IF(B10=0,INDEX(INDIRECT("'"&$C10&"'!$F:$F"),$A10,1),INDEX(INDIRECT("'"&$C10&"'!$F:$F"),$A10-1,1)) -> 380.49 | H10: =SUM(K10:O10) -> 0 | I10: =SUM(P10:W10) -> 0 | J10: =G10+H10-I10 -> 380.49 | K10: =SUMIFS(INDIRECT("'"&$C10&"'!$D:$D"),INDIRECT("'"&$C10&"'!$C:$C"),K$3,INDIRECT("'"&$C10&"'!$A:$A"),$F$2) -> 0 | L10: =SUMIFS(INDIRECT("'"&$C10&"'!$D:$D"),INDIRECT("'"&$C10&"'!$C:$C"),L$3,INDIRECT("'"&$C10&"'!$A:$A"),$F$2) -> 0 | M10: =SUMIFS(INDIRECT("'"&$C10&"'!$D:$D"),INDIRECT("'"&$C10&"'!$C:$C"),M$3,INDIRECT("'"&$C10&"'!$A:$A"),$F$2) -> 0 | N10: =SUMIFS(INDIRECT("'"&$C10&"'!$D:$D"),INDIRECT("'"&$C10&"'!$C:$C"),N$3,INDIRECT("'"&$C10&"'!$A:$A"),$F$2) -> 0 | O10: =SUMIFS(INDIRECT("'"&$C10&"'!$D:$D"),INDIRECT("'"&$C10&"'!$C:$C"),O$3,INDIRECT("'"&$C10&"'!$A:$A"),$F$2) -> 0 | P10: =SUMIFS(INDIRECT("'"&$C10&"'!$e:$e"),INDIRECT("'"&$C10&"'!$C:$C"),P$3,INDIRECT("'"&$C10&"'!$A:$A"),$F$2) -> 0 | Q10: =SUMIFS(INDIRECT("'"&$C10&"'!$e:$e"),INDIRECT("'"&$C10&"'!$C:$C"),Q$3,INDIRECT("'"&$C10&"'!$A:$A"),$F$2) -> 0 | R10: =SUMIFS(INDIRECT("'"&$C10&"'!$e:$e"),INDIRECT("'"&$C10&"'!$C:$C"),R$3,INDIRECT("'"&$C10&"'!$A:$A"),$F$2) -> 0 | S10: =SUMIFS(INDIRECT("'"&$C10&"'!$e:$e"),INDIRECT("'"&$C10&"'!$C:$C"),S$3,INDIRECT("'"&$C10&"'!$A:$A"),$F$2) -> 0 | T10: =SUMIFS(INDIRECT("'"&$C10&"'!$e:$e"),INDIRECT("'"&$C10&"'!$C:$C"),T$3,INDIRECT("'"&$C10&"'!$A:$A"),$F$2) -> 0 | U10: =SUMIFS(INDIRECT("'"&$C10&"'!$e:$e"),INDIRECT("'"&$C10&"'!$C:$C"),U$3,INDIRECT("'"&$C10&"'!$A:$A"),$F$2) -> 0 | V10: =SUMIFS(INDIRECT("'"&$C10&"'!$e:$e"),INDIRECT("'"&$C10&"'!$C:$C"),V$3,INDIRECT("'"&$C10&"'!$A:$A"),$F$2) -> 0 | W10: =SUMIFS(INDIRECT("'"&$C10&"'!$e:$e"),INDIRECT("'"&$C10&"'!$C:$C"),W$3,INDIRECT("'"&$C10&"'!$A:$A"),$F$2) -> 0
A11: =IF(B11=0,MATCH($F$2,INDIRECT("'"&C11&"'!A:A"),1),MATCH($F$2,INDIRECT("'"&C11&"'!A:A"),0)) -> 30 | B11: =COUNTIF(INDIRECT("'"&C11&"'!A:A"),$F$2) -> 0 | C11: 8 | F11: =VLOOKUP(C11,档案!A:B,2,FALSE) -> 宁波银行余姚支行营业部825161 | G11: =IF(B11=0,INDEX(INDIRECT("'"&$C11&"'!$F:$F"),$A11,1),INDEX(INDIRECT("'"&$C11&"'!$F:$F"),$A11-1,1)) -> 71668.02 | H11: =SUM(K11:O11) -> 0 | I11: =SUM(P11:W11) -> 0 | J11: =G11+H11-I11 -> 71668.02 | K11: =SUMIFS(INDIRECT("'"&$C11&"'!$D:$D"),INDIRECT("'"&$C11&"'!$C:$C"),K$3,INDIRECT("'"&$C11&"'!$A:$A"),$F$2) -> 0 | L11: =SUMIFS(INDIRECT("'"&$C11&"'!$D:$D"),INDIRECT("'"&$C11&"'!$C:$C"),L$3,INDIRECT("'"&$C11&"'!$A:$A"),$F$2) -> 0 | M11: =SUMIFS(INDIRECT("'"&$C11&"'!$D:$D"),INDIRECT("'"&$C11&"'!$C:$C"),M$3,INDIRECT("'"&$C11&"'!$A:$A"),$F$2) -> 0 | N11: =SUMIFS(INDIRECT("'"&$C11&"'!$D:$D"),INDIRECT("'"&$C11&"'!$C:$C"),N$3,INDIRECT("'"&$C11&"'!$A:$A"),$F$2) -> 0 | O11: =SUMIFS(INDIRECT("'"&$C11&"'!$D:$D"),INDIRECT("'"&$C11&"'!$C:$C"),O$3,INDIRECT("'"&$C11&"'!$A:$A"),$F$2) -> 0 | P11: =SUMIFS(INDIRECT("'"&$C11&"'!$e:$e"),INDIRECT("'"&$C11&"'!$C:$C"),P$3,INDIRECT("'"&$C11&"'!$A:$A"),$F$2) -> 0 | Q11: =SUMIFS(INDIRECT("'"&$C11&"'!$e:$e"),INDIRECT("'"&$C11&"'!$C:$C"),Q$3,INDIRECT("'"&$C11&"'!$A:$A"),$F$2) -> 0 | R11: =SUMIFS(INDIRECT("'"&$C11&"'!$e:$e"),INDIRECT("'"&$C11&"'!$C:$C"),R$3,INDIRECT("'"&$C11&"'!$A:$A"),$F$2) -> 0 | S11: =SUMIFS(INDIRECT("'"&$C11&"'!$e:$e"),INDIRECT("'"&$C11&"'!$C:$C"),S$3,INDIRECT("'"&$C11&"'!$A:$A"),$F$2) -> 0 | T11: =SUMIFS(INDIRECT("'"&$C11&"'!$e:$e"),INDIRECT("'"&$C11&"'!$C:$C"),T$3,INDIRECT("'"&$C11&"'!$A:$A"),$F$2) -> 0 | U11: =SUMIFS(INDIRECT("'"&$C11&"'!$e:$e"),INDIRECT("'"&$C11&"'!$C:$C"),U$3,INDIRECT("'"&$C11&"'!$A:$A"),$F$2) -> 0 | V11: =SUMIFS(INDIRECT("'"&$C11&"'!$e:$e"),INDIRECT("'"&$C11&"'!$C:$C"),V$3,INDIRECT("'"&$C11&"'!$A:$A"),$F$2) -> 0 | W11: =SUMIFS(INDIRECT("'"&$C11&"'!$e:$e"),INDIRECT("'"&$C11&"'!$C:$C"),W$3,INDIRECT("'"&$C11&"'!$A:$A"),$F$2) -> 0
A12: =IF(B12=0,MATCH($F$2,INDIRECT("'"&C12&"'!A:A"),1),MATCH($F$2,INDIRECT("'"&C12&"'!A:A"),0)) -> 2387 | B12: =COUNTIF(INDIRECT("'"&C12&"'!A:A"),$F$2) -> 0 | C12: 9 | F12: =VLOOKUP(C12,档案!A:B,2,FALSE) -> 农商行豹澥支行310028 | G12: =IF(B12=0,INDEX(INDIRECT("'"&$C12&"'!$F:$F"),$A12,1),INDEX(INDIRECT("'"&$C12&"'!$F:$F"),$A12-1,1)) -> 380075.61 | H12: =SUM(K12:O12) -> 0 | I12: =SUM(P12:W12) -> 0 | J12: =G12+H12-I12 -> 380075.61 | K12: =SUMIFS(INDIRECT("'"&$C12&"'!$D:$D"),INDIRECT("'"&$C12&"'!$C:$C"),K$3,INDIRECT("'"&$C12&"'!$A:$A"),$F$2) -> 0 | L12: =SUMIFS(INDIRECT("'"&$C12&"'!$D:$D"),INDIRECT("'"&$C12&"'!$C:$C"),L$3,INDIRECT("'"&$C12&"'!$A:$A"),$F$2) -> 0 | M12: =SUMIFS(INDIRECT("'"&$C12&"'!$D:$D"),INDIRECT("'"&$C12&"'!$C:$C"),M$3,INDIRECT("'"&$C12&"'!$A:$A"),$F$2) -> 0 | N12: =SUMIFS(INDIRECT("'"&$C12&"'!$D:$D"),INDIRECT("'"&$C12&"'!$C:$C"),N$3,INDIRECT("'"&$C12&"'!$A:$A"),$F$2) -> 0 | O12: =SUMIFS(INDIRECT("'"&$C12&"'!$D:$D"),INDIRECT("'"&$C12&"'!$C:$C"),O$3,INDIRECT("'"&$C12&"'!$A:$A"),$F$2) -> 0 | P12: =SUMIFS(INDIRECT("'"&$C12&"'!$e:$e"),INDIRECT("'"&$C12&"'!$C:$C"),P$3,INDIRECT("'"&$C12&"'!$A:$A"),$F$2) -> 0 | Q12: =SUMIFS(INDIRECT("'"&$C12&"'!$e:$e"),INDIRECT("'"&$C12&"'!$C:$C"),Q$3,INDIRECT("'"&$C12&"'!$A:$A"),$F$2) -> 0 | R12: =SUMIFS(INDIRECT("'"&$C12&"'!$e:$e"),INDIRECT("'"&$C12&"'!$C:$C"),R$3,INDIRECT("'"&$C12&"'!$A:$A"),$F$2) -> 0 | S12: =SUMIFS(INDIRECT("'"&$C12&"'!$e:$e"),INDIRECT("'"&$C12&"'!$C:$C"),S$3,INDIRECT("'"&$C12&"'!$A:$A"),$F$2) -> 0 | T12: =SUMIFS(INDIRECT("'"&$C12&"'!$e:$e"),INDIRECT("'"&$C12&"'!$C:$C"),T$3,INDIRECT("'"&$C12&"'!$A:$A"),$F$2) -> 0 | U12: =SUMIFS(INDIRECT("'"&$C12&"'!$e:$e"),INDIRECT("'"&$C12&"'!$C:$C"),U$3,INDIRECT("'"&$C12&"'!$A:$A"),$F$2) -> 0 | V12: =SUMIFS(INDIRECT("'"&$C12&"'!$e:$e"),INDIRECT("'"&$C12&"'!$C:$C"),V$3,INDIRECT("'"&$C12&"'!$A:$A"),$F$2) -> 0 | W12: =SUMIFS(INDIRECT("'"&$C12&"'!$e:$e"),INDIRECT("'"&$C12&"'!$C:$C"),W$3,INDIRECT("'"&$C12&"'!$A:$A"),$F$2) -> 0
A13: =IF(B13=0,MATCH($F$2,INDIRECT("'"&C13&"'!A:A"),1),MATCH($F$2,INDIRECT("'"&C13&"'!A:A"),0)) -> 109 | B13: =COUNTIF(INDIRECT("'"&C13&"'!A:A"),$F$2) -> 0 | C13: 10 | F13: =VLOOKUP(C13,档案!A:B,2,FALSE) -> 工行武汉瀚城支行004604 | G13: =IF(B13=0,INDEX(INDIRECT("'"&$C13&"'!$F:$F"),$A13,1),INDEX(INDIRECT("'"&$C13&"'!$F:$F"),$A13-1,1)) -> 15856.36 | H13: =SUM(K13:O13) -> 0 | I13: =SUM(P13:W13) -> 0 | J13: =G13+H13-I13 -> 15856.36 | K13: =SUMIFS(INDIRECT("'"&$C13&"'!$D:$D"),INDIRECT("'"&$C13&"'!$C:$C"),K$3,INDIRECT("'"&$C13&"'!$A:$A"),$F$2) -> 0 | L13: =SUMIFS(INDIRECT("'"&$C13&"'!$D:$D"),INDIRECT("'"&$C13&"'!$C:$C"),L$3,INDIRECT("'"&$C13&"'!$A:$A"),$F$2) -> 0 | M13: =SUMIFS(INDIRECT("'"&$C13&"'!$D:$D"),INDIRECT("'"&$C13&"'!$C:$C"),M$3,INDIRECT("'"&$C13&"'!$A:$A"),$F$2) -> 0 | N13: =SUMIFS(INDIRECT("'"&$C13&"'!$D:$D"),INDIRECT("'"&$C13&"'!$C:$C"),N$3,INDIRECT("'"&$C13&"'!$A:$A"),$F$2) -> 0 | O13: =SUMIFS(INDIRECT("'"&$C13&"'!$D:$D"),INDIRECT("'"&$C13&"'!$C:$C"),O$3,INDIRECT("'"&$C13&"'!$A:$A"),$F$2) -> 0 | P13: =SUMIFS(INDIRECT("'"&$C13&"'!$e:$e"),INDIRECT("'"&$C13&"'!$C:$C"),P$3,INDIRECT("'"&$C13&"'!$A:$A"),$F$2) -> 0 | Q13: =SUMIFS(INDIRECT("'"&$C13&"'!$e:$e"),INDIRECT("'"&$C13&"'!$C:$C"),Q$3,INDIRECT("'"&$C13&"'!$A:$A"),$F$2) -> 0 | R13: =SUMIFS(INDIRECT("'"&$C13&"'!$e:$e"),INDIRECT("'"&$C13&"'!$C:$C"),R$3,INDIRECT("'"&$C13&"'!$A:$A"),$F$2) -> 0 | S13: =SUMIFS(INDIRECT("'"&$C13&"'!$e:$e"),INDIRECT("'"&$C13&"'!$C:$C"),S$3,INDIRECT("'"&$C13&"'!$A:$A"),$F$2) -> 0 | T13: =SUMIFS(INDIRECT("'"&$C13&"'!$e:$e"),INDIRECT("'"&$C13&"'!$C:$C"),T$3,INDIRECT("'"&$C13&"'!$A:$A"),$F$2) -> 0 | U13: =SUMIFS(INDIRECT("'"&$C13&"'!$e:$e"),INDIRECT("'"&$C13&"'!$C:$C"),U$3,INDIRECT("'"&$C13&"'!$A:$A"),$F$2) -> 0 | V13: =SUMIFS(INDIRECT("'"&$C13&"'!$e:$e"),INDIRECT("'"&$C13&"'!$C:$C"),V$3,INDIRECT("'"&$C13&"'!$A:$A"),$F$2) -> 0 | W13: =SUMIFS(INDIRECT("'"&$C13&"'!$e:$e"),INDIRECT("'"&$C13&"'!$C:$C"),W$3,INDIRECT("'"&$C13&"'!$A:$A"),$F$2) -> 0
A14: =IF(B14=0,MATCH($F$2,INDIRECT("'"&C14&"'!A:A"),1),MATCH($F$2,INDIRECT("'"&C14&"'!A:A"),0)) -> 18 | B14: =COUNTIF(INDIRECT("'"&C14&"'!A:A"),$F$2) -> 0 | C14: 11 | F14: =VLOOKUP(C14,档案!A:B,2,FALSE) -> 青海农商行农民工工资保证金954442 | G14: =IF(B14=0,INDEX(INDIRECT("'"&$C14&"'!$F:$F"),$A14,1),INDEX(INDIRECT("'"&$C14&"'!$F:$F"),$A14-1,1)) -> 316856.32 | H14: =SUM(K14:O14) -> 0 | I14: =SUM(P14:W14) -> 0 | J14: =G14+H14-I14 -> 316856.32 | K14: =SUMIFS(INDIRECT("'"&$C14&"'!$D:$D"),INDIRECT("'"&$C14&"'!$C:$C"),K$3,INDIRECT("'"&$C14&"'!$A:$A"),$F$2) -> 0 | L14: =SUMIFS(INDIRECT("'"&$C14&"'!$D:$D"),INDIRECT("'"&$C14&"'!$C:$C"),L$3,INDIRECT("'"&$C14&"'!$A:$A"),$F$2) -> 0 | M14: =SUMIFS(INDIRECT("'"&$C14&"'!$D:$D"),INDIRECT("'"&$C14&"'!$C:$C"),M$3,INDIRECT("'"&$C14&"'!$A:$A"),$F$2) -> 0 | N14: =SUMIFS(INDIRECT("'"&$C14&"'!$D:$D"),INDIRECT("'"&$C14&"'!$C:$C"),N$3,INDIRECT("'"&$C14&"'!$A:$A"),$F$2) -> 0 | O14: =SUMIFS(INDIRECT("'"&$C14&"'!$D:$D"),INDIRECT("'"&$C14&"'!$C:$C"),O$3,INDIRECT("'"&$C14&"'!$A:$A"),$F$2) -> 0 | P14: =SUMIFS(INDIRECT("'"&$C14&"'!$e:$e"),INDIRECT("'"&$C14&"'!$C:$C"),P$3,INDIRECT("'"&$C14&"'!$A:$A"),$F$2) -> 0 | Q14: =SUMIFS(INDIRECT("'"&$C14&"'!$e:$e"),INDIRECT("'"&$C14&"'!$C:$C"),Q$3,INDIRECT("'"&$C14&"'!$A:$A"),$F$2) -> 0 | R14: =SUMIFS(INDIRECT("'"&$C14&"'!$e:$e"),INDIRECT("'"&$C14&"'!$C:$C"),R$3,INDIRECT("'"&$C14&"'!$A:$A"),$F$2) -> 0 | S14: =SUMIFS(INDIRECT("'"&$C14&"'!$e:$e"),INDIRECT("'"&$C14&"'!$C:$C"),S$3,INDIRECT("'"&$C14&"'!$A:$A"),$F$2) -> 0 | T14: =SUMIFS(INDIRECT("'"&$C14&"'!$e:$e"),INDIRECT("'"&$C14&"'!$C:$C"),T$3,INDIRECT("'"&$C14&"'!$A:$A"),$F$2) -> 0 | U14: =SUMIFS(INDIRECT("'"&$C14&"'!$e:$e"),INDIRECT("'"&$C14&"'!$C:$C"),U$3,INDIRECT("'"&$C14&"'!$A:$A"),$F$2) -> 0 | V14: =SUMIFS(INDIRECT("'"&$C14&"'!$e:$e"),INDIRECT("'"&$C14&"'!$C:$C"),V$3,INDIRECT("'"&$C14&"'!$A:$A"),$F$2) -> 0 | W14: =SUMIFS(INDIRECT("'"&$C14&"'!$e:$e"),INDIRECT("'"&$C14&"'!$C:$C"),W$3,INDIRECT("'"&$C14&"'!$A:$A"),$F$2) -> 0
A15: =IF(B15=0,MATCH($F$2,INDIRECT("'"&C15&"'!A:A"),1),MATCH($F$2,INDIRECT("'"&C15&"'!A:A"),0)) -> 3 | B15: =COUNTIF(INDIRECT("'"&C15&"'!A:A"),$F$2) -> 0 | C15: 12 | F15: =VLOOKUP(C15,档案!A:B,2,FALSE) -> 中国银行鹦鹉大道支行 | G15: =IF(B15=0,INDEX(INDIRECT("'"&$C15&"'!$F:$F"),$A15,1),INDEX(INDIRECT("'"&$C15&"'!$F:$F"),$A15-1,1)) -> 0 | H15: =SUM(K15:O15) -> 0 | I15: =SUM(P15:W15) -> 0 | J15: =G15+H15-I15 -> 0 | K15: =SUMIFS(INDIRECT("'"&$C15&"'!$D:$D"),INDIRECT("'"&$C15&"'!$C:$C"),K$3,INDIRECT("'"&$C15&"'!$A:$A"),$F$2) -> 0 | L15: =SUMIFS(INDIRECT("'"&$C15&"'!$D:$D"),INDIRECT("'"&$C15&"'!$C:$C"),L$3,INDIRECT("'"&$C15&"'!$A:$A"),$F$2) -> 0 | M15: =SUMIFS(INDIRECT("'"&$C15&"'!$D:$D"),INDIRECT("'"&$C15&"'!$C:$C"),M$3,INDIRECT("'"&$C15&"'!$A:$A"),$F$2) -> 0 | N15: =SUMIFS(INDIRECT("'"&$C15&"'!$D:$D"),INDIRECT("'"&$C15&"'!$C:$C"),N$3,INDIRECT("'"&$C15&"'!$A:$A"),$F$2) -> 0 | O15: =SUMIFS(INDIRECT("'"&$C15&"'!$D:$D"),INDIRECT("'"&$C15&"'!$C:$C"),O$3,INDIRECT("'"&$C15&"'!$A:$A"),$F$2) -> 0 | P15: =SUMIFS(INDIRECT("'"&$C15&"'!$e:$e"),INDIRECT("'"&$C15&"'!$C:$C"),P$3,INDIRECT("'"&$C15&"'!$A:$A"),$F$2) -> 0 | Q15: =SUMIFS(INDIRECT("'"&$C15&"'!$e:$e"),INDIRECT("'"&$C15&"'!$C:$C"),Q$3,INDIRECT("'"&$C15&"'!$A:$A"),$F$2) -> 0 | R15: =SUMIFS(INDIRECT("'"&$C15&"'!$e:$e"),INDIRECT("'"&$C15&"'!$C:$C"),R$3,INDIRECT("'"&$C15&"'!$A:$A"),$F$2) -> 0 | S15: =SUMIFS(INDIRECT("'"&$C15&"'!$e:$e"),INDIRECT("'"&$C15&"'!$C:$C"),S$3,INDIRECT("'"&$C15&"'!$A:$A"),$F$2) -> 0 | T15: =SUMIFS(INDIRECT("'"&$C15&"'!$e:$e"),INDIRECT("'"&$C15&"'!$C:$C"),T$3,INDIRECT("'"&$C15&"'!$A:$A"),$F$2) -> 0 | U15: =SUMIFS(INDIRECT("'"&$C15&"'!$e:$e"),INDIRECT("'"&$C15&"'!$C:$C"),U$3,INDIRECT("'"&$C15&"'!$A:$A"),$F$2) -> 0 | V15: =SUMIFS(INDIRECT("'"&$C15&"'!$e:$e"),INDIRECT("'"&$C15&"'!$C:$C"),V$3,INDIRECT("'"&$C15&"'!$A:$A"),$F$2) -> 0 | W15: =SUMIFS(INDIRECT("'"&$C15&"'!$e:$e"),INDIRECT("'"&$C15&"'!$C:$C"),W$3,INDIRECT("'"&$C15&"'!$A:$A"),$F$2) -> 0
A16: =IF(B16=0,MATCH($F$2,INDIRECT("'"&C16&"'!A:A"),1),MATCH($F$2,INDIRECT("'"&C16&"'!A:A"),0)) -> 8 | B16: =COUNTIF(INDIRECT("'"&C16&"'!A:A"),$F$2) -> 0 | C16: 13 | F16: =VLOOKUP(C16,档案!A:B,2,FALSE) -> 华夏银行京汉支行948890 | G16: =IF(B16=0,INDEX(INDIRECT("'"&$C16&"'!$F:$F"),$A16,1),INDEX(INDIRECT("'"&$C16&"'!$F:$F"),$A16-1,1)) -> 20458.33 | H16: =SUM(K16:O16) -> 0 | I16: =SUM(P16:W16) -> 0 | J16: =G16+H16-I16 -> 20458.33 | K16: =SUMIFS(INDIRECT("'"&$C16&"'!$D:$D"),INDIRECT("'"&$C16&"'!$C:$C"),K$3,INDIRECT("'"&$C16&"'!$A:$A"),$F$2) -> 0 | L16: =SUMIFS(INDIRECT("'"&$C16&"'!$D:$D"),INDIRECT("'"&$C16&"'!$C:$C"),L$3,INDIRECT("'"&$C16&"'!$A:$A"),$F$2) -> 0 | M16: =SUMIFS(INDIRECT("'"&$C16&"'!$D:$D"),INDIRECT("'"&$C16&"'!$C:$C"),M$3,INDIRECT("'"&$C16&"'!$A:$A"),$F$2) -> 0 | N16: =SUMIFS(INDIRECT("'"&$C16&"'!$D:$D"),INDIRECT("'"&$C16&"'!$C:$C"),N$3,INDIRECT("'"&$C16&"'!$A:$A"),$F$2) -> 0 | O16: =SUMIFS(INDIRECT("'"&$C16&"'!$D:$D"),INDIRECT("'"&$C16&"'!$C:$C"),O$3,INDIRECT("'"&$C16&"'!$A:$A"),$F$2) -> 0 | P16: =SUMIFS(INDIRECT("'"&$C16&"'!$e:$e"),INDIRECT("'"&$C16&"'!$C:$C"),P$3,INDIRECT("'"&$C16&"'!$A:$A"),$F$2) -> 0 | Q16: =SUMIFS(INDIRECT("'"&$C16&"'!$e:$e"),INDIRECT("'"&$C16&"'!$C:$C"),Q$3,INDIRECT("'"&$C16&"'!$A:$A"),$F$2) -> 0 | R16: =SUMIFS(INDIRECT("'"&$C16&"'!$e:$e"),INDIRECT("'"&$C16&"'!$C:$C"),R$3,INDIRECT("'"&$C16&"'!$A:$A"),$F$2) -> 0 | S16: =SUMIFS(INDIRECT("'"&$C16&"'!$e:$e"),INDIRECT("'"&$C16&"'!$C:$C"),S$3,INDIRECT("'"&$C16&"'!$A:$A"),$F$2) -> 0 | T16: =SUMIFS(INDIRECT("'"&$C16&"'!$e:$e"),INDIRECT("'"&$C16&"'!$C:$C"),T$3,INDIRECT("'"&$C16&"'!$A:$A"),$F$2) -> 0 | U16: =SUMIFS(INDIRECT("'"&$C16&"'!$e:$e"),INDIRECT("'"&$C16&"'!$C:$C"),U$3,INDIRECT("'"&$C16&"'!$A:$A"),$F$2) -> 0 | V16: =SUMIFS(INDIRECT("'"&$C16&"'!$e:$e"),INDIRECT("'"&$C16&"'!$C:$C"),V$3,INDIRECT("'"&$C16&"'!$A:$A"),$F$2) -> 0 | W16: =SUMIFS(INDIRECT("'"&$C16&"'!$e:$e"),INDIRECT("'"&$C16&"'!$C:$C"),W$3,INDIRECT("'"&$C16&"'!$A:$A"),$F$2) -> 0
... A18: =IF(B18=0,MATCH($F$2,INDIRECT("'"&C18&"'!A:A"),1),MATCH($F$2,INDIRECT("'"&C18&"'!A:A"),0)) -> 18 | B18: =COUNTIF(INDIRECT("'"&C18&"'!A:A"),$F$2) -> 0 | C18: 15 | F18: =VLOOKUP(C18,档案!A:B,2,FALSE) -> 青海农商行农民工工资发放账户001680 | G18: =IF(B18=0,INDEX(INDIRECT("'"&$C18&"'!$F:$F"),$A18,1),INDEX(INDIRECT("'"&$C18&"'!$F:$F"),$A18-1,1)) -> 17.24 | H18: =SUM(K18:O18) -> 0 | I18: =SUM(P18:W18) -> 0 | J18: =G18+H18-I18 -> 17.24 | K18: =SUMIFS(INDIRECT("'"&$C18&"'!$D:$D"),INDIRECT("'"&$C18&"'!$C:$C"),K$3,INDIRECT("'"&$C18&"'!$A:$A"),$F$2) -> 0 | L18: =SUMIFS(INDIRECT("'"&$C18&"'!$D:$D"),INDIRECT("'"&$C18&"'!$C:$C"),L$3,INDIRECT("'"&$C18&"'!$A:$A"),$F$2) -> 0 | M18: =SUMIFS(INDIRECT("'"&$C18&"'!$D:$D"),INDIRECT("'"&$C18&"'!$C:$C"),M$3,INDIRECT("'"&$C18&"'!$A:$A"),$F$2) -> 0 | N18: =SUMIFS(INDIRECT("'"&$C18&"'!$D:$D"),INDIRECT("'"&$C18&"'!$C:$C"),N$3,INDIRECT("'"&$C18&"'!$A:$A"),$F$2) -> 0 | O18: =SUMIFS(INDIRECT("'"&$C18&"'!$D:$D"),INDIRECT("'"&$C18&"'!$C:$C"),O$3,INDIRECT("'"&$C18&"'!$A:$A"),$F$2) -> 0 | P18: =SUMIFS(INDIRECT("'"&$C18&"'!$e:$e"),INDIRECT("'"&$C18&"'!$C:$C"),P$3,INDIRECT("'"&$C18&"'!$A:$A"),$F$2) -> 0 | Q18: =SUMIFS(INDIRECT("'"&$C18&"'!$e:$e"),INDIRECT("'"&$C18&"'!$C:$C"),Q$3,INDIRECT("'"&$C18&"'!$A:$A"),$F$2) -> 0 | R18: =SUMIFS(INDIRECT("'"&$C18&"'!$e:$e"),INDIRECT("'"&$C18&"'!$C:$C"),R$3,INDIRECT("'"&$C18&"'!$A:$A"),$F$2) -> 0 | S18: =SUMIFS(INDIRECT("'"&$C18&"'!$e:$e"),INDIRECT("'"&$C18&"'!$C:$C"),S$3,INDIRECT("'"&$C18&"'!$A:$A"),$F$2) -> 0 | T18: =SUMIFS(INDIRECT("'"&$C18&"'!$e:$e"),INDIRECT("'"&$C18&"'!$C:$C"),T$3,INDIRECT("'"&$C18&"'!$A:$A"),$F$2) -> 0 | U18: =SUMIFS(INDIRECT("'"&$C18&"'!$e:$e"),INDIRECT("'"&$C18&"'!$C:$C"),U$3,INDIRECT("'"&$C18&"'!$A:$A"),$F$2) -> 0 | V18: =SUMIFS(INDIRECT("'"&$C18&"'!$e:$e"),INDIRECT("'"&$C18&"'!$C:$C"),V$3,INDIRECT("'"&$C18&"'!$A:$A"),$F$2) -> 0 | W18: =SUMIFS(INDIRECT("'"&$C18&"'!$e:$e"),INDIRECT("'"&$C18&"'!$C:$C"),W$3,INDIRECT("'"&$C18&"'!$A:$A"),$F$2) -> 0
A19: =IF(B19=0,MATCH($F$2,INDIRECT("'"&C19&"'!A:A"),1),MATCH($F$2,INDIRECT("'"&C19&"'!A:A"),0)) -> #REF! | B19: =COUNTIF(INDIRECT("'"&C19&"'!A:A"),$F$2) -> #REF! | F19: 小计 | G19: =SUM(G4:G18) -> 931348.47 | H19: =SUM(K19:O19) -> 40000 | I19: =SUM(P19:W19) -> 3.5 | J19: =G19+H19-I19 -> 971344.97 | K19: =SUM(K4:K18) -> 0 | L19: =SUM(L4:L18) -> 0 | M19: =SUM(M4:M18) -> 0 | N19: =SUM(N4:N18) -> 40000 | O19: =SUM(O4:O18) -> 0 | P19: =SUM(P4:P18) -> 0 | Q19: =SUM(Q4:Q18) -> 0 | R19: =SUM(R4:R18) -> 1.5 | ... W19: =SUM(W4:W18) -> 0
A20: =IF(B20=0,MATCH($F$2,INDIRECT("'"&C20&"'!A:A"),1),MATCH($F$2,INDIRECT("'"&C20&"'!A:A"),0)) -> 265 | B20: =COUNTIF(INDIRECT("'"&C20&"'!A:A"),$F$2) -> 0 | C20: 16 | E20: =VLOOKUP(C20,档案!A:B,2,FALSE) -> 电子承兑汇票 | G20: =IF(B20=0,INDEX(INDIRECT("'"&$C20&"'!$F:$F"),$A20,1),INDEX(INDIRECT("'"&$C20&"'!$F:$F"),$A20-1,1)) -> 615485.38 | H20: =SUM(K20:O20) -> 0 | I20: =SUM(P20:W20) -> 0 | J20: =G20+H20-I20 -> 615485.38 | K20: =SUMIFS(INDIRECT("'"&$C20&"'!$D:$D"),INDIRECT("'"&$C20&"'!$C:$C"),K$3,INDIRECT("'"&$C20&"'!$A:$A"),$F$2) -> 0 | L20: =SUMIFS(INDIRECT("'"&$C20&"'!$D:$D"),INDIRECT("'"&$C20&"'!$C:$C"),L$3,INDIRECT("'"&$C20&"'!$A:$A"),$F$2) -> 0 | M20: =SUMIFS(INDIRECT("'"&$C20&"'!$D:$D"),INDIRECT("'"&$C20&"'!$C:$C"),M$3,INDIRECT("'"&$C20&"'!$A:$A"),$F$2) -> 0 | N20: =SUMIFS(INDIRECT("'"&$C20&"'!$D:$D"),INDIRECT("'"&$C20&"'!$C:$C"),N$3,INDIRECT("'"&$C20&"'!$A:$A"),$F$2) -> 0 | O20: =SUMIFS(INDIRECT("'"&$C20&"'!$D:$D"),INDIRECT("'"&$C20&"'!$C:$C"),O$3,INDIRECT("'"&$C20&"'!$A:$A"),$F$2) -> 0 | P20: =SUMIFS(INDIRECT("'"&$C20&"'!$e:$e"),INDIRECT("'"&$C20&"'!$C:$C"),P$3,INDIRECT("'"&$C20&"'!$A:$A"),$F$2) -> 0 | Q20: =SUMIFS(INDIRECT("'"&$C20&"'!$e:$e"),INDIRECT("'"&$C20&"'!$C:$C"),Q$3,INDIRECT("'"&$C20&"'!$A:$A"),$F$2) -> 0 | R20: =SUMIFS(INDIRECT("'"&$C20&"'!$e:$e"),INDIRECT("'"&$C20&"'!$C:$C"),R$3,INDIRECT("'"&$C20&"'!$A:$A"),$F$2) -> 0 | S20: =SUMIFS(INDIRECT("'"&$C20&"'!$e:$e"),INDIRECT("'"&$C20&"'!$C:$C"),S$3,INDIRECT("'"&$C20&"'!$A:$A"),$F$2) -> 0 | T20: =SUMIFS(INDIRECT("'"&$C20&"'!$e:$e"),INDIRECT("'"&$C20&"'!$C:$C"),T$3,INDIRECT("'"&$C20&"'!$A:$A"),$F$2) -> 0 | U20: =SUMIFS(INDIRECT("'"&$C20&"'!$e:$e"),INDIRECT("'"&$C20&"'!$C:$C"),U$3,INDIRECT("'"&$C20&"'!$A:$A"),$F$2) -> 0 | V20: =SUMIFS(INDIRECT("'"&$C20&"'!$e:$e"),INDIRECT("'"&$C20&"'!$C:$C"),V$3,INDIRECT("'"&$C20&"'!$A:$A"),$F$2) -> 0 | W20: =SUMIFS(INDIRECT("'"&$C20&"'!$e:$e"),INDIRECT("'"&$C20&"'!$C:$C"),W$3,INDIRECT("'"&$C20&"'!$A:$A"),$F$2) -> 0
A21: =IF(B21=0,MATCH($F$2,INDIRECT("'"&C21&"'!A:A"),1),MATCH($F$2,INDIRECT("'"&C21&"'!A:A"),0)) -> 7 | B21: =COUNTIF(INDIRECT("'"&C21&"'!A:A"),$F$2) -> 0 | C21: 17 | E21: =VLOOKUP(C21,档案!A:B,2,FALSE) -> 库存现金 | G21: =IF(B21=0,INDEX(INDIRECT("'"&$C21&"'!$F:$F"),$A21,1),INDEX(INDIRECT("'"&$C21&"'!$F:$F"),$A21-1,1)) -> 305 | H21: =SUM(K21:O21) -> 0 | I21: =SUM(P21:W21) -> 0 | J21: =G21+H21-I21 -> 305 | K21: =SUMIFS(INDIRECT("'"&$C21&"'!$D:$D"),INDIRECT("'"&$C21&"'!$C:$C"),K$3,INDIRECT("'"&$C21&"'!$A:$A"),$F$2) -> 0 | L21: =SUMIFS(INDIRECT("'"&$C21&"'!$D:$D"),INDIRECT("'"&$C21&"'!$C:$C"),L$3,INDIRECT("'"&$C21&"'!$A:$A"),$F$2) -> 0 | M21: =SUMIFS(INDIRECT("'"&$C21&"'!$D:$D"),INDIRECT("'"&$C21&"'!$C:$C"),M$3,INDIRECT("'"&$C21&"'!$A:$A"),$F$2) -> 0 | N21: =SUMIFS(INDIRECT("'"&$C21&"'!$D:$D"),INDIRECT("'"&$C21&"'!$C:$C"),N$3,INDIRECT("'"&$C21&"'!$A:$A"),$F$2) -> 0 | O21: =SUMIFS(INDIRECT("'"&$C21&"'!$D:$D"),INDIRECT("'"&$C21&"'!$C:$C"),O$3,INDIRECT("'"&$C21&"'!$A:$A"),$F$2) -> 0 | P21: =SUMIFS(INDIRECT("'"&$C21&"'!$e:$e"),INDIRECT("'"&$C21&"'!$C:$C"),P$3,INDIRECT("'"&$C21&"'!$A:$A"),$F$2) -> 0 | Q21: =SUMIFS(INDIRECT("'"&$C21&"'!$e:$e"),INDIRECT("'"&$C21&"'!$C:$C"),Q$3,INDIRECT("'"&$C21&"'!$A:$A"),$F$2) -> 0 | R21: =SUMIFS(INDIRECT("'"&$C21&"'!$e:$e"),INDIRECT("'"&$C21&"'!$C:$C"),R$3,INDIRECT("'"&$C21&"'!$A:$A"),$F$2) -> 0 | S21: =SUMIFS(INDIRECT("'"&$C21&"'!$e:$e"),INDIRECT("'"&$C21&"'!$C:$C"),S$3,INDIRECT("'"&$C21&"'!$A:$A"),$F$2) -> 0 | T21: =SUMIFS(INDIRECT("'"&$C21&"'!$e:$e"),INDIRECT("'"&$C21&"'!$C:$C"),T$3,INDIRECT("'"&$C21&"'!$A:$A"),$F$2) -> 0 | U21: =SUMIFS(INDIRECT("'"&$C21&"'!$e:$e"),INDIRECT("'"&$C21&"'!$C:$C"),U$3,INDIRECT("'"&$C21&"'!$A:$A"),$F$2) -> 0 | V21: =SUMIFS(INDIRECT("'"&$C21&"'!$e:$e"),INDIRECT("'"&$C21&"'!$C:$C"),V$3,INDIRECT("'"&$C21&"'!$A:$A"),$F$2) -> 0 | W21: =SUMIFS(INDIRECT("'"&$C21&"'!$e:$e"),INDIRECT("'"&$C21&"'!$C:$C"),W$3,INDIRECT("'"&$C21&"'!$A:$A"),$F$2) -> 0
A22: =IF(B22=0,MATCH($F$2,INDIRECT("'"&C22&"'!A:A"),1),MATCH($F$2,INDIRECT("'"&C22&"'!A:A"),0)) -> #REF! | B22: =COUNTIF(INDIRECT("'"&C22&"'!A:A"),$F$2) -> #REF! | E22: 合计 | G22: =SUM(G19:G21) -> 1547138.9 | H22: =SUM(K22:O22) -> 40000 | I22: =SUM(P22:W22) -> 3.5 | J22: =G22+H22-I22 -> 1587135.4 | K22: =SUM(K19:K21) -> 0 | L22: =SUM(L19:L21) -> 0 | M22: =SUM(M19:M21) -> 0 | N22: =SUM(N19:N21) -> 40000 | O22: =SUM(O19:O21) -> 0 | P22: =SUM(P19:P21) -> 0 | Q22: =SUM(Q19:Q21) -> 0 | R22: =SUM(R19:R21) -> 1.5 | ... W22: =SUM(W19:W21) -> 0
A23: =IF(B23=0,MATCH($F$2,INDIRECT("'"&C23&"'!A:A"),1),MATCH($F$2,INDIRECT("'"&C23&"'!A:A"),0)) -> 22 | B23: =COUNTIF(INDIRECT("'"&C23&"'!A:A"),$F$2) -> 0 | C23: 18 | D23: 武汉彤烨 | E23: 银行存款 | F23: =VLOOKUP(C23,档案!A:B,2,FALSE) -> 工商银行西山支行15212 | G23: =IF(B23=0,INDEX(INDIRECT("'"&$C23&"'!$F:$F"),$A23,1),INDEX(INDIRECT("'"&$C23&"'!$F:$F"),$A23-1,1)) -> 790.72 | H23: =SUM(K23:O23) -> 0 | I23: =SUM(P23:W23) -> 0 | J23: =G23+H23-I23 -> 790.72 | K23: =SUMIFS(INDIRECT("'"&$C23&"'!$D:$D"),INDIRECT("'"&$C23&"'!$C:$C"),K$3,INDIRECT("'"&$C23&"'!$A:$A"),$F$2) -> 0 | L23: =SUMIFS(INDIRECT("'"&$C23&"'!$D:$D"),INDIRECT("'"&$C23&"'!$C:$C"),L$3,INDIRECT("'"&$C23&"'!$A:$A"),$F$2) -> 0 | M23: =SUMIFS(INDIRECT("'"&$C23&"'!$D:$D"),INDIRECT("'"&$C23&"'!$C:$C"),M$3,INDIRECT("'"&$C23&"'!$A:$A"),$F$2) -> 0 | N23: =SUMIFS(INDIRECT("'"&$C23&"'!$D:$D"),INDIRECT("'"&$C23&"'!$C:$C"),N$3,INDIRECT("'"&$C23&"'!$A:$A"),$F$2) -> 0 | O23: =SUMIFS(INDIRECT("'"&$C23&"'!$D:$D"),INDIRECT("'"&$C23&"'!$C:$C"),O$3,INDIRECT("'"&$C23&"'!$A:$A"),$F$2) -> 0 | P23: =SUMIFS(INDIRECT("'"&$C23&"'!$e:$e"),INDIRECT("'"&$C23&"'!$C:$C"),P$3,INDIRECT("'"&$C23&"'!$A:$A"),$F$2) -> 0 | Q23: =SUMIFS(INDIRECT("'"&$C23&"'!$e:$e"),INDIRECT("'"&$C23&"'!$C:$C"),Q$3,INDIRECT("'"&$C23&"'!$A:$A"),$F$2) -> 0 | R23: =SUMIFS(INDIRECT("'"&$C23&"'!$e:$e"),INDIRECT("'"&$C23&"'!$C:$C"),R$3,INDIRECT("'"&$C23&"'!$A:$A"),$F$2) -> 0 | S23: =SUMIFS(INDIRECT("'"&$C23&"'!$e:$e"),INDIRECT("'"&$C23&"'!$C:$C"),S$3,INDIRECT("'"&$C23&"'!$A:$A"),$F$2) -> 0 | T23: =SUMIFS(INDIRECT("'"&$C23&"'!$e:$e"),INDIRECT("'"&$C23&"'!$C:$C"),T$3,INDIRECT("'"&$C23&"'!$A:$A"),$F$2) -> 0 | U23: =SUMIFS(INDIRECT("'"&$C23&"'!$e:$e"),INDIRECT("'"&$C23&"'!$C:$C"),U$3,INDIRECT("'"&$C23&"'!$A:$A"),$F$2) -> 0 | V23: =SUMIFS(INDIRECT("'"&$C23&"'!$e:$e"),INDIRECT("'"&$C23&"'!$C:$C"),V$3,INDIRECT("'"&$C23&"'!$A:$A"),$F$2) -> 0 | W23: =SUMIFS(INDIRECT("'"&$C23&"'!$e:$e"),INDIRECT("'"&$C23&"'!$C:$C"),W$3,INDIRECT("'"&$C23&"'!$A:$A"),$F$2) -> 0
A24: =IF(B24=0,MATCH($F$2,INDIRECT("'"&C24&"'!A:A"),1),MATCH($F$2,INDIRECT("'"&C24&"'!A:A"),0)) -> 155 | B24: =COUNTIF(INDIRECT("'"&C24&"'!A:A"),$F$2) -> 0 | C24: 19 | F24: =VLOOKUP(C24,档案!A:B,2,FALSE) -> 建设银行绿地支行0564 | G24: =IF(B24=0,INDEX(INDIRECT("'"&$C24&"'!$F:$F"),$A24,1),INDEX(INDIRECT("'"&$C24&"'!$F:$F"),$A24-1,1)) -> 7497.59 | H24: =SUM(K24:O24) -> 0 | I24: =SUM(P24:W24) -> 0 | J24: =G24+H24-I24 -> 7497.59 | K24: =SUMIFS(INDIRECT("'"&$C24&"'!$D:$D"),INDIRECT("'"&$C24&"'!$C:$C"),K$3,INDIRECT("'"&$C24&"'!$A:$A"),$F$2) -> 0 | L24: =SUMIFS(INDIRECT("'"&$C24&"'!$D:$D"),INDIRECT("'"&$C24&"'!$C:$C"),L$3,INDIRECT("'"&$C24&"'!$A:$A"),$F$2) -> 0 | M24: =SUMIFS(INDIRECT("'"&$C24&"'!$D:$D"),INDIRECT("'"&$C24&"'!$C:$C"),M$3,INDIRECT("'"&$C24&"'!$A:$A"),$F$2) -> 0 | N24: =SUMIFS(INDIRECT("'"&$C24&"'!$D:$D"),INDIRECT("'"&$C24&"'!$C:$C"),N$3,INDIRECT("'"&$C24&"'!$A:$A"),$F$2) -> 0 | O24: =SUMIFS(INDIRECT("'"&$C24&"'!$D:$D"),INDIRECT("'"&$C24&"'!$C:$C"),O$3,INDIRECT("'"&$C24&"'!$A:$A"),$F$2) -> 0 | P24: =SUMIFS(INDIRECT("'"&$C24&"'!$e:$e"),INDIRECT("'"&$C24&"'!$C:$C"),P$3,INDIRECT("'"&$C24&"'!$A:$A"),$F$2) -> 0 | Q24: =SUMIFS(INDIRECT("'"&$C24&"'!$e:$e"),INDIRECT("'"&$C24&"'!$C:$C"),Q$3,INDIRECT("'"&$C24&"'!$A:$A"),$F$2) -> 0 | R24: =SUMIFS(INDIRECT("'"&$C24&"'!$e:$e"),INDIRECT("'"&$C24&"'!$C:$C"),R$3,INDIRECT("'"&$C24&"'!$A:$A"),$F$2) -> 0 | S24: =SUMIFS(INDIRECT("'"&$C24&"'!$e:$e"),INDIRECT("'"&$C24&"'!$C:$C"),S$3,INDIRECT("'"&$C24&"'!$A:$A"),$F$2) -> 0 | T24: =SUMIFS(INDIRECT("'"&$C24&"'!$e:$e"),INDIRECT("'"&$C24&"'!$C:$C"),T$3,INDIRECT("'"&$C24&"'!$A:$A"),$F$2) -> 0 | U24: =SUMIFS(INDIRECT("'"&$C24&"'!$e:$e"),INDIRECT("'"&$C24&"'!$C:$C"),U$3,INDIRECT("'"&$C24&"'!$A:$A"),$F$2) -> 0 | V24: =SUMIFS(INDIRECT("'"&$C24&"'!$e:$e"),INDIRECT("'"&$C24&"'!$C:$C"),V$3,INDIRECT("'"&$C24&"'!$A:$A"),$F$2) -> 0 | W24: =SUMIFS(INDIRECT("'"&$C24&"'!$e:$e"),INDIRECT("'"&$C24&"'!$C:$C"),W$3,INDIRECT("'"&$C24&"'!$A:$A"),$F$2) -> 0
A25: =IF(B25=0,MATCH($F$2,INDIRECT("'"&C25&"'!A:A"),1),MATCH($F$2,INDIRECT("'"&C25&"'!A:A"),0)) -> 191 | B25: =COUNTIF(INDIRECT("'"&C25&"'!A:A"),$F$2) -> 0 | C25: 20 | F25: =VLOOKUP(C25,档案!A:B,2,FALSE) -> 中信银行武汉东湖支行181028 | G25: =IF(B25=0,INDEX(INDIRECT("'"&$C25&"'!$F:$F"),$A25,1),INDEX(INDIRECT("'"&$C25&"'!$F:$F"),$A25-1,1)) -> 8121.22 | H25: =SUM(K25:O25) -> 0 | I25: =SUM(P25:W25) -> 0 | J25: =G25+H25-I25 -> 8121.22 | K25: =SUMIFS(INDIRECT("'"&$C25&"'!$D:$D"),INDIRECT("'"&$C25&"'!$C:$C"),K$3,INDIRECT("'"&$C25&"'!$A:$A"),$F$2) -> 0 | L25: =SUMIFS(INDIRECT("'"&$C25&"'!$D:$D"),INDIRECT("'"&$C25&"'!$C:$C"),L$3,INDIRECT("'"&$C25&"'!$A:$A"),$F$2) -> 0 | M25: =SUMIFS(INDIRECT("'"&$C25&"'!$D:$D"),INDIRECT("'"&$C25&"'!$C:$C"),M$3,INDIRECT("'"&$C25&"'!$A:$A"),$F$2) -> 0 | N25: =SUMIFS(INDIRECT("'"&$C25&"'!$D:$D"),INDIRECT("'"&$C25&"'!$C:$C"),N$3,INDIRECT("'"&$C25&"'!$A:$A"),$F$2) -> 0 | O25: =SUMIFS(INDIRECT("'"&$C25&"'!$D:$D"),INDIRECT("'"&$C25&"'!$C:$C"),O$3,INDIRECT("'"&$C25&"'!$A:$A"),$F$2) -> 0 | P25: =SUMIFS(INDIRECT("'"&$C25&"'!$e:$e"),INDIRECT("'"&$C25&"'!$C:$C"),P$3,INDIRECT("'"&$C25&"'!$A:$A"),$F$2) -> 0 | Q25: =SUMIFS(INDIRECT("'"&$C25&"'!$e:$e"),INDIRECT("'"&$C25&"'!$C:$C"),Q$3,INDIRECT("'"&$C25&"'!$A:$A"),$F$2) -> 0 | R25: =SUMIFS(INDIRECT("'"&$C25&"'!$e:$e"),INDIRECT("'"&$C25&"'!$C:$C"),R$3,INDIRECT("'"&$C25&"'!$A:$A"),$F$2) -> 0 | S25: =SUMIFS(INDIRECT("'"&$C25&"'!$e:$e"),INDIRECT("'"&$C25&"'!$C:$C"),S$3,INDIRECT("'"&$C25&"'!$A:$A"),$F$2) -> 0 | T25: =SUMIFS(INDIRECT("'"&$C25&"'!$e:$e"),INDIRECT("'"&$C25&"'!$C:$C"),T$3,INDIRECT("'"&$C25&"'!$A:$A"),$F$2) -> 0 | U25: =SUMIFS(INDIRECT("'"&$C25&"'!$e:$e"),INDIRECT("'"&$C25&"'!$C:$C"),U$3,INDIRECT("'"&$C25&"'!$A:$A"),$F$2) -> 0 | V25: =SUMIFS(INDIRECT("'"&$C25&"'!$e:$e"),INDIRECT("'"&$C25&"'!$C:$C"),V$3,INDIRECT("'"&$C25&"'!$A:$A"),$F$2) -> 0 | W25: =SUMIFS(INDIRECT("'"&$C25&"'!$e:$e"),INDIRECT("'"&$C25&"'!$C:$C"),W$3,INDIRECT("'"&$C25&"'!$A:$A"),$F$2) -> 0
A26: =IF(B26=0,MATCH($F$2,INDIRECT("'"&C26&"'!A:A"),1),MATCH($F$2,INDIRECT("'"&C26&"'!A:A"),0)) -> 8 | B26: =COUNTIF(INDIRECT("'"&C26&"'!A:A"),$F$2) -> 0 | C26: 21 | F26: =VLOOKUP(C26,档案!A:B,2,FALSE) -> 汉口银行光谷分行454891 | G26: =IF(B26=0,INDEX(INDIRECT("'"&$C26&"'!$F:$F"),$A26,1),INDEX(INDIRECT("'"&$C26&"'!$F:$F"),$A26-1,1)) -> 631.97 | H26: =SUM(K26:O26) -> 0 | I26: =SUM(P26:W26) -> 0 | J26: =G26+H26-I26 -> 631.97 | K26: =SUMIFS(INDIRECT("'"&$C26&"'!$D:$D"),INDIRECT("'"&$C26&"'!$C:$C"),K$3,INDIRECT("'"&$C26&"'!$A:$A"),$F$2) -> 0 | L26: =SUMIFS(INDIRECT("'"&$C26&"'!$D:$D"),INDIRECT("'"&$C26&"'!$C:$C"),L$3,INDIRECT("'"&$C26&"'!$A:$A"),$F$2) -> 0 | M26: =SUMIFS(INDIRECT("'"&$C26&"'!$D:$D"),INDIRECT("'"&$C26&"'!$C:$C"),M$3,INDIRECT("'"&$C26&"'!$A:$A"),$F$2) -> 0 | N26: =SUMIFS(INDIRECT("'"&$C26&"'!$D:$D"),INDIRECT("'"&$C26&"'!$C:$C"),N$3,INDIRECT("'"&$C26&"'!$A:$A"),$F$2) -> 0 | O26: =SUMIFS(INDIRECT("'"&$C26&"'!$D:$D"),INDIRECT("'"&$C26&"'!$C:$C"),O$3,INDIRECT("'"&$C26&"'!$A:$A"),$F$2) -> 0 | P26: =SUMIFS(INDIRECT("'"&$C26&"'!$e:$e"),INDIRECT("'"&$C26&"'!$C:$C"),P$3,INDIRECT("'"&$C26&"'!$A:$A"),$F$2) -> 0 | Q26: =SUMIFS(INDIRECT("'"&$C26&"'!$e:$e"),INDIRECT("'"&$C26&"'!$C:$C"),Q$3,INDIRECT("'"&$C26&"'!$A:$A"),$F$2) -> 0 | R26: =SUMIFS(INDIRECT("'"&$C26&"'!$e:$e"),INDIRECT("'"&$C26&"'!$C:$C"),R$3,INDIRECT("'"&$C26&"'!$A:$A"),$F$2) -> 0 | S26: =SUMIFS(INDIRECT("'"&$C26&"'!$e:$e"),INDIRECT("'"&$C26&"'!$C:$C"),S$3,INDIRECT("'"&$C26&"'!$A:$A"),$F$2) -> 0 | T26: =SUMIFS(INDIRECT("'"&$C26&"'!$e:$e"),INDIRECT("'"&$C26&"'!$C:$C"),T$3,INDIRECT("'"&$C26&"'!$A:$A"),$F$2) -> 0 | U26: =SUMIFS(INDIRECT("'"&$C26&"'!$e:$e"),INDIRECT("'"&$C26&"'!$C:$C"),U$3,INDIRECT("'"&$C26&"'!$A:$A"),$F$2) -> 0 | V26: =SUMIFS(INDIRECT("'"&$C26&"'!$e:$e"),INDIRECT("'"&$C26&"'!$C:$C"),V$3,INDIRECT("'"&$C26&"'!$A:$A"),$F$2) -> 0 | W26: =SUMIFS(INDIRECT("'"&$C26&"'!$e:$e"),INDIRECT("'"&$C26&"'!$C:$C"),W$3,INDIRECT("'"&$C26&"'!$A:$A"),$F$2) -> 0
A27: =IF(B27=0,MATCH($F$2,INDIRECT("'"&C27&"'!A:A"),1),MATCH($F$2,INDIRECT("'"&C27&"'!A:A"),0)) -> 3 | B27: =COUNTIF(INDIRECT("'"&C27&"'!A:A"),$F$2) -> 0 | C27: 22 | F27: =VLOOKUP(C27,档案!A:B,2,FALSE) -> 0 | G27: =IF(B27=0,INDEX(INDIRECT("'"&$C27&"'!$F:$F"),$A27,1),INDEX(INDIRECT("'"&$C27&"'!$F:$F"),$A27-1,1)) -> 0 | H27: =SUM(K27:O27) -> 0 | I27: =SUM(P27:W27) -> 0 | J27: =G27+H27-I27 -> 0 | K27: =SUMIFS(INDIRECT("'"&$C27&"'!$D:$D"),INDIRECT("'"&$C27&"'!$C:$C"),K$3,INDIRECT("'"&$C27&"'!$A:$A"),$F$2) -> 0 | L27: =SUMIFS(INDIRECT("'"&$C27&"'!$D:$D"),INDIRECT("'"&$C27&"'!$C:$C"),L$3,INDIRECT("'"&$C27&"'!$A:$A"),$F$2) -> 0 | M27: =SUMIFS(INDIRECT("'"&$C27&"'!$D:$D"),INDIRECT("'"&$C27&"'!$C:$C"),M$3,INDIRECT("'"&$C27&"'!$A:$A"),$F$2) -> 0 | N27: =SUMIFS(INDIRECT("'"&$C27&"'!$D:$D"),INDIRECT("'"&$C27&"'!$C:$C"),N$3,INDIRECT("'"&$C27&"'!$A:$A"),$F$2) -> 0 | O27: =SUMIFS(INDIRECT("'"&$C27&"'!$D:$D"),INDIRECT("'"&$C27&"'!$C:$C"),O$3,INDIRECT("'"&$C27&"'!$A:$A"),$F$2) -> 0 | P27: =SUMIFS(INDIRECT("'"&$C27&"'!$e:$e"),INDIRECT("'"&$C27&"'!$C:$C"),P$3,INDIRECT("'"&$C27&"'!$A:$A"),$F$2) -> 0 | Q27: =SUMIFS(INDIRECT("'"&$C27&"'!$e:$e"),INDIRECT("'"&$C27&"'!$C:$C"),Q$3,INDIRECT("'"&$C27&"'!$A:$A"),$F$2) -> 0 | R27: =SUMIFS(INDIRECT("'"&$C27&"'!$e:$e"),INDIRECT("'"&$C27&"'!$C:$C"),R$3,INDIRECT("'"&$C27&"'!$A:$A"),$F$2) -> 0 | S27: =SUMIFS(INDIRECT("'"&$C27&"'!$e:$e"),INDIRECT("'"&$C27&"'!$C:$C"),S$3,INDIRECT("'"&$C27&"'!$A:$A"),$F$2) -> 0 | T27: =SUMIFS(INDIRECT("'"&$C27&"'!$e:$e"),INDIRECT("'"&$C27&"'!$C:$C"),T$3,INDIRECT("'"&$C27&"'!$A:$A"),$F$2) -> 0 | U27: =SUMIFS(INDIRECT("'"&$C27&"'!$e:$e"),INDIRECT("'"&$C27&"'!$C:$C"),U$3,INDIRECT("'"&$C27&"'!$A:$A"),$F$2) -> 0 | V27: =SUMIFS(INDIRECT("'"&$C27&"'!$e:$e"),INDIRECT("'"&$C27&"'!$C:$C"),V$3,INDIRECT("'"&$C27&"'!$A:$A"),$F$2) -> 0 | W27: =SUMIFS(INDIRECT("'"&$C27&"'!$e:$e"),INDIRECT("'"&$C27&"'!$C:$C"),W$3,INDIRECT("'"&$C27&"'!$A:$A"),$F$2) -> 0
A28: =IF(B28=0,MATCH($F$2,INDIRECT("'"&C28&"'!A:A"),1),MATCH($F$2,INDIRECT("'"&C28&"'!A:A"),0)) -> 3 | B28: =COUNTIF(INDIRECT("'"&C28&"'!A:A"),$F$2) -> 0 | C28: 23 | F28: =VLOOKUP(C28,档案!A:B,2,FALSE) -> 0 | G28: =IF(B28=0,INDEX(INDIRECT("'"&$C28&"'!$F:$F"),$A28,1),INDEX(INDIRECT("'"&$C28&"'!$F:$F"),$A28-1,1)) -> 0 | H28: =SUM(K28:O28) -> 0 | I28: =SUM(P28:W28) -> 0 | J28: =G28+H28-I28 -> 0 | K28: =SUMIFS(INDIRECT("'"&$C28&"'!$D:$D"),INDIRECT("'"&$C28&"'!$C:$C"),K$3,INDIRECT("'"&$C28&"'!$A:$A"),$F$2) -> 0 | L28: =SUMIFS(INDIRECT("'"&$C28&"'!$D:$D"),INDIRECT("'"&$C28&"'!$C:$C"),L$3,INDIRECT("'"&$C28&"'!$A:$A"),$F$2) -> 0 | M28: =SUMIFS(INDIRECT("'"&$C28&"'!$D:$D"),INDIRECT("'"&$C28&"'!$C:$C"),M$3,INDIRECT("'"&$C28&"'!$A:$A"),$F$2) -> 0 | N28: =SUMIFS(INDIRECT("'"&$C28&"'!$D:$D"),INDIRECT("'"&$C28&"'!$C:$C"),N$3,INDIRECT("'"&$C28&"'!$A:$A"),$F$2) -> 0 | O28: =SUMIFS(INDIRECT("'"&$C28&"'!$D:$D"),INDIRECT("'"&$C28&"'!$C:$C"),O$3,INDIRECT("'"&$C28&"'!$A:$A"),$F$2) -> 0 | P28: =SUMIFS(INDIRECT("'"&$C28&"'!$e:$e"),INDIRECT("'"&$C28&"'!$C:$C"),P$3,INDIRECT("'"&$C28&"'!$A:$A"),$F$2) -> 0 | Q28: =SUMIFS(INDIRECT("'"&$C28&"'!$e:$e"),INDIRECT("'"&$C28&"'!$C:$C"),Q$3,INDIRECT("'"&$C28&"'!$A:$A"),$F$2) -> 0 | R28: =SUMIFS(INDIRECT("'"&$C28&"'!$e:$e"),INDIRECT("'"&$C28&"'!$C:$C"),R$3,INDIRECT("'"&$C28&"'!$A:$A"),$F$2) -> 0 | S28: =SUMIFS(INDIRECT("'"&$C28&"'!$e:$e"),INDIRECT("'"&$C28&"'!$C:$C"),S$3,INDIRECT("'"&$C28&"'!$A:$A"),$F$2) -> 0 | T28: =SUMIFS(INDIRECT("'"&$C28&"'!$e:$e"),INDIRECT("'"&$C28&"'!$C:$C"),T$3,INDIRECT("'"&$C28&"'!$A:$A"),$F$2) -> 0 | U28: =SUMIFS(INDIRECT("'"&$C28&"'!$e:$e"),INDIRECT("'"&$C28&"'!$C:$C"),U$3,INDIRECT("'"&$C28&"'!$A:$A"),$F$2) -> 0 | V28: =SUMIFS(INDIRECT("'"&$C28&"'!$e:$e"),INDIRECT("'"&$C28&"'!$C:$C"),V$3,INDIRECT("'"&$C28&"'!$A:$A"),$F$2) -> 0 | W28: =SUMIFS(INDIRECT("'"&$C28&"'!$e:$e"),INDIRECT("'"&$C28&"'!$C:$C"),W$3,INDIRECT("'"&$C28&"'!$A:$A"),$F$2) -> 0
A29: =IF(B29=0,MATCH($F$2,INDIRECT("'"&C29&"'!A:A"),1),MATCH($F$2,INDIRECT("'"&C29&"'!A:A"),0)) -> 3 | B29: =COUNTIF(INDIRECT("'"&C29&"'!A:A"),$F$2) -> 0 | C29: 24 | F29: =VLOOKUP(C29,档案!A:B,2,FALSE) -> 0 | G29: =IF(B29=0,INDEX(INDIRECT("'"&$C29&"'!$F:$F"),$A29,1),INDEX(INDIRECT("'"&$C29&"'!$F:$F"),$A29-1,1)) -> 0 | H29: =SUM(K29:O29) -> 0 | I29: =SUM(P29:W29) -> 0 | J29: =G29+H29-I29 -> 0 | K29: =SUMIFS(INDIRECT("'"&$C29&"'!$D:$D"),INDIRECT("'"&$C29&"'!$C:$C"),K$3,INDIRECT("'"&$C29&"'!$A:$A"),$F$2) -> 0 | L29: =SUMIFS(INDIRECT("'"&$C29&"'!$D:$D"),INDIRECT("'"&$C29&"'!$C:$C"),L$3,INDIRECT("'"&$C29&"'!$A:$A"),$F$2) -> 0 | M29: =SUMIFS(INDIRECT("'"&$C29&"'!$D:$D"),INDIRECT("'"&$C29&"'!$C:$C"),M$3,INDIRECT("'"&$C29&"'!$A:$A"),$F$2) -> 0 | N29: =SUMIFS(INDIRECT("'"&$C29&"'!$D:$D"),INDIRECT("'"&$C29&"'!$C:$C"),N$3,INDIRECT("'"&$C29&"'!$A:$A"),$F$2) -> 0 | O29: =SUMIFS(INDIRECT("'"&$C29&"'!$D:$D"),INDIRECT("'"&$C29&"'!$C:$C"),O$3,INDIRECT("'"&$C29&"'!$A:$A"),$F$2) -> 0 | P29: =SUMIFS(INDIRECT("'"&$C29&"'!$e:$e"),INDIRECT("'"&$C29&"'!$C:$C"),P$3,INDIRECT("'"&$C29&"'!$A:$A"),$F$2) -> 0 | Q29: =SUMIFS(INDIRECT("'"&$C29&"'!$e:$e"),INDIRECT("'"&$C29&"'!$C:$C"),Q$3,INDIRECT("'"&$C29&"'!$A:$A"),$F$2) -> 0 | R29: =SUMIFS(INDIRECT("'"&$C29&"'!$e:$e"),INDIRECT("'"&$C29&"'!$C:$C"),R$3,INDIRECT("'"&$C29&"'!$A:$A"),$F$2) -> 0 | S29: =SUMIFS(INDIRECT("'"&$C29&"'!$e:$e"),INDIRECT("'"&$C29&"'!$C:$C"),S$3,INDIRECT("'"&$C29&"'!$A:$A"),$F$2) -> 0 | T29: =SUMIFS(INDIRECT("'"&$C29&"'!$e:$e"),INDIRECT("'"&$C29&"'!$C:$C"),T$3,INDIRECT("'"&$C29&"'!$A:$A"),$F$2) -> 0 | U29: =SUMIFS(INDIRECT("'"&$C29&"'!$e:$e"),INDIRECT("'"&$C29&"'!$C:$C"),U$3,INDIRECT("'"&$C29&"'!$A:$A"),$F$2) -> 0 | V29: =SUMIFS(INDIRECT("'"&$C29&"'!$e:$e"),INDIRECT("'"&$C29&"'!$C:$C"),V$3,INDIRECT("'"&$C29&"'!$A:$A"),$F$2) -> 0 | W29: =SUMIFS(INDIRECT("'"&$C29&"'!$e:$e"),INDIRECT("'"&$C29&"'!$C:$C"),W$3,INDIRECT("'"&$C29&"'!$A:$A"),$F$2) -> 0
A30: =IF(B30=0,MATCH($F$2,INDIRECT("'"&C30&"'!A:A"),1),MATCH($F$2,INDIRECT("'"&C30&"'!A:A"),0)) -> #REF! | B30: =COUNTIF(INDIRECT("'"&C30&"'!A:A"),$F$2) -> #REF! | F30: 小计 | G30: =SUM(G23:G29) -> 17041.5 | H30: =SUM(K30:O30) -> 0 | I30: =SUM(P30:W30) -> 0 | J30: =G30+H30-I30 -> 17041.5 | K30: =SUM(K23:K29) -> 0 | L30: =SUM(L23:L29) -> 0 | M30: =SUM(M23:M29) -> 0 | N30: =SUM(N23:N29) -> 0 | O30: =SUM(O23:O29) -> 0 | P30: =SUM(P23:P29) -> 0 | Q30: =SUM(Q23:Q29) -> 0 | R30: =SUM(R23:R29) -> 0 | ... W30: =SUM(W23:W29) -> 0
A31: =IF(B31=0,MATCH($F$2,INDIRECT("'"&C31&"'!A:A"),1),MATCH($F$2,INDIRECT("'"&C31&"'!A:A"),0)) -> 16 | B31: =COUNTIF(INDIRECT("'"&C31&"'!A:A"),$F$2) -> 0 | C31: 25 | E31: =VLOOKUP(C31,档案!A:B,2,FALSE) -> 电子承兑汇票 | G31: =IF(B31=0,INDEX(INDIRECT("'"&$C31&"'!$F:$F"),$A31,1),INDEX(INDIRECT("'"&$C31&"'!$F:$F"),$A31-1,1)) -> 0 | H31: =SUM(K31:O31) -> 0 | I31: =SUM(P31:W31) -> 0 | J31: =G31+H31-I31 -> 0 | K31: =SUMIFS(INDIRECT("'"&$C31&"'!$D:$D"),INDIRECT("'"&$C31&"'!$C:$C"),K$3,INDIRECT("'"&$C31&"'!$A:$A"),$F$2) -> 0 | L31: =SUMIFS(INDIRECT("'"&$C31&"'!$D:$D"),INDIRECT("'"&$C31&"'!$C:$C"),L$3,INDIRECT("'"&$C31&"'!$A:$A"),$F$2) -> 0 | M31: =SUMIFS(INDIRECT("'"&$C31&"'!$D:$D"),INDIRECT("'"&$C31&"'!$C:$C"),M$3,INDIRECT("'"&$C31&"'!$A:$A"),$F$2) -> 0 | N31: =SUMIFS(INDIRECT("'"&$C31&"'!$D:$D"),INDIRECT("'"&$C31&"'!$C:$C"),N$3,INDIRECT("'"&$C31&"'!$A:$A"),$F$2) -> 0 | O31: =SUMIFS(INDIRECT("'"&$C31&"'!$D:$D"),INDIRECT("'"&$C31&"'!$C:$C"),O$3,INDIRECT("'"&$C31&"'!$A:$A"),$F$2) -> 0 | P31: =SUMIFS(INDIRECT("'"&$C31&"'!$e:$e"),INDIRECT("'"&$C31&"'!$C:$C"),P$3,INDIRECT("'"&$C31&"'!$A:$A"),$F$2) -> 0 | Q31: =SUMIFS(INDIRECT("'"&$C31&"'!$e:$e"),INDIRECT("'"&$C31&"'!$C:$C"),Q$3,INDIRECT("'"&$C31&"'!$A:$A"),$F$2) -> 0 | R31: =SUMIFS(INDIRECT("'"&$C31&"'!$e:$e"),INDIRECT("'"&$C31&"'!$C:$C"),R$3,INDIRECT("'"&$C31&"'!$A:$A"),$F$2) -> 0 | S31: =SUMIFS(INDIRECT("'"&$C31&"'!$e:$e"),INDIRECT("'"&$C31&"'!$C:$C"),S$3,INDIRECT("'"&$C31&"'!$A:$A"),$F$2) -> 0 | T31: =SUMIFS(INDIRECT("'"&$C31&"'!$e:$e"),INDIRECT("'"&$C31&"'!$C:$C"),T$3,INDIRECT("'"&$C31&"'!$A:$A"),$F$2) -> 0 | U31: =SUMIFS(INDIRECT("'"&$C31&"'!$e:$e"),INDIRECT("'"&$C31&"'!$C:$C"),U$3,INDIRECT("'"&$C31&"'!$A:$A"),$F$2) -> 0 | V31: =SUMIFS(INDIRECT("'"&$C31&"'!$e:$e"),INDIRECT("'"&$C31&"'!$C:$C"),V$3,INDIRECT("'"&$C31&"'!$A:$A"),$F$2) -> 0 | W31: =SUMIFS(INDIRECT("'"&$C31&"'!$e:$e"),INDIRECT("'"&$C31&"'!$C:$C"),W$3,INDIRECT("'"&$C31&"'!$A:$A"),$F$2) -> 0
