Workbook

Sheet 保证金登记
C1: 其他应收明细表
A2: 序号 | B2: 编号 | C2: 月份 | D2: 账龄 | E2: 支付日期 | F2: 部门 | G2: 经办人 | H2: 公司名称 | I2: 公司名称2 | J2: 支付金额 | K2: 公司 | L2: 支付方式 | M2: 支付类型 | N2: 退款金额/ 发票冲账 | O2: 未退余额 | P2: 退款时间 | Q2: 退回月份 | R2: 未退原因 | S2: 备注 | T2: 省份 | U2: 业务经理 | V2: 联系人 | W2: 中标结果 | X2: 业务员 | Y2: 支付状态
A3: 182 | B3: BZJ-0001 | C3: 42370 | D3: =IF(TODAY()-E3<60,"2个月内",IF(TODAY()-E3<180,"3-6个月",IF(TODAY()-E3<360,"6个月-1年","一年以上"))) -> 一年以上 | H3: 三门峡腾跃同力水泥有限公司 | I3: 三门峡腾跃同力水泥有限公司 | J3: 1000 | K3: 武汉 | L3: 期初余额 | M3: 投标保证金 | N3: 1000 | O3: =J3-N3 -> 0 | P3: 42826 | Q3: =P3 -> 42826 | R3: 找付款凭证 | T3: 河南省 | U3: =VLOOKUP(T3,[1]区域划分!$A$1:$C$39,3,0) -> 方渊
A4: 183 | B4: BZJ-0002 | C4: 42370 | D4: =IF(TODAY()-E4<60,"2个月内",IF(TODAY()-E4<180,"3-6个月",IF(TODAY()-E4<360,"6个月-1年","一年以上"))) -> 一年以上 | H4: 云南西南水泥有限公司 | I4: 云南西南水泥有限公司 | J4: 50000 | L4: 期初余额 | M4: 投标保证金 | N4: 50000 | O4: =J4-N4 -> 0 | P4: 44155 | Q4: =P4 -> 44155
A5: 184 | B5: BZJ-0003 | C5: 42370 | D5: =IF(TODAY()-E5<60,"2个月内",IF(TODAY()-E5<180,"3-6个月",IF(TODAY()-E5<360,"6个月-1年","一年以上"))) -> 一年以上 | H5: 淮北众城水泥有限责任公司 | I5: 淮北众城水泥有限责任公司 | J5: 3000 | K5: 武汉 | L5: 期初余额 | M5: 投标保证金 | O5: =J5-N5 -> 3000 | Q5: =P5 -> 0 | S5: 已被收购 | T5: 安徽省 | U5: =VLOOKUP(T5,[1]区域划分!$A$1:$C$39,3,0) -> 方渊
A6: 186 | B6: BZJ-0004 | C6: 42370 | D6: =IF(TODAY()-E6<60,"2个月内",IF(TODAY()-E6<180,"3-6个月",IF(TODAY()-E6<360,"6个月-1年","一年以上"))) -> 一年以上 | H6: 吉林亚泰（集团）股份有限公司物资经销分公司 | I6: 吉林亚泰集团物资贸易有限公司 | J6: 3800 | K6: 武汉 | L6: 期初余额 | M6: 投标保证金 | O6: =J6-N6 -> 3800 | Q6: =P6 -> 0 | R6: 预计2023.04或2023.05月退还，熊伟跟进中.客人无此笔,我司资料为期初数据有23800 | S6: 有凭证才可查询 | T6: 吉林省 | U6: =VLOOKUP(T6,[1]区域划分!$A$1:$C$39,3,0) -> 殷坤鹏 | V6: 张玉鹏13634307383
A7: 187 | B7: BZJ-0005 | C7: 42370 | D7: =IF(TODAY()-E7<60,"2个月内",IF(TODAY()-E7<180,"3-6个月",IF(TODAY()-E7<360,"6个月-1年","一年以上"))) -> 一年以上 | H7: 江苏永钢集团物资贸易有限公司 | I7: 江苏永钢集团物资贸易有限公司 | J7: 20000 | K7: 武汉 | L7: 期初余额 | M7: 投标保证金 | O7: =J7-N7 -> 20000 | Q7: =P7 -> 0 | R7: 对方财务查询并无此款 | S7: 对方财务查询并无此款 | T7: 江苏省 | U7: =VLOOKUP(T7,[1]区域划分!$A$1:$C$39,3,0) -> 龚运谱
A8: 188 | B8: BZJ-0006 | C8: 42370 | D8: =IF(TODAY()-E8<60,"2个月内",IF(TODAY()-E8<180,"3-6个月",IF(TODAY()-E8<360,"6个月-1年","一年以上"))) -> 一年以上 | H8: 酒泉钢铁（集团）有限公司 | I8: 酒泉钢铁（集团）有限公司 | J8: 300 | L8: 期初余额 | M8: 投标保证金 | N8: 300 | O8: =J8-N8 -> 0 | P8: 44728 | Q8: =P8 -> 44728 | S8: 可能是标书费
A9: 185 | B9: BZJ-0007 | C9: 42370 | D9: =IF(TODAY()-E9<60,"2个月内",IF(TODAY()-E9<180,"3-6个月",IF(TODAY()-E9<360,"6个月-1年","一年以上"))) -> 一年以上 | E9: 42390 | G9: 吴海波 | H9: 亚泰伊通 | I9: 亚泰集团伊通水泥有限公司 | J9: 20000 | K9: 武汉 | L9: 武汉对公 | M9: 投标保证金 | O9: =J9-N9 -> 20000 | Q9: =P9 -> 0 | R9: 预计2023.04或2023.05月退还，熊伟跟进中.客人无此笔,我司资料为期初数据有23800 | S9: 2016年1月42#凭证 | T9: 吉林省 | U9: =VLOOKUP(T9,[1]区域划分!$A$1:$C$39,3,0) -> 殷坤鹏 | V9: 张玉鹏13634307383
A10: 189 | B10: BZJ-0008 | C10: 42370 | D10: =IF(TODAY()-E10<60,"2个月内",IF(TODAY()-E10<180,"3-6个月",IF(TODAY()-E10<360,"6个月-1年","一年以上"))) -> 一年以上 | E10: 42400 | H10: 江苏沙钢集团有限公司 | I10: 江苏沙钢集团有限公司 | J10: 10000 | K10: 武汉 | L10: 平台上共8万 | M10: 投标保证金 | N10: 10000 | O10: =J10-N10 -> 0 | P10: 45923 | Q10: =P10 -> 45923 | R10: 长期投标不退 | S10: 投标保证金（前期借支2万元 后期借支5万元） 销售部查询系统里面有8万元保证金，长期投标不退 | T10: 江苏省 | U10: =VLOOKUP(T10,[1]区域划分!$A$1:$C$39,3,0) -> 龚运谱
A11: 1 | B11: BZJ-0009 | C11: 42887 | D11: =IF(TODAY()-E11<60,"2个月内",IF(TODAY()-E11<180,"3-6个月",IF(TODAY()-E11<360,"6个月-1年","一年以上"))) -> 一年以上 | E11: 42887 | H11: 江苏沙钢集团有限公司 | I11: 江苏沙钢集团有限公司 | J11: 10000 | K11: 武汉 | L11: 平台上共8万 | M11: 安全保证金 | N11: 10000 | O11: =J11-N11 -> 0 | P11: 45923 | Q11: =P11 -> 45923 | S11: 2025-9-23退回8万元 | T11: 江苏省 | U11: =VLOOKUP(T11,[1]区域划分!$A$1:$C$39,3,0) -> 龚运谱
A12: 190 | B12: BZJ-0010 | C12: 43466 | D12: =IF(TODAY()-E12<60,"2个月内",IF(TODAY()-E12<180,"3-6个月",IF(TODAY()-E12<360,"6个月-1年","一年以上"))) -> 一年以上 | E12: 43475 | G12: 汤勇华 | H12: 江苏沙钢集团有限公司 | I12: 江苏沙钢集团有限公司 | J12: 50000 | K12: 武汉 | L12: 平台上共8万 | M12: 投标保证金 | N12: 50000 | O12: =J12-N12 -> 0 | P12: 45923 | Q12: =P12 -> 45923 | R12: 长期投标不退 | S12: 投标保证金（前期借支2万元 后期借支5万元） 销售部查询系统里面有8万元保证金，长期投标不退 | T12: 江苏省 | U12: =VLOOKUP(T12,[1]区域划分!$A$1:$C$39,3,0) -> 龚运谱
A13: 5 | B13: BZJ-0011 | C13: 43101 | D13: =IF(TODAY()-E13<60,"2个月内",IF(TODAY()-E13<180,"3-6个月",IF(TODAY()-E13<360,"6个月-1年","一年以上"))) -> 一年以上 | E13: 43113 | F13: 生产部 | G13: 姜兵 | H13: 永登祁连山水泥有限公司 | I13: 永登祁连山水泥有限公司 | J13: 2000 | L13: 对公 | M13: 安全保证金 | N13: 2000 | O13: =J13-N13 -> 0 | P13: 44099 | Q13: =P13 -> 44099 | S13: 近期要施工
A14: 2 | B14: BZJ-0012 | C14: 43101 | D14: =IF(TODAY()-E14<60,"2个月内",IF(TODAY()-E14<180,"3-6个月",IF(TODAY()-E14<360,"6个月-1年","一年以上"))) -> 一年以上 | E14: 43124 | G14: 丁俊 | H14: 逸盛大化石化有限公司 | I14: 逸盛大化石化有限公司 | J14: 7000 | K14: 武汉 | M14: 安全保证金 | O14: 7000 | Q14: =P14 -> 0 | R14: 2023.03月殷总说之前做的质量有重大问题暂时不催 | S14: 2019年12月从丁俊个人转公司账7000元 | T14: 辽宁省 | U14: =VLOOKUP(T14,[1]区域划分!$A$1:$C$39,3,0) -> 殷坤鹏
A15: 10 | B15: BZJ-0013 | C15: 43252 | D15: =IF(TODAY()-E15<60,"2个月内",IF(TODAY()-E15<180,"3-6个月",IF(TODAY()-E15<360,"6个月-1年","一年以上"))) -> 一年以上 | E15: 43255 | F15: 生产一部 | G15: 汪勇刚 | H15: 德州中联大坝水泥有限公司 | I15: 德州中联大坝水泥有限公司 | J15: 15000 | K15: 武汉 | L15: 武汉对公 | M15: 安全保证金 | N15: 15000 | O15: =J15-N15 -> 0 | P15: 44936 | Q15: =P15 -> 44936 | S15: 武汉2018.06-40 | T15: 山东省 | U15: 李松林
A16: 15 | B16: BZJ-0014 | C16: 43313 | D16: =IF(TODAY()-E16<60,"2个月内",IF(TODAY()-E16<180,"3-6个月",IF(TODAY()-E16<360,"6个月-1年","一年以上"))) -> 一年以上 | E16: 43330 | F16: 生产部 | G16: 张子仪 | H16: 四川西南水泥有限公司 | I16: 四川西南水泥有限公司 | J16: 2000 | L16: 对公 | M16: 安全保证金 | N16: 2000 | O16: =J16-N16 -> 0 | P16: 43707 | Q16: =P16 -> 43707
A17: 6 | B17: BZJ-0015 | C17: 43374 | D17: =IF(TODAY()-E17<60,"2个月内",IF(TODAY()-E17<180,"3-6个月",IF(TODAY()-E17<360,"6个月-1年","一年以上"))) -> 一年以上 | E17: 43393 | F17: 生产部 | G17: 刘西 | H17: 新安中联万基水泥有限公司 | I17: 新安中联万基水泥有限公司 | J17: 3000 | L17: 对公 | M17: 安全保证金 | N17: 3000 | O17: =J17-N17 -> 0 | P17: 44126 | Q17: =P17 -> 44126 | S17: 施工质量问题无法办理
A18: 19 | B18: BZJ-0016 | C18: 43374 | D18: =IF(TODAY()-E18<60,"2个月内",IF(TODAY()-E18<180,"3-6个月",IF(TODAY()-E18<360,"6个月-1年","一年以上"))) -> 一年以上 | E18: 43404 | F18: 生产部 | G18: 丁俊 | H18: 逸盛大化石化有限公司 | I18: 逸盛大化石化有限公司 | J18: 7000 | L18: 个人 | M18: 安全保证金 | N18: 7000 | O18: =J18-N18 -> 0 | P18: 43480 | Q18: =P18 -> 43480
A19: 3 | B19: BZJ-0017 | C19: 43405 | D19: =IF(TODAY()-E19<60,"2个月内",IF(TODAY()-E19<180,"3-6个月",IF(TODAY()-E19<360,"6个月-1年","一年以上"))) -> 一年以上 | E19: 43414 | F19: 生产部 | G19: 丁俊 | H19: 韩城尧柏阳山庄水泥有限公司 | I19: 韩城尧柏阳山庄水泥有限公司 | J19: =20000 -> 20000 | K19: 武汉 | L19: 对公 | M19: 安全保证金 | N19: 20000 | O19: =J19-N19 -> 0 | P19: 43823 | Q19: =P19 -> 43823 | S19: 2019/12/24退19800
A20: 4 | B20: BZJ-0018 | C20: 43435 | D20: =IF(TODAY()-E20<60,"2个月内",IF(TODAY()-E20<180,"3-6个月",IF(TODAY()-E20<360,"6个月-1年","一年以上"))) -> 一年以上 | E20: 43446 | F20: 生产部 | G20: 冯海雄 | H20: 民和祁连山水泥有限公司 | I20: 民和祁连山水泥有限公司 | J20: 8000 | L20: 对公 | M20: 安全保证金 | N20: 8000 | O20: =J20-N20 -> 0 | P20: 43609 | Q20: =P20 -> 43609
A21: 12 | B21: BZJ-0019 | C21: 43466 | D21: =IF(TODAY()-E21<60,"2个月内",IF(TODAY()-E21<180,"3-6个月",IF(TODAY()-E21<360,"6个月-1年","一年以上"))) -> 一年以上 | E21: 43493 | F21: 生产部 | G21: 吴昌松 | H21: 冀东海天水泥闻喜有限公司 | I21: 冀东海天水泥闻喜有限公司 | J21: 10000 | L21: 对公 | M21: 安全保证金 | N21: 10000 | O21: =J21-N21 -> 0 | P21: 43664 | Q21: =P21 -> 43664
A22: 11 | B22: BZJ-0020 | C22: 43497 | D22: =IF(TODAY()-E22<60,"2个月内",IF(TODAY()-E22<180,"3-6个月",IF(TODAY()-E22<360,"6个月-1年","一年以上"))) -> 一年以上 | E22: 43511 | F22: 生产部 | G22: 汪勇刚 | H22: 贵州中诚水泥有限公司 | I22: 贵州中诚水泥有限公司 | J22: 3000 | L22: 对公 | M22: 安全保证金 | N22: 3000 | O22: =J22-N22 -> 0 | P22: 43646 | Q22: =P22 -> 43646
A23: 8 | B23: BZJ-0021 | C23: 43497 | D23: =IF(TODAY()-E23<60,"2个月内",IF(TODAY()-E23<180,"3-6个月",IF(TODAY()-E23<360,"6个月-1年","一年以上"))) -> 一年以上 | E23: 43516 | F23: 生产部 | G23: 覃延吉 | H23: 云南丽江西南水泥有限公司 | I23: 云南丽江西南水泥有限公司 | J23: 1000 | L23: 对公 | M23: 安全保证金 | N23: 1000 | O23: =J23-N23 -> 0 | P23: 43692 | Q23: =P23 -> 43692
A24: 14 | B24: BZJ-0022 | C24: 43525 | D24: =IF(TODAY()-E24<60,"2个月内",IF(TODAY()-E24<180,"3-6个月",IF(TODAY()-E24<360,"6个月-1年","一年以上"))) -> 一年以上 | E24: 43526 | F24: 生产部 | G24: 詹年喜 | H24: 邯郸涉县金隅水泥有限公司 | I24: 邯郸涉县金隅水泥有限公司 | J24: 2000 | L24: 对公 | M24: 安全保证金 | N24: 2000 | O24: =J24-N24 -> 0 | P24: 43698 | Q24: =P24 -> 43698
A25: 13 | B25: BZJ-0023 | C25: 43525 | D25: =IF(TODAY()-E25<60,"2个月内",IF(TODAY()-E25<180,"3-6个月",IF(TODAY()-E25<360,"6个月-1年","一年以上"))) -> 一年以上 | E25: 43530 | F25: 生产部 | G25: 詹年喜 | H25: 阳泉冀东水泥有限责任公司 | I25: 阳泉冀东水泥有限责任公司 | J25: 3000 | L25: 对公 | M25: 安全保证金 | N25: 3000 | O25: =J25-N25 -> 0 | P25: 43700 | Q25: =P25 -> 43700
A26: 9 | B26: BZJ-0024 | C26: 43525 | D26: =IF(TODAY()-E26<60,"2个月内",IF(TODAY()-E26<180,"3-6个月",IF(TODAY()-E26<360,"6个月-1年","一年以上"))) -> 一年以上 | E26: 43539 | F26: 生产部 | G26: 覃延吉 | H26: 河钢股份有限公司邯郸分公司 | I26: 河钢股份有限公司邯郸分公司 | J26: 10000 | L26: 对公 | M26: 安全保证金 | N26: 10000 | O26: =J26-N26 -> 0 | P26: 43613 | Q26: =P26 -> 43613
A27: 7 | B27: BZJ-0025 | C27: 43556 | D27: =IF(TODAY()-E27<60,"2个月内",IF(TODAY()-E27<180,"3-6个月",IF(TODAY()-E27<360,"6个月-1年","一年以上"))) -> 一年以上 | E27: 43557 | F27: 生产部 | G27: 石靖 | H27: 达州利森水泥有限公司 | I27: 达州利森水泥有限公司 | J27: 5000 | L27: 对公 | M27: 安全保证金 | N27: 5000 | O27: =J27-N27 -> 0 | P27: 43633 | Q27: =P27 -> 43633
A28: 16 | B28: BZJ-0026 | C28: 43556 | D28: =IF(TODAY()-E28<60,"2个月内",IF(TODAY()-E28<180,"3-6个月",IF(TODAY()-E28<360,"6个月-1年","一年以上"))) -> 一年以上 | E28: 43560 | F28: 总经办 | G28: 汤勇华 | H28: 张家港宏昌钢板有限公司 | I28: 张家港宏昌钢板有限公司 | J28: 124500 | K28: 武汉 | L28: 武汉对公 | M28: 安全保证金 | N28: 124500 | O28: =J28-N28 -> 0 | P28: 44890 | Q28: =P28 -> 44890 | S28: 武汉2019.4-50 | T28: 江苏省 | U28: 杨春龙 | V28: 预计2022.10月，收完全款后退回
A29: 194 | B29: BZJ-0027 | C29: 43556 | D29: =IF(TODAY()-E29<60,"2个月内",IF(TODAY()-E29<180,"3-6个月",IF(TODAY()-E29<360,"6个月-1年","一年以上"))) -> 一年以上 | E29: 43570 | G29: 夏锋泽 | H29: 四川西南水泥有限公司 | I29: 四川西南水泥有限公司 | J29: 10000 | L29: 对公 | M29: 投标保证金 | N29: 10000 | O29: =J29-N29 -> 0 | P29: 44064 | Q29: =P29 -> 44064 | S29: 长期投标不退
A30: 343 | B30: BZJ-0028 | C30: 43556 | D30: =IF(TODAY()-E30<60,"2个月内",IF(TODAY()-E30<180,"3-6个月",IF(TODAY()-E30<360,"6个月-1年","一年以上"))) -> 一年以上 | E30: 43585 | F30: 销售部 | G30: 李辉 | H30: 葛洲坝钟祥水泥有限公司 | I30: 葛洲坝钟祥水泥有限公司 | J30: 10000 | L30: 对公 | M30: 履约保证金 | N30: 10000 | O30: =J30-N30 -> 0 | P30: 43938 | Q30: =P30 -> 43938 | S30: 履约保证金
A31: 17 | B31: BZJ-0029 | C31: 43586 | D31: =IF(TODAY()-E31<60,"2个月内",IF(TODAY()-E31<180,"3-6个月",IF(TODAY()-E31<360,"6个月-1年","一年以上"))) -> 一年以上 | E31: 43600 | F31: 生产部 | G31: 李文池 | H31: 四川峨眉山西南水泥有限公司 | I31: 四川峨眉山西南水泥有限公司 | J31: 3000 | L31: 对公 | M31: 安全保证金 | N31: 3000 | O31: =J31-N31 -> 0 | P31: 43824 | Q31: =P31 -> 43824
A32: 18 | B32: BZJ-0030 | C32: 43586 | D32: =IF(TODAY()-E32<60,"2个月内",IF(TODAY()-E32<180,"3-6个月",IF(TODAY()-E32<360,"6个月-1年","一年以上"))) -> 一年以上 | E32: 43601 | F32: 生产部 | G32: 吴昌松 | H32: 云南昆钢嘉华水泥建材有限公司 | I32: 云南昆钢嘉华水泥建材有限公司 | J32: 3000 | L32: 对公 | M32: 安全保证金 | N32: 3000 | O32: =J32-N32 -> 0 | P32: 44484 | Q32: =P32 -> 44484
A33: 20 | B33: BZJ-0031 | C33: 43586 | D33: =IF(TODAY()-E33<60,"2个月内",IF(TODAY()-E33<180,"3-6个月",IF(TODAY()-E33<360,"6个月-1年","一年以上"))) -> 一年以上 | E33: 43601 | F33: 生产部 | G33: 余茶林 | H33: 汉中尧柏水泥有限公司 | I33: 汉中尧柏水泥有限公司 | J33: 10000 | L33: 对公 | M33: 安全保证金 | N33: 10000 | O33: =J33-N33 -> 0 | P33: 43973 | Q33: =P33 -> 43973
A34: 21 | B34: BZJ-0032 | C34: 43617 | D34: =IF(TODAY()-E34<60,"2个月内",IF(TODAY()-E34<180,"3-6个月",IF(TODAY()-E34<360,"6个月-1年","一年以上"))) -> 一年以上 | E34: 43621 | F34: 生产部 | G34: 房延云 | H34: 鲁南中联水泥有限公司 | I34: 鲁南中联水泥有限公司 | J34: 2000 | L34: 个人 | M34: 安全保证金 | N34: 2000 | O34: =J34-N34 -> 0 | P34: 43676 | Q34: =P34 -> 43676
A35: 22 | B35: BZJ-0033 | C35: 43617 | D35: =IF(TODAY()-E35<60,"2个月内",IF(TODAY()-E35<180,"3-6个月",IF(TODAY()-E35<360,"6个月-1年","一年以上"))) -> 一年以上 | E35: 43628 | F35: 生产部 | G35: 王小勇 | H35: 莒县中联水泥有限公司 | I35: 莒县中联水泥有限公司 | J35: 5000 | L35: 对公 | M35: 安全保证金 | N35: 5000 | O35: =J35-N35 -> 0 | P35: 43641 | Q35: =P35 -> 43641
A36: 23 | B36: BZJ-0034 | C36: 43617 | D36: =IF(TODAY()-E36<60,"2个月内",IF(TODAY()-E36<180,"3-6个月",IF(TODAY()-E36<360,"6个月-1年","一年以上"))) -> 一年以上 | E36: 43635 | F36: 生产部 | G36: 程时勇 | H36: 贵州沿河西南水泥有限公司 | I36: 贵州沿河西南水泥有限公司 | J36: 2000 | L36: 对公 | M36: 安全保证金 | N36: 2000 | O36: =J36-N36 -> 0 | P36: 43644 | Q36: =P36 -> 43644
A37: 24 | B37: BZJ-0035 | C37: 43617 | D37: =IF(TODAY()-E37<60,"2个月内",IF(TODAY()-E37<180,"3-6个月",IF(TODAY()-E37<360,"6个月-1年","一年以上"))) -> 一年以上 | E37: 43644 | F37: 生产部 | G37: 李文池 | H37: 西安蓝田尧柏水泥有限公司 | I37: 西安蓝田尧柏水泥有限公司 | J37: 10000 | L37: 对公 | M37: 安全保证金 | N37: 10000 | O37: =J37-N37 -> 0 | P37: 43703 | Q37: =P37 -> 43703
A38: 25 | B38: BZJ-0036 | C38: 43647 | D38: =IF(TODAY()-E38<60,"2个月内",IF(TODAY()-E38<180,"3-6个月",IF(TODAY()-E38<360,"6个月-1年","一年以上"))) -> 一年以上 | E38: 43657 | F38: 生产部 | G38: 吴昌松 | H38: 会东利森水泥有限公司 | I38: 会东利森水泥有限公司 | J38: 3000 | L38: 对公 | M38: 安全保证金 | N38: 3000 | O38: =J38-N38 -> 0 | P38: 43703 | Q38: =P38 -> 43703
A39: 27 | B39: BZJ-0037 | C39: 43647 | D39: =IF(TODAY()-E39<60,"2个月内",IF(TODAY()-E39<180,"3-6个月",IF(TODAY()-E39<360,"6个月-1年","一年以上"))) -> 一年以上 | E39: 43657 | F39: 生产部 | G39: 熊军 | H39: 冀东水泥铜川有限公司 | I39: 冀东水泥铜川有限公司 | J39: 1000 | L39: 个人 | M39: 安全保证金 | N39: 1000 | O39: =J39-N39 -> 0 | P39: 43661 | Q39: =P39 -> 43661
A40: 26 | B40: BZJ-0038 | C40: 43647 | D40: =IF(TODAY()-E40<60,"2个月内",IF(TODAY()-E40<180,"3-6个月",IF(TODAY()-E40<360,"6个月-1年","一年以上"))) -> 一年以上 | E40: 43664 | F40: 生产部 | G40: 吴昌松 | H40: 四川省绵竹澳东水泥有限责任公司 | I40: 四川省绵竹澳东水泥有限责任公司 | J40: 3000 | L40: 对公 | M40: 安全保证金 | N40: 3000 | O40: =J40-N40 -> 0 | P40: 43794 | Q40: =P40 -> 43794
...

Sheet 退款明细
A1: 保证金回款明细表
A2: 序列 | B2: 日期 | C2: 公司名称 | D2: 合同号 | E2: 回款类型 | F2: 回款金额（元） | G2: 回款方式 | H2: 备注 | I2: 保证金编号 | J2: 退款退还编号
A3: 1 | B3: 46029 | C3: 山东泰山钢铁集团有限公司 | E3: 转账 | F3: 5000 | G3: 林维转款（武汉浦发） | H3: 安全保证金 | K3: =_xlfn.XLOOKUP(I3,保证金登记!B:B,保证金登记!O:O) -> 0
A4: 2 | B4: 46045 | C4: 安徽省优质采科技发展有限责任公司 | E4: 转账 | F4: 20000 | G4: 武汉浦发 | H4: 投标保证金 | I4: BZJSQ-20251118-0158 | J4: BZJTH-20260126-0001 | K4: =_xlfn.XLOOKUP(I4,保证金登记!B:B,保证金登记!O:O) -> 0
A5: 3 | B5: 46049 | C5: 青海发投碱业有限公司 | E5: 转账 | F5: 28000 | G5: 武汉浦发 | H5: 履约保证金 | I5: BZJSQ-20250311-0032 | J5: BZJTH-20260128-0002 | K5: =_xlfn.XLOOKUP(I5,保证金登记!B:B,保证金登记!O:O) -> 0
A6: 4 | B6: 46049 | C6: 青海发投碱业有限公司 | E6: 转账 | F6: 18000 | G6: 武汉浦发 | H6: 安全保证金 | I6: BZJSQ-20250318-0040 | J6: BZJTH-20260128-0003 | K6: =_xlfn.XLOOKUP(I6,保证金登记!B:B,保证金登记!O:O) -> 0
A7: 5 | B7: 46049 | C7: 青海发投碱业有限公司 | E7: 转账 | F7: 17875 | G7: 武汉浦发 | H7: 履约保证金 | I7: BZJSQ-20250319-0045 | J7: BZJTH-20260128-0004 | K7: =_xlfn.XLOOKUP(I7,保证金登记!B:B,保证金登记!O:O) -> 0
A8: 6 | B8: 46049 | C8: 青海发投碱业有限公司 | E8: 转账 | F8: 50000 | G8: 武汉浦发 | H8: 安全保证金 | I8: BZJSQ-20250429-0069 | J8: BZJTH-20260128-0005 | K8: =_xlfn.XLOOKUP(I8,保证金登记!B:B,保证金登记!O:O) -> 0
A9: 7 | B9: 46049 | C9: 青海发投碱业有限公司 | E9: 转账 | F9: 9000 | G9: 武汉浦发 | H9: 安全保证金 | I9: BZJSQ-20250609-0092 | J9: BZJTH-20260128-0006 | K9: =_xlfn.XLOOKUP(I9,保证金登记!B:B,保证金登记!O:O) -> 0
A10: 8 | B10: 46049 | C10: 青海发投碱业有限公司 | E10: 转账 | F10: 7500 | G10: 武汉浦发 | H10: 安全保证金 | I10: BZJSQ-20250609-0095 | J10: BZJTH-20260128-0007 | K10: =_xlfn.XLOOKUP(I10,保证金登记!B:B,保证金登记!O:O) -> 0
A11: 9 | B11: 46049 | C11: 青海发投碱业有限公司 | E11: 转账 | F11: 8500 | G11: 武汉浦发 | H11: 安全保证金 | I11: BZJSQ-20250609-0098 | J11: BZJTH-20260128-0008 | K11: =_xlfn.XLOOKUP(I11,保证金登记!B:B,保证金登记!O:O) -> 0
A12: 10 | B12: 46049 | C12: 青海发投碱业有限公司 | E12: 转账 | F12: 16500 | G12: 武汉浦发 | H12: 安全保证金 | I12: BZJSQ-20250609-0101 | J12: BZJTH-20260128-0009 | K12: =_xlfn.XLOOKUP(I12,保证金登记!B:B,保证金登记!O:O) -> 0
A13: 11 | B13: 46049 | C13: 青海发投碱业有限公司 | E13: 转账 | F13: 500 | G13: 武汉浦发 | H13: 安全保证金 | I13: BZJSQ-20250623-0108 | J13: BZJTH-20260128-0010 | K13: =_xlfn.XLOOKUP(I13,保证金登记!B:B,保证金登记!O:O) -> 0
A14: 12 | B14: 46049 | C14: 青海发投碱业有限公司 | E14: 转账 | F14: 500 | G14: 武汉浦发 | H14: 安全保证金 | I14: BZJSQ-20250623-0109 | J14: BZJTH-20260128-0011 | K14: =_xlfn.XLOOKUP(I14,保证金登记!B:B,保证金登记!O:O) -> 0
A15: 13 | B15: 46049 | C15: 青海发投碱业有限公司 | E15: 转账 | F15: 500 | G15: 武汉浦发 | H15: 安全保证金 | I15: BZJSQ-20250623-0110 | J15: BZJTH-20260128-0012 | K15: =_xlfn.XLOOKUP(I15,保证金登记!B:B,保证金登记!O:O) -> 0
A16: 14 | B16: 46049 | C16: 青海发投碱业有限公司 | E16: 转账 | F16: 37000 | G16: 湖北岚丹中信 | H16: 安全保证金 | I16: BZJSQ-20250318-0038 | J16: BZJTH-20260128-0013 | K16: =_xlfn.XLOOKUP(I16,保证金登记!B:B,保证金登记!O:O) -> 0
A17: 15 | B17: 46049 | C17: 江苏唐电电力安装有限公司 | E17: 转账 | F17: 44000 | H17: 安全保证金 | I17: BZJSQ-20250416-0059 | J17: BZJTH-20260128-0014 | K17: =_xlfn.XLOOKUP(I17,保证金登记!B:B,保证金登记!O:O) -> 0
A18: 16 | B18: 46062 | C18: 新疆伊犁钢铁有限责任公司 | E18: 转账 | F18: 25536.9 | G18: 武汉浦发 | H18: 农民工工资保证金 | I18: BZJSQ-20241026-0115 | J18: BZJTH-20260209-0015 | K18: =_xlfn.XLOOKUP(I18,保证金登记!B:B,保证金登记!O:O) -> 0
A19: 17 | B19: 46062 | C19: 新疆伊犁钢铁有限责任公司 | E19: 转账 | F19: 4644.08 | G19: 武汉浦发 | H19: 农民工工资保证金 | I19: BZJSQ-20241026-0116 | J19: BZJTH-20260209-0016 | K19: =_xlfn.XLOOKUP(I19,保证金登记!B:B,保证金登记!O:O) -> 0
A20: 18 | B20: 46062 | C20: 新疆伊犁钢铁有限责任公司 | E20: 转账 | F20: 20838.39 | G20: 武汉浦发 | H20: 农民工工资保证金 | I20: BZJSQ-20241026-0117 | J20: BZJTH-20260209-0017 | K20: =_xlfn.XLOOKUP(I20,保证金登记!B:B,保证金登记!O:O) -> 0
A21: 19 | B21: 46062 | C21: 新疆伊犁钢铁有限责任公司 | E21: 转账 | F21: 15500 | G21: 武汉浦发 | H21: 履约保证金 | I21: BZJSQ-20241030-0122 | J21: BZJTH-20260209-0018 | K21: =_xlfn.XLOOKUP(I21,保证金登记!B:B,保证金登记!O:O) -> 0
A22: 20 | B22: 46062 | C22: 新疆伊犁钢铁有限责任公司 | E22: 转账 | F22: 69500 | G22: 武汉浦发 | H22: 履约保证金 | I22: BZJSQ-20241030-0123 | J22: BZJTH-20260209-0019 | K22: =_xlfn.XLOOKUP(I22,保证金登记!B:B,保证金登记!O:O) -> 0
A23: 21 | B23: 46062 | C23: 新疆伊犁钢铁有限责任公司 | E23: 转账 | F23: 85100 | G23: 武汉浦发 | H23: 履约保证金 | I23: BZJSQ-20241030-0124 | J23: BZJTH-20260209-0020 | K23: =_xlfn.XLOOKUP(I23,保证金登记!B:B,保证金登记!O:O) -> 0
A24: 22 | B24: 46080 | C24: 青海发投碱业有限公司 | E24: 转账 | F24: 6500 | G24: 湖北岚丹中信 | H24: 安全保证金 | I24: BZJSQ-20241230-0143 | J24: BZJTH-20260227-0021 | K24: =_xlfn.XLOOKUP(I24,保证金登记!B:B,保证金登记!O:O) -> 0
A25: 23 | B25: 46080 | C25: 青海发投碱业有限公司 | E25: 转账 | F25: 50000 | G25: 武汉浦发 | H25: 安全保证金 | I25: BZJSQ-20250114-0006 | J25: BZJTH-20260227-0022 | K25: =_xlfn.XLOOKUP(I25,保证金登记!B:B,保证金登记!O:O) -> 0
A26: 24 | B26: 46080 | C26: 青海发投碱业有限公司 | E26: 转账 | F26: 28000 | G26: 武汉浦发 | H26: 安全保证金 | I26: BZJSQ-20250311-0033 | J26: BZJTH-20260227-0023 | K26: =_xlfn.XLOOKUP(I26,保证金登记!B:B,保证金登记!O:O) -> 0
B27: 46081 | C27: 青海发投碱业有限公司 | E27: 转账 | F27: 11500 | H27: 履约保证金 | I27: BZJSQ-20231208-0777 | J27: BZJTH-20260228-0024 | K27: =_xlfn.XLOOKUP(I27,保证金登记!B:B,保证金登记!O:O) -> 0
B28: 46081 | C28: 青海发投碱业有限公司 | E28: 转账 | F28: 14300 | H28: 履约保证金 | I28: BZJSQ-20240508-0076 | J28: BZJTH-20260228-0025 | K28: =_xlfn.XLOOKUP(I28,保证金登记!B:B,保证金登记!O:O) -> 0
B29: 46081 | C29: 青海发投碱业有限公司 | E29: 转账 | F29: 14300 | H29: 农民工工资保证金 | I29: BZJSQ-20240508-0077 | J29: BZJTH-20260228-0026 | K29: =_xlfn.XLOOKUP(I29,保证金登记!B:B,保证金登记!O:O) -> 0
B30: 46081 | C30: 青海发投碱业有限公司 | E30: 转账 | F30: 50000 | H30: 履约保证金 | I30: BZJSQ-20250114-0005 | J30: BZJTH-20260228-0027 | K30: =_xlfn.XLOOKUP(I30,保证金登记!B:B,保证金登记!O:O) -> 0
B31: 46090 | C31: 安徽省优质采科技发展有限责任公司 | E31: 转账 | F31: 2000 | G31: 武汉浦发 | H31: 保证金 | I31: BZJSQ-20260227-0008 | J31: BZJTH-20260310-0028 | K31: =_xlfn.XLOOKUP(I31,保证金登记!B:B,保证金登记!O:O) -> 0
B32: 46094 | C32: 新疆宜化化工有限公司 | E32: 转账 | F32: 5500 | G32: 武汉浦发 | H32: 保证金 | I32: BZJSQ-20260129-0001 | J32: BZJTH-20260314-0029 | K32: =_xlfn.XLOOKUP(I32,保证金登记!B:B,保证金登记!O:O) -> 0
B33: 46094 | C33: 新疆宜化化工有限公司 | E33: 转账 | F33: 10000 | G33: 武汉浦发 | H33: 保证金 | I33: BZJSQ-20260209-0004 | J33: BZJTH-20260314-0030 | K33: =_xlfn.XLOOKUP(I33,保证金登记!B:B,保证金登记!O:O) -> 0
B34: 46097 | C34: 新疆宜化化工有限公司 | E34: 转账 | F34: 22000 | G34: 武汉浦发 | H34: 保证金 | I34: BZJSQ-20260209-0003 | J34: ZJTH-20260316-0031 | K34: =_xlfn.XLOOKUP(I34,保证金登记!B:B,保证金登记!O:O) -> 0
B35: 46099 | C35: 新疆宜化化工有限公司 | E35: 转账 | F35: 35000 | G35: 武汉浦发 | H35: 保证金 | I35: BZJSQ-20251225-0163 | J35: BZJTH-20260318-0032 | K35: =_xlfn.XLOOKUP(I35,保证金登记!B:B,保证金登记!O:O) -> 0
B36: 46106 | C36: 佛山住商肥料有限公司 | E36: 转账 | F36: 3000 | H36: 保证金 | I36: BZJSQ-20260303-0014 | J36: BZJTH-20260325-0033 | K36: =_xlfn.XLOOKUP(I36,保证金登记!B:B,保证金登记!O:O) -> 0
B37: 46119 | C37: 成都云图控股股份有限公司 | E37: 转账 | F37: 30000 | G37: 湖北岚丹中信 | H37: 投标保证金 | I37: BZJSQ-20260311-0017 | J37: BZJTH-20260407-0034 | K37: =_xlfn.XLOOKUP(I37,保证金登记!B:B,保证金登记!O:O) -> 0
B38: 46119 | C38: 江西省精彩纵横采购咨询有限公司 | E38: 转账 | F38: 2000.26 | G38: 武汉浦发 | H38: 投标保证金 | I38: BZJSQ-20260302-0013 | J38: BZJTH-20260407-0035 | K38: =_xlfn.XLOOKUP(I38,保证金登记!B:B,保证金登记!O:O) -> -0.26
B39: 46121 | C39: 江苏唐电电力安装有限公司 | E39: 转账 | F39: 8000 | G39: 王先梅 | H39: 投标保证金 | I39: BZJSQ-20260224-0007 | J39: BZJTH-20260409-0036 | K39: =_xlfn.XLOOKUP(I39,保证金登记!B:B,保证金登记!O:O) -> 0
B40: 46120 | C40: 江西省精彩纵横采购咨询有限公司 | E40: 转账 | F40: 4000.16 | G40: 武汉浦发 | H40: 保证金 | I40: BZJSQ-20260403-0027 | J40: BZJTH-20260414-0037 | K40: =_xlfn.XLOOKUP(I40,保证金登记!B:B,保证金登记!O:O) -> -0.16
...

Sheet 标书
C1: 其他应收明细表
A2: 序号 | B2: 编号 | C2: 月份 | D2: 账龄 | E2: 支付日期 | F2: 部门 | G2: 经办人 | H2: 公司名称 | I2: 公司名称2 | J2: 支付金额 | K2: 公司 | L2: 支付方式 | M2: 支付类型 | N2: 退款金额/ 发票冲账 | O2: 未退余额 | P2: 退款时间 | Q2: 退回月份 | R2: 未退原因 | S2: 备注 | T2: 省份 | U2: 业务经理 | V2: 联系人 | W2: 中标结果 | X2: 业务员
A3: 182 | B3: BZJ-0001 | C3: 42370 | D3: =IF(TODAY()-E3<60,"2个月内",IF(TODAY()-E3<180,"3-6个月",IF(TODAY()-E3<360,"6个月-1年","一年以上"))) -> 一年以上 | H3: 三门峡腾跃同力水泥有限公司 | I3: 三门峡腾跃同力水泥有限公司 | J3: 1000 | K3: 武汉 | L3: 期初余额 | M3: 投标保证金 | O3: =J3-N3 -> 1000 | Q3: =P3 -> 0 | R3: 找付款凭证 | T3: 河南省 | U3: =VLOOKUP(T3,[1]区域划分!$A$1:$C$39,3,0) -> 方渊
A4: 183 | B4: BZJ-0002 | C4: 42370 | D4: =IF(TODAY()-E4<60,"2个月内",IF(TODAY()-E4<180,"3-6个月",IF(TODAY()-E4<360,"6个月-1年","一年以上"))) -> 一年以上 | H4: 云南西南水泥有限公司 | I4: 云南西南水泥有限公司 | J4: 50000 | L4: 期初余额 | M4: 投标保证金 | N4: 50000 | O4: =J4-N4 -> 0 | P4: 44155 | Q4: =P4 -> 44155
A5: 184 | B5: BZJ-0003 | C5: 42370 | D5: =IF(TODAY()-E5<60,"2个月内",IF(TODAY()-E5<180,"3-6个月",IF(TODAY()-E5<360,"6个月-1年","一年以上"))) -> 一年以上 | H5: 淮北众城水泥有限责任公司 | I5: 淮北众城水泥有限责任公司 | J5: 3000 | K5: 武汉 | L5: 期初余额 | M5: 投标保证金 | O5: =J5-N5 -> 3000 | Q5: =P5 -> 0 | S5: 已被收购 | T5: 安徽省 | U5: =VLOOKUP(T5,[1]区域划分!$A$1:$C$39,3,0) -> 方渊
A6: 186 | B6: BZJ-0004 | C6: 42370 | D6: =IF(TODAY()-E6<60,"2个月内",IF(TODAY()-E6<180,"3-6个月",IF(TODAY()-E6<360,"6个月-1年","一年以上"))) -> 一年以上 | H6: 吉林亚泰（集团）股份有限公司物资经销分公司 | I6: 吉林亚泰集团物资贸易有限公司 | J6: 3800 | K6: 武汉 | L6: 期初余额 | M6: 投标保证金 | O6: =J6-N6 -> 3800 | Q6: =P6 -> 0 | R6: 预计2023.04或2023.05月退还，熊伟跟进中.客人无此笔,我司资料为期初数据有23800 | S6: 有凭证才可查询 | T6: 吉林省 | U6: =VLOOKUP(T6,[1]区域划分!$A$1:$C$39,3,0) -> 殷坤鹏 | V6: 张玉鹏13634307383
A7: 187 | B7: BZJ-0005 | C7: 42370 | D7: =IF(TODAY()-E7<60,"2个月内",IF(TODAY()-E7<180,"3-6个月",IF(TODAY()-E7<360,"6个月-1年","一年以上"))) -> 一年以上 | H7: 江苏永钢集团物资贸易有限公司 | I7: 江苏永钢集团物资贸易有限公司 | J7: 20000 | K7: 武汉 | L7: 期初余额 | M7: 投标保证金 | O7: =J7-N7 -> 20000 | Q7: =P7 -> 0 | R7: 对方财务查询并无此款 | S7: 对方财务查询并无此款 | T7: 江苏省 | U7: =VLOOKUP(T7,[1]区域划分!$A$1:$C$39,3,0) -> 龚运谱
A8: 188 | B8: BZJ-0006 | C8: 42370 | D8: =IF(TODAY()-E8<60,"2个月内",IF(TODAY()-E8<180,"3-6个月",IF(TODAY()-E8<360,"6个月-1年","一年以上"))) -> 一年以上 | H8: 酒泉钢铁（集团）有限公司 | I8: 酒泉钢铁（集团）有限公司 | J8: 300 | L8: 期初余额 | M8: 投标保证金 | N8: 300 | O8: =J8-N8 -> 0 | P8: 44728 | Q8: =P8 -> 44728 | S8: 可能是标书费
A9: 185 | B9: BZJ-0007 | C9: 42370 | D9: =IF(TODAY()-E9<60,"2个月内",IF(TODAY()-E9<180,"3-6个月",IF(TODAY()-E9<360,"6个月-1年","一年以上"))) -> 一年以上 | E9: 42390 | G9: 吴海波 | H9: 亚泰伊通 | I9: 亚泰集团伊通水泥有限公司 | J9: 20000 | K9: 武汉 | L9: 武汉对公 | M9: 投标保证金 | O9: =J9-N9 -> 20000 | Q9: =P9 -> 0 | R9: 预计2023.04或2023.05月退还，熊伟跟进中.客人无此笔,我司资料为期初数据有23800 | S9: 2016年1月42#凭证 | T9: 吉林省 | U9: =VLOOKUP(T9,[1]区域划分!$A$1:$C$39,3,0) -> 殷坤鹏 | V9: 张玉鹏13634307383
A10: 189 | B10: BZJ-0008 | C10: 42370 | D10: =IF(TODAY()-E10<60,"2个月内",IF(TODAY()-E10<180,"3-6个月",IF(TODAY()-E10<360,"6个月-1年","一年以上"))) -> 一年以上 | E10: 42400 | H10: 江苏沙钢集团有限公司 | I10: 江苏沙钢集团有限公司 | J10: 10000 | K10: 武汉 | L10: 平台上共8万 | M10: 投标保证金 | O10: =J10-N10 -> 10000 | Q10: =P10 -> 0 | R10: 长期投标不退 | S10: 投标保证金（前期借支2万元 后期借支5万元） 销售部查询系统里面有8万元保证金，长期投标不退 | T10: 江苏省 | U10: =VLOOKUP(T10,[1]区域划分!$A$1:$C$39,3,0) -> 龚运谱
A11: 1 | B11: BZJ-0009 | C11: 42887 | D11: =IF(TODAY()-E11<60,"2个月内",IF(TODAY()-E11<180,"3-6个月",IF(TODAY()-E11<360,"6个月-1年","一年以上"))) -> 一年以上 | E11: 42887 | H11: 江苏沙钢集团有限公司 | I11: 江苏沙钢集团有限公司 | J11: 10000 | K11: 武汉 | L11: 平台上共8万 | M11: 安全保证金 | O11: 10000 | Q11: =P11 -> 0 | T11: 江苏省 | U11: =VLOOKUP(T11,[1]区域划分!$A$1:$C$39,3,0) -> 龚运谱
A12: 190 | B12: BZJ-0010 | C12: 43466 | D12: =IF(TODAY()-E12<60,"2个月内",IF(TODAY()-E12<180,"3-6个月",IF(TODAY()-E12<360,"6个月-1年","一年以上"))) -> 一年以上 | E12: 43475 | G12: 汤勇华 | H12: 江苏沙钢集团有限公司 | I12: 江苏沙钢集团有限公司 | J12: 50000 | K12: 武汉 | L12: 平台上共8万 | M12: 投标保证金 | O12: =J12-N12 -> 50000 | Q12: =P12 -> 0 | R12: 长期投标不退 | S12: 投标保证金（前期借支2万元 后期借支5万元） 销售部查询系统里面有8万元保证金，长期投标不退 | T12: 江苏省 | U12: =VLOOKUP(T12,[1]区域划分!$A$1:$C$39,3,0) -> 龚运谱
A13: 5 | B13: BZJ-0011 | C13: 43101 | D13: =IF(TODAY()-E13<60,"2个月内",IF(TODAY()-E13<180,"3-6个月",IF(TODAY()-E13<360,"6个月-1年","一年以上"))) -> 一年以上 | E13: 43113 | F13: 生产部 | G13: 姜兵 | H13: 永登祁连山水泥有限公司 | I13: 永登祁连山水泥有限公司 | J13: 2000 | L13: 对公 | M13: 安全保证金 | N13: 2000 | O13: =J13-N13 -> 0 | P13: 44099 | Q13: =P13 -> 44099 | S13: 近期要施工
A14: 2 | B14: BZJ-0012 | C14: 43101 | D14: =IF(TODAY()-E14<60,"2个月内",IF(TODAY()-E14<180,"3-6个月",IF(TODAY()-E14<360,"6个月-1年","一年以上"))) -> 一年以上 | E14: 43124 | G14: 丁俊 | H14: 逸盛大化石化有限公司 | I14: 逸盛大化石化有限公司 | J14: 7000 | K14: 武汉 | M14: 安全保证金 | O14: 7000 | Q14: =P14 -> 0 | R14: 2023.03月殷总说之前做的质量有重大问题暂时不催 | S14: 2019年12月从丁俊个人转公司账7000元 | T14: 辽宁省 | U14: =VLOOKUP(T14,[1]区域划分!$A$1:$C$39,3,0) -> 殷坤鹏
A15: 10 | B15: BZJ-0013 | C15: 43252 | D15: =IF(TODAY()-E15<60,"2个月内",IF(TODAY()-E15<180,"3-6个月",IF(TODAY()-E15<360,"6个月-1年","一年以上"))) -> 一年以上 | E15: 43255 | F15: 生产一部 | G15: 汪勇刚 | H15: 德州中联大坝水泥有限公司 | I15: 德州中联大坝水泥有限公司 | J15: 15000 | K15: 武汉 | L15: 武汉对公 | M15: 安全保证金 | N15: 15000 | O15: =J15-N15 -> 0 | P15: 44936 | Q15: =P15 -> 44936 | S15: 武汉2018.06-40 | T15: 山东省 | U15: 李松林
A16: 15 | B16: BZJ-0014 | C16: 43313 | D16: =IF(TODAY()-E16<60,"2个月内",IF(TODAY()-E16<180,"3-6个月",IF(TODAY()-E16<360,"6个月-1年","一年以上"))) -> 一年以上 | E16: 43330 | F16: 生产部 | G16: 张子仪 | H16: 四川西南水泥有限公司 | I16: 四川西南水泥有限公司 | J16: 2000 | L16: 对公 | M16: 安全保证金 | N16: 2000 | O16: =J16-N16 -> 0 | P16: 43707 | Q16: =P16 -> 43707
A17: 6 | B17: BZJ-0015 | C17: 43374 | D17: =IF(TODAY()-E17<60,"2个月内",IF(TODAY()-E17<180,"3-6个月",IF(TODAY()-E17<360,"6个月-1年","一年以上"))) -> 一年以上 | E17: 43393 | F17: 生产部 | G17: 刘西 | H17: 新安中联万基水泥有限公司 | I17: 新安中联万基水泥有限公司 | J17: 3000 | L17: 对公 | M17: 安全保证金 | N17: 3000 | O17: =J17-N17 -> 0 | P17: 44126 | Q17: =P17 -> 44126 | S17: 施工质量问题无法办理
A18: 19 | B18: BZJ-0016 | C18: 43374 | D18: =IF(TODAY()-E18<60,"2个月内",IF(TODAY()-E18<180,"3-6个月",IF(TODAY()-E18<360,"6个月-1年","一年以上"))) -> 一年以上 | E18: 43404 | F18: 生产部 | G18: 丁俊 | H18: 逸盛大化石化有限公司 | I18: 逸盛大化石化有限公司 | J18: 7000 | L18: 个人 | M18: 安全保证金 | N18: 7000 | O18: =J18-N18 -> 0 | P18: 43480 | Q18: =P18 -> 43480
A19: 3 | B19: BZJ-0017 | C19: 43405 | D19: =IF(TODAY()-E19<60,"2个月内",IF(TODAY()-E19<180,"3-6个月",IF(TODAY()-E19<360,"6个月-1年","一年以上"))) -> 一年以上 | E19: 43414 | F19: 生产部 | G19: 丁俊 | H19: 韩城尧柏阳山庄水泥有限公司 | I19: 韩城尧柏阳山庄水泥有限公司 | J19: =20000 -> 20000 | K19: 武汉 | L19: 对公 | M19: 安全保证金 | N19: 20000 | O19: =J19-N19 -> 0 | Q19: =P19 -> 0 | S19: 2019/12/24退19800
A20: 4 | B20: BZJ-0018 | C20: 43435 | D20: =IF(TODAY()-E20<60,"2个月内",IF(TODAY()-E20<180,"3-6个月",IF(TODAY()-E20<360,"6个月-1年","一年以上"))) -> 一年以上 | E20: 43446 | F20: 生产部 | G20: 冯海雄 | H20: 民和祁连山水泥有限公司 | I20: 民和祁连山水泥有限公司 | J20: 8000 | L20: 对公 | M20: 安全保证金 | N20: 8000 | O20: =J20-N20 -> 0 | P20: 43609 | Q20: =P20 -> 43609
A21: 12 | B21: BZJ-0019 | C21: 43466 | D21: =IF(TODAY()-E21<60,"2个月内",IF(TODAY()-E21<180,"3-6个月",IF(TODAY()-E21<360,"6个月-1年","一年以上"))) -> 一年以上 | E21: 43493 | F21: 生产部 | G21: 吴昌松 | H21: 冀东海天水泥闻喜有限公司 | I21: 冀东海天水泥闻喜有限公司 | J21: 10000 | L21: 对公 | M21: 安全保证金 | N21: 10000 | O21: =J21-N21 -> 0 | P21: 43664 | Q21: =P21 -> 43664
A22: 11 | B22: BZJ-0020 | C22: 43497 | D22: =IF(TODAY()-E22<60,"2个月内",IF(TODAY()-E22<180,"3-6个月",IF(TODAY()-E22<360,"6个月-1年","一年以上"))) -> 一年以上 | E22: 43511 | F22: 生产部 | G22: 汪勇刚 | H22: 贵州中诚水泥有限公司 | I22: 贵州中诚水泥有限公司 | J22: 3000 | L22: 对公 | M22: 安全保证金 | N22: 3000 | O22: =J22-N22 -> 0 | P22: 43646 | Q22: =P22 -> 43646
A23: 8 | B23: BZJ-0021 | C23: 43497 | D23: =IF(TODAY()-E23<60,"2个月内",IF(TODAY()-E23<180,"3-6个月",IF(TODAY()-E23<360,"6个月-1年","一年以上"))) -> 一年以上 | E23: 43516 | F23: 生产部 | G23: 覃延吉 | H23: 云南丽江西南水泥有限公司 | I23: 云南丽江西南水泥有限公司 | J23: 1000 | L23: 对公 | M23: 安全保证金 | N23: 1000 | O23: =J23-N23 -> 0 | P23: 43692 | Q23: =P23 -> 43692
A24: 14 | B24: BZJ-0022 | C24: 43525 | D24: =IF(TODAY()-E24<60,"2个月内",IF(TODAY()-E24<180,"3-6个月",IF(TODAY()-E24<360,"6个月-1年","一年以上"))) -> 一年以上 | E24: 43526 | F24: 生产部 | G24: 詹年喜 | H24: 邯郸涉县金隅水泥有限公司 | I24: 邯郸涉县金隅水泥有限公司 | J24: 2000 | L24: 对公 | M24: 安全保证金 | N24: 2000 | O24: =J24-N24 -> 0 | P24: 43698 | Q24: =P24 -> 43698
A25: 13 | B25: BZJ-0023 | C25: 43525 | D25: =IF(TODAY()-E25<60,"2个月内",IF(TODAY()-E25<180,"3-6个月",IF(TODAY()-E25<360,"6个月-1年","一年以上"))) -> 一年以上 | E25: 43530 | F25: 生产部 | G25: 詹年喜 | H25: 阳泉冀东水泥有限责任公司 | I25: 阳泉冀东水泥有限责任公司 | J25: 3000 | L25: 对公 | M25: 安全保证金 | N25: 3000 | O25: =J25-N25 -> 0 | P25: 43700 | Q25: =P25 -> 43700
A26: 9 | B26: BZJ-0024 | C26: 43525 | D26: =IF(TODAY()-E26<60,"2个月内",IF(TODAY()-E26<180,"3-6个月",IF(TODAY()-E26<360,"6个月-1年","一年以上"))) -> 一年以上 | E26: 43539 | F26: 生产部 | G26: 覃延吉 | H26: 河钢股份有限公司邯郸分公司 | I26: 河钢股份有限公司邯郸分公司 | J26: 10000 | L26: 对公 | M26: 安全保证金 | N26: 10000 | O26: =J26-N26 -> 0 | P26: 43613 | Q26: =P26 -> 43613
A27: 7 | B27: BZJ-0025 | C27: 43556 | D27: =IF(TODAY()-E27<60,"2个月内",IF(TODAY()-E27<180,"3-6个月",IF(TODAY()-E27<360,"6个月-1年","一年以上"))) -> 一年以上 | E27: 43557 | F27: 生产部 | G27: 石靖 | H27: 达州利森水泥有限公司 | I27: 达州利森水泥有限公司 | J27: 5000 | L27: 对公 | M27: 安全保证金 | N27: 5000 | O27: =J27-N27 -> 0 | P27: 43633 | Q27: =P27 -> 43633
A28: 16 | B28: BZJ-0026 | C28: 43556 | D28: =IF(TODAY()-E28<60,"2个月内",IF(TODAY()-E28<180,"3-6个月",IF(TODAY()-E28<360,"6个月-1年","一年以上"))) -> 一年以上 | E28: 43560 | F28: 总经办 | G28: 汤勇华 | H28: 张家港宏昌钢板有限公司 | I28: 张家港宏昌钢板有限公司 | J28: 124500 | K28: 武汉 | L28: 武汉对公 | M28: 安全保证金 | N28: 124500 | O28: =J28-N28 -> 0 | P28: 44890 | Q28: =P28 -> 44890 | S28: 武汉2019.4-50 | T28: 江苏省 | U28: 杨春龙 | V28: 预计2022.10月，收完全款后退回
A29: 194 | B29: BZJ-0027 | C29: 43556 | D29: =IF(TODAY()-E29<60,"2个月内",IF(TODAY()-E29<180,"3-6个月",IF(TODAY()-E29<360,"6个月-1年","一年以上"))) -> 一年以上 | E29: 43570 | G29: 夏锋泽 | H29: 四川西南水泥有限公司 | I29: 四川西南水泥有限公司 | J29: 10000 | L29: 对公 | M29: 投标保证金 | N29: 10000 | O29: =J29-N29 -> 0 | P29: 44064 | Q29: =P29 -> 44064 | S29: 长期投标不退
A30: 343 | B30: BZJ-0028 | C30: 43556 | D30: =IF(TODAY()-E30<60,"2个月内",IF(TODAY()-E30<180,"3-6个月",IF(TODAY()-E30<360,"6个月-1年","一年以上"))) -> 一年以上 | E30: 43585 | F30: 销售部 | G30: 李辉 | H30: 葛洲坝钟祥水泥有限公司 | I30: 葛洲坝钟祥水泥有限公司 | J30: 10000 | L30: 对公 | M30: 履约保证金 | N30: 10000 | O30: =J30-N30 -> 0 | P30: 43938 | Q30: =P30 -> 43938 | S30: 履约保证金
A31: 17 | B31: BZJ-0029 | C31: 43586 | D31: =IF(TODAY()-E31<60,"2个月内",IF(TODAY()-E31<180,"3-6个月",IF(TODAY()-E31<360,"6个月-1年","一年以上"))) -> 一年以上 | E31: 43600 | F31: 生产部 | G31: 李文池 | H31: 四川峨眉山西南水泥有限公司 | I31: 四川峨眉山西南水泥有限公司 | J31: 3000 | L31: 对公 | M31: 安全保证金 | N31: 3000 | O31: =J31-N31 -> 0 | P31: 43824 | Q31: =P31 -> 43824
A32: 18 | B32: BZJ-0030 | C32: 43586 | D32: =IF(TODAY()-E32<60,"2个月内",IF(TODAY()-E32<180,"3-6个月",IF(TODAY()-E32<360,"6个月-1年","一年以上"))) -> 一年以上 | E32: 43601 | F32: 生产部 | G32: 吴昌松 | H32: 云南昆钢嘉华水泥建材有限公司 | I32: 云南昆钢嘉华水泥建材有限公司 | J32: 3000 | L32: 对公 | M32: 安全保证金 | N32: 3000 | O32: =J32-N32 -> 0 | P32: 44484 | Q32: =P32 -> 44484
A33: 20 | B33: BZJ-0031 | C33: 43586 | D33: =IF(TODAY()-E33<60,"2个月内",IF(TODAY()-E33<180,"3-6个月",IF(TODAY()-E33<360,"6个月-1年","一年以上"))) -> 一年以上 | E33: 43601 | F33: 生产部 | G33: 余茶林 | H33: 汉中尧柏水泥有限公司 | I33: 汉中尧柏水泥有限公司 | J33: 10000 | L33: 对公 | M33: 安全保证金 | N33: 10000 | O33: =J33-N33 -> 0 | P33: 43973 | Q33: =P33 -> 43973
A34: 21 | B34: BZJ-0032 | C34: 43617 | D34: =IF(TODAY()-E34<60,"2个月内",IF(TODAY()-E34<180,"3-6个月",IF(TODAY()-E34<360,"6个月-1年","一年以上"))) -> 一年以上 | E34: 43621 | F34: 生产部 | G34: 房延云 | H34: 鲁南中联水泥有限公司 | I34: 鲁南中联水泥有限公司 | J34: 2000 | L34: 个人 | M34: 安全保证金 | N34: 2000 | O34: =J34-N34 -> 0 | P34: 43676 | Q34: =P34 -> 43676
A35: 22 | B35: BZJ-0033 | C35: 43617 | D35: =IF(TODAY()-E35<60,"2个月内",IF(TODAY()-E35<180,"3-6个月",IF(TODAY()-E35<360,"6个月-1年","一年以上"))) -> 一年以上 | E35: 43628 | F35: 生产部 | G35: 王小勇 | H35: 莒县中联水泥有限公司 | I35: 莒县中联水泥有限公司 | J35: 5000 | L35: 对公 | M35: 安全保证金 | N35: 5000 | O35: =J35-N35 -> 0 | P35: 43641 | Q35: =P35 -> 43641
A36: 23 | B36: BZJ-0034 | C36: 43617 | D36: =IF(TODAY()-E36<60,"2个月内",IF(TODAY()-E36<180,"3-6个月",IF(TODAY()-E36<360,"6个月-1年","一年以上"))) -> 一年以上 | E36: 43635 | F36: 生产部 | G36: 程时勇 | H36: 贵州沿河西南水泥有限公司 | I36: 贵州沿河西南水泥有限公司 | J36: 2000 | L36: 对公 | M36: 安全保证金 | N36: 2000 | O36: =J36-N36 -> 0 | P36: 43644 | Q36: =P36 -> 43644
A37: 24 | B37: BZJ-0035 | C37: 43617 | D37: =IF(TODAY()-E37<60,"2个月内",IF(TODAY()-E37<180,"3-6个月",IF(TODAY()-E37<360,"6个月-1年","一年以上"))) -> 一年以上 | E37: 43644 | F37: 生产部 | G37: 李文池 | H37: 西安蓝田尧柏水泥有限公司 | I37: 西安蓝田尧柏水泥有限公司 | J37: 10000 | L37: 对公 | M37: 安全保证金 | N37: 10000 | O37: =J37-N37 -> 0 | P37: 43703 | Q37: =P37 -> 43703
A38: 25 | B38: BZJ-0036 | C38: 43647 | D38: =IF(TODAY()-E38<60,"2个月内",IF(TODAY()-E38<180,"3-6个月",IF(TODAY()-E38<360,"6个月-1年","一年以上"))) -> 一年以上 | E38: 43657 | F38: 生产部 | G38: 吴昌松 | H38: 会东利森水泥有限公司 | I38: 会东利森水泥有限公司 | J38: 3000 | L38: 对公 | M38: 安全保证金 | N38: 3000 | O38: =J38-N38 -> 0 | P38: 43703 | Q38: =P38 -> 43703
A39: 27 | B39: BZJ-0037 | C39: 43647 | D39: =IF(TODAY()-E39<60,"2个月内",IF(TODAY()-E39<180,"3-6个月",IF(TODAY()-E39<360,"6个月-1年","一年以上"))) -> 一年以上 | E39: 43657 | F39: 生产部 | G39: 熊军 | H39: 冀东水泥铜川有限公司 | I39: 冀东水泥铜川有限公司 | J39: 1000 | L39: 个人 | M39: 安全保证金 | N39: 1000 | O39: =J39-N39 -> 0 | P39: 43661 | Q39: =P39 -> 43661
A40: 26 | B40: BZJ-0038 | C40: 43647 | D40: =IF(TODAY()-E40<60,"2个月内",IF(TODAY()-E40<180,"3-6个月",IF(TODAY()-E40<360,"6个月-1年","一年以上"))) -> 一年以上 | E40: 43664 | F40: 生产部 | G40: 吴昌松 | H40: 四川省绵竹澳东水泥有限责任公司 | I40: 四川省绵竹澳东水泥有限责任公司 | J40: 3000 | L40: 对公 | M40: 安全保证金 | N40: 3000 | O40: =J40-N40 -> 0 | P40: 43794 | Q40: =P40 -> 43794
...

Sheet Sheet1 (2)
C1: 其他应收明细表
A2: 序号 | B2: 编号 | C2: 月份 | D2: 账龄 | E2: 支付日期 | F2: 部门 | G2: 经办人 | H2: 公司名称 | I2: 公司名称2 | J2: 支付金额 | K2: 公司 | L2: 支付方式 | M2: 支付类型 | N2: 退款金额/ 发票冲账 | O2: 未退余额 | P2: 退款时间 | Q2: 退回月份 | R2: 未退原因 | S2: 备注 | T2: 省份 | U2: 业务经理 | V2: 联系人 | W2: 中标结果 | X2: 业务员
A3: 182 | B3: BZJ-0001 | C3: 42370 | D3: =IF(TODAY()-E3<60,"2个月内",IF(TODAY()-E3<180,"3-6个月",IF(TODAY()-E3<360,"6个月-1年","一年以上"))) -> 一年以上 | H3: 三门峡腾跃同力水泥有限公司 | I3: 三门峡腾跃同力水泥有限公司 | J3: 1000 | K3: 武汉 | L3: 期初余额 | M3: 投标保证金 | O3: =J3-N3 -> 1000 | Q3: =P3 -> 0 | R3: 找付款凭证 | T3: 河南省 | U3: =VLOOKUP(T3,[1]区域划分!$A$1:$C$39,3,0) -> 方渊
A4: 183 | B4: BZJ-0002 | C4: 42370 | D4: =IF(TODAY()-E4<60,"2个月内",IF(TODAY()-E4<180,"3-6个月",IF(TODAY()-E4<360,"6个月-1年","一年以上"))) -> 一年以上 | H4: 云南西南水泥有限公司 | I4: 云南西南水泥有限公司 | J4: 50000 | L4: 期初余额 | M4: 投标保证金 | N4: 50000 | O4: =J4-N4 -> 0 | P4: 44155 | Q4: =P4 -> 44155
A5: 184 | B5: BZJ-0003 | C5: 42370 | D5: =IF(TODAY()-E5<60,"2个月内",IF(TODAY()-E5<180,"3-6个月",IF(TODAY()-E5<360,"6个月-1年","一年以上"))) -> 一年以上 | H5: 淮北众城水泥有限责任公司 | I5: 淮北众城水泥有限责任公司 | J5: 3000 | K5: 武汉 | L5: 期初余额 | M5: 投标保证金 | O5: =J5-N5 -> 3000 | Q5: =P5 -> 0 | S5: 已被收购 | T5: 安徽省 | U5: =VLOOKUP(T5,[1]区域划分!$A$1:$C$39,3,0) -> 方渊
A6: 186 | B6: BZJ-0004 | C6: 42370 | D6: =IF(TODAY()-E6<60,"2个月内",IF(TODAY()-E6<180,"3-6个月",IF(TODAY()-E6<360,"6个月-1年","一年以上"))) -> 一年以上 | H6: 吉林亚泰（集团）股份有限公司物资经销分公司 | I6: 吉林亚泰集团物资贸易有限公司 | J6: 3800 | K6: 武汉 | L6: 期初余额 | M6: 投标保证金 | O6: =J6-N6 -> 3800 | Q6: =P6 -> 0 | R6: 预计2023.04或2023.05月退还，熊伟跟进中.客人无此笔,我司资料为期初数据有23800 | S6: 有凭证才可查询 | T6: 吉林省 | U6: =VLOOKUP(T6,[1]区域划分!$A$1:$C$39,3,0) -> 殷坤鹏 | V6: 张玉鹏13634307383
A7: 187 | B7: BZJ-0005 | C7: 42370 | D7: =IF(TODAY()-E7<60,"2个月内",IF(TODAY()-E7<180,"3-6个月",IF(TODAY()-E7<360,"6个月-1年","一年以上"))) -> 一年以上 | H7: 江苏永钢集团物资贸易有限公司 | I7: 江苏永钢集团物资贸易有限公司 | J7: 20000 | K7: 武汉 | L7: 期初余额 | M7: 投标保证金 | O7: =J7-N7 -> 20000 | Q7: =P7 -> 0 | R7: 对方财务查询并无此款 | S7: 对方财务查询并无此款 | T7: 江苏省 | U7: =VLOOKUP(T7,[1]区域划分!$A$1:$C$39,3,0) -> 龚运谱
A8: 188 | B8: BZJ-0006 | C8: 42370 | D8: =IF(TODAY()-E8<60,"2个月内",IF(TODAY()-E8<180,"3-6个月",IF(TODAY()-E8<360,"6个月-1年","一年以上"))) -> 一年以上 | H8: 酒泉钢铁（集团）有限公司 | I8: 酒泉钢铁（集团）有限公司 | J8: 300 | L8: 期初余额 | M8: 投标保证金 | N8: 300 | O8: =J8-N8 -> 0 | P8: 44728 | Q8: =P8 -> 44728 | S8: 可能是标书费
A9: 185 | B9: BZJ-0007 | C9: 42370 | D9: =IF(TODAY()-E9<60,"2个月内",IF(TODAY()-E9<180,"3-6个月",IF(TODAY()-E9<360,"6个月-1年","一年以上"))) -> 一年以上 | E9: 42390 | G9: 吴海波 | H9: 亚泰伊通 | I9: 亚泰集团伊通水泥有限公司 | J9: 20000 | K9: 武汉 | L9: 武汉对公 | M9: 投标保证金 | O9: =J9-N9 -> 20000 | Q9: =P9 -> 0 | R9: 预计2023.04或2023.05月退还，熊伟跟进中.客人无此笔,我司资料为期初数据有23800 | S9: 2016年1月42#凭证 | T9: 吉林省 | U9: =VLOOKUP(T9,[1]区域划分!$A$1:$C$39,3,0) -> 殷坤鹏 | V9: 张玉鹏13634307383
A10: 189 | B10: BZJ-0008 | C10: 42370 | D10: =IF(TODAY()-E10<60,"2个月内",IF(TODAY()-E10<180,"3-6个月",IF(TODAY()-E10<360,"6个月-1年","一年以上"))) -> 一年以上 | E10: 42400 | H10: 江苏沙钢集团有限公司 | I10: 江苏沙钢集团有限公司 | J10: 10000 | K10: 武汉 | L10: 平台上共8万 | M10: 投标保证金 | O10: =J10-N10 -> 10000 | Q10: =P10 -> 0 | R10: 长期投标不退 | S10: 投标保证金（前期借支2万元 后期借支5万元） 销售部查询系统里面有8万元保证金，长期投标不退 | T10: 江苏省 | U10: =VLOOKUP(T10,[1]区域划分!$A$1:$C$39,3,0) -> 龚运谱
A11: 1 | B11: BZJ-0009 | C11: 42887 | D11: =IF(TODAY()-E11<60,"2个月内",IF(TODAY()-E11<180,"3-6个月",IF(TODAY()-E11<360,"6个月-1年","一年以上"))) -> 一年以上 | E11: 42887 | H11: 江苏沙钢集团有限公司 | I11: 江苏沙钢集团有限公司 | J11: 10000 | K11: 武汉 | L11: 平台上共8万 | M11: 安全保证金 | O11: 10000 | Q11: =P11 -> 0 | T11: 江苏省 | U11: =VLOOKUP(T11,[1]区域划分!$A$1:$C$39,3,0) -> 龚运谱
A12: 190 | B12: BZJ-0010 | C12: 43466 | D12: =IF(TODAY()-E12<60,"2个月内",IF(TODAY()-E12<180,"3-6个月",IF(TODAY()-E12<360,"6个月-1年","一年以上"))) -> 一年以上 | E12: 43475 | G12: 汤勇华 | H12: 江苏沙钢集团有限公司 | I12: 江苏沙钢集团有限公司 | J12: 50000 | K12: 武汉 | L12: 平台上共8万 | M12: 投标保证金 | O12: =J12-N12 -> 50000 | Q12: =P12 -> 0 | R12: 长期投标不退 | S12: 投标保证金（前期借支2万元 后期借支5万元） 销售部查询系统里面有8万元保证金，长期投标不退 | T12: 江苏省 | U12: =VLOOKUP(T12,[1]区域划分!$A$1:$C$39,3,0) -> 龚运谱
A13: 5 | B13: BZJ-0011 | C13: 43101 | D13: =IF(TODAY()-E13<60,"2个月内",IF(TODAY()-E13<180,"3-6个月",IF(TODAY()-E13<360,"6个月-1年","一年以上"))) -> 一年以上 | E13: 43113 | F13: 生产部 | G13: 姜兵 | H13: 永登祁连山水泥有限公司 | I13: 永登祁连山水泥有限公司 | J13: 2000 | L13: 对公 | M13: 安全保证金 | N13: 2000 | O13: =J13-N13 -> 0 | P13: 44099 | Q13: =P13 -> 44099 | S13: 近期要施工
A14: 2 | B14: BZJ-0012 | C14: 43101 | D14: =IF(TODAY()-E14<60,"2个月内",IF(TODAY()-E14<180,"3-6个月",IF(TODAY()-E14<360,"6个月-1年","一年以上"))) -> 一年以上 | E14: 43124 | G14: 丁俊 | H14: 逸盛大化石化有限公司 | I14: 逸盛大化石化有限公司 | J14: 7000 | K14: 武汉 | M14: 安全保证金 | O14: 7000 | Q14: =P14 -> 0 | R14: 2023.03月殷总说之前做的质量有重大问题暂时不催 | S14: 2019年12月从丁俊个人转公司账7000元 | T14: 辽宁省 | U14: =VLOOKUP(T14,[1]区域划分!$A$1:$C$39,3,0) -> 殷坤鹏
A15: 10 | B15: BZJ-0013 | C15: 43252 | D15: =IF(TODAY()-E15<60,"2个月内",IF(TODAY()-E15<180,"3-6个月",IF(TODAY()-E15<360,"6个月-1年","一年以上"))) -> 一年以上 | E15: 43255 | F15: 生产一部 | G15: 汪勇刚 | H15: 德州中联大坝水泥有限公司 | I15: 德州中联大坝水泥有限公司 | J15: 15000 | K15: 武汉 | L15: 武汉对公 | M15: 安全保证金 | N15: 15000 | O15: =J15-N15 -> 0 | P15: 44936 | Q15: =P15 -> 44936 | S15: 武汉2018.06-40 | T15: 山东省 | U15: 李松林
A16: 15 | B16: BZJ-0014 | C16: 43313 | D16: =IF(TODAY()-E16<60,"2个月内",IF(TODAY()-E16<180,"3-6个月",IF(TODAY()-E16<360,"6个月-1年","一年以上"))) -> 一年以上 | E16: 43330 | F16: 生产部 | G16: 张子仪 | H16: 四川西南水泥有限公司 | I16: 四川西南水泥有限公司 | J16: 2000 | L16: 对公 | M16: 安全保证金 | N16: 2000 | O16: =J16-N16 -> 0 | P16: 43707 | Q16: =P16 -> 43707
A17: 6 | B17: BZJ-0015 | C17: 43374 | D17: =IF(TODAY()-E17<60,"2个月内",IF(TODAY()-E17<180,"3-6个月",IF(TODAY()-E17<360,"6个月-1年","一年以上"))) -> 一年以上 | E17: 43393 | F17: 生产部 | G17: 刘西 | H17: 新安中联万基水泥有限公司 | I17: 新安中联万基水泥有限公司 | J17: 3000 | L17: 对公 | M17: 安全保证金 | N17: 3000 | O17: =J17-N17 -> 0 | P17: 44126 | Q17: =P17 -> 44126 | S17: 施工质量问题无法办理
A18: 19 | B18: BZJ-0016 | C18: 43374 | D18: =IF(TODAY()-E18<60,"2个月内",IF(TODAY()-E18<180,"3-6个月",IF(TODAY()-E18<360,"6个月-1年","一年以上"))) -> 一年以上 | E18: 43404 | F18: 生产部 | G18: 丁俊 | H18: 逸盛大化石化有限公司 | I18: 逸盛大化石化有限公司 | J18: 7000 | L18: 个人 | M18: 安全保证金 | N18: 7000 | O18: =J18-N18 -> 0 | P18: 43480 | Q18: =P18 -> 43480
A19: 3 | B19: BZJ-0017 | C19: 43405 | D19: =IF(TODAY()-E19<60,"2个月内",IF(TODAY()-E19<180,"3-6个月",IF(TODAY()-E19<360,"6个月-1年","一年以上"))) -> 一年以上 | E19: 43414 | F19: 生产部 | G19: 丁俊 | H19: 韩城尧柏阳山庄水泥有限公司 | I19: 韩城尧柏阳山庄水泥有限公司 | J19: =20000 -> 20000 | K19: 武汉 | L19: 对公 | M19: 安全保证金 | N19: 20000 | O19: =J19-N19 -> 0 | Q19: =P19 -> 0 | S19: 2019/12/24退19800
A20: 4 | B20: BZJ-0018 | C20: 43435 | D20: =IF(TODAY()-E20<60,"2个月内",IF(TODAY()-E20<180,"3-6个月",IF(TODAY()-E20<360,"6个月-1年","一年以上"))) -> 一年以上 | E20: 43446 | F20: 生产部 | G20: 冯海雄 | H20: 民和祁连山水泥有限公司 | I20: 民和祁连山水泥有限公司 | J20: 8000 | L20: 对公 | M20: 安全保证金 | N20: 8000 | O20: =J20-N20 -> 0 | P20: 43609 | Q20: =P20 -> 43609
A21: 12 | B21: BZJ-0019 | C21: 43466 | D21: =IF(TODAY()-E21<60,"2个月内",IF(TODAY()-E21<180,"3-6个月",IF(TODAY()-E21<360,"6个月-1年","一年以上"))) -> 一年以上 | E21: 43493 | F21: 生产部 | G21: 吴昌松 | H21: 冀东海天水泥闻喜有限公司 | I21: 冀东海天水泥闻喜有限公司 | J21: 10000 | L21: 对公 | M21: 安全保证金 | N21: 10000 | O21: =J21-N21 -> 0 | P21: 43664 | Q21: =P21 -> 43664
A22: 11 | B22: BZJ-0020 | C22: 43497 | D22: =IF(TODAY()-E22<60,"2个月内",IF(TODAY()-E22<180,"3-6个月",IF(TODAY()-E22<360,"6个月-1年","一年以上"))) -> 一年以上 | E22: 43511 | F22: 生产部 | G22: 汪勇刚 | H22: 贵州中诚水泥有限公司 | I22: 贵州中诚水泥有限公司 | J22: 3000 | L22: 对公 | M22: 安全保证金 | N22: 3000 | O22: =J22-N22 -> 0 | P22: 43646 | Q22: =P22 -> 43646
A23: 8 | B23: BZJ-0021 | C23: 43497 | D23: =IF(TODAY()-E23<60,"2个月内",IF(TODAY()-E23<180,"3-6个月",IF(TODAY()-E23<360,"6个月-1年","一年以上"))) -> 一年以上 | E23: 43516 | F23: 生产部 | G23: 覃延吉 | H23: 云南丽江西南水泥有限公司 | I23: 云南丽江西南水泥有限公司 | J23: 1000 | L23: 对公 | M23: 安全保证金 | N23: 1000 | O23: =J23-N23 -> 0 | P23: 43692 | Q23: =P23 -> 43692
A24: 14 | B24: BZJ-0022 | C24: 43525 | D24: =IF(TODAY()-E24<60,"2个月内",IF(TODAY()-E24<180,"3-6个月",IF(TODAY()-E24<360,"6个月-1年","一年以上"))) -> 一年以上 | E24: 43526 | F24: 生产部 | G24: 詹年喜 | H24: 邯郸涉县金隅水泥有限公司 | I24: 邯郸涉县金隅水泥有限公司 | J24: 2000 | L24: 对公 | M24: 安全保证金 | N24: 2000 | O24: =J24-N24 -> 0 | P24: 43698 | Q24: =P24 -> 43698
A25: 13 | B25: BZJ-0023 | C25: 43525 | D25: =IF(TODAY()-E25<60,"2个月内",IF(TODAY()-E25<180,"3-6个月",IF(TODAY()-E25<360,"6个月-1年","一年以上"))) -> 一年以上 | E25: 43530 | F25: 生产部 | G25: 詹年喜 | H25: 阳泉冀东水泥有限责任公司 | I25: 阳泉冀东水泥有限责任公司 | J25: 3000 | L25: 对公 | M25: 安全保证金 | N25: 3000 | O25: =J25-N25 -> 0 | P25: 43700 | Q25: =P25 -> 43700
A26: 9 | B26: BZJ-0024 | C26: 43525 | D26: =IF(TODAY()-E26<60,"2个月内",IF(TODAY()-E26<180,"3-6个月",IF(TODAY()-E26<360,"6个月-1年","一年以上"))) -> 一年以上 | E26: 43539 | F26: 生产部 | G26: 覃延吉 | H26: 河钢股份有限公司邯郸分公司 | I26: 河钢股份有限公司邯郸分公司 | J26: 10000 | L26: 对公 | M26: 安全保证金 | N26: 10000 | O26: =J26-N26 -> 0 | P26: 43613 | Q26: =P26 -> 43613
A27: 7 | B27: BZJ-0025 | C27: 43556 | D27: =IF(TODAY()-E27<60,"2个月内",IF(TODAY()-E27<180,"3-6个月",IF(TODAY()-E27<360,"6个月-1年","一年以上"))) -> 一年以上 | E27: 43557 | F27: 生产部 | G27: 石靖 | H27: 达州利森水泥有限公司 | I27: 达州利森水泥有限公司 | J27: 5000 | L27: 对公 | M27: 安全保证金 | N27: 5000 | O27: =J27-N27 -> 0 | P27: 43633 | Q27: =P27 -> 43633
A28: 16 | B28: BZJ-0026 | C28: 43556 | D28: =IF(TODAY()-E28<60,"2个月内",IF(TODAY()-E28<180,"3-6个月",IF(TODAY()-E28<360,"6个月-1年","一年以上"))) -> 一年以上 | E28: 43560 | F28: 总经办 | G28: 汤勇华 | H28: 张家港宏昌钢板有限公司 | I28: 张家港宏昌钢板有限公司 | J28: 124500 | K28: 武汉 | L28: 武汉对公 | M28: 安全保证金 | N28: 124500 | O28: =J28-N28 -> 0 | P28: 44890 | Q28: =P28 -> 44890 | S28: 武汉2019.4-50 | T28: 江苏省 | U28: 杨春龙 | V28: 预计2022.10月，收完全款后退回
A29: 194 | B29: BZJ-0027 | C29: 43556 | D29: =IF(TODAY()-E29<60,"2个月内",IF(TODAY()-E29<180,"3-6个月",IF(TODAY()-E29<360,"6个月-1年","一年以上"))) -> 一年以上 | E29: 43570 | G29: 夏锋泽 | H29: 四川西南水泥有限公司 | I29: 四川西南水泥有限公司 | J29: 10000 | L29: 对公 | M29: 投标保证金 | N29: 10000 | O29: =J29-N29 -> 0 | P29: 44064 | Q29: =P29 -> 44064 | S29: 长期投标不退
A30: 343 | B30: BZJ-0028 | C30: 43556 | D30: =IF(TODAY()-E30<60,"2个月内",IF(TODAY()-E30<180,"3-6个月",IF(TODAY()-E30<360,"6个月-1年","一年以上"))) -> 一年以上 | E30: 43585 | F30: 销售部 | G30: 李辉 | H30: 葛洲坝钟祥水泥有限公司 | I30: 葛洲坝钟祥水泥有限公司 | J30: 10000 | L30: 对公 | M30: 履约保证金 | N30: 10000 | O30: =J30-N30 -> 0 | P30: 43938 | Q30: =P30 -> 43938 | S30: 履约保证金
A31: 17 | B31: BZJ-0029 | C31: 43586 | D31: =IF(TODAY()-E31<60,"2个月内",IF(TODAY()-E31<180,"3-6个月",IF(TODAY()-E31<360,"6个月-1年","一年以上"))) -> 一年以上 | E31: 43600 | F31: 生产部 | G31: 李文池 | H31: 四川峨眉山西南水泥有限公司 | I31: 四川峨眉山西南水泥有限公司 | J31: 3000 | L31: 对公 | M31: 安全保证金 | N31: 3000 | O31: =J31-N31 -> 0 | P31: 43824 | Q31: =P31 -> 43824
A32: 18 | B32: BZJ-0030 | C32: 43586 | D32: =IF(TODAY()-E32<60,"2个月内",IF(TODAY()-E32<180,"3-6个月",IF(TODAY()-E32<360,"6个月-1年","一年以上"))) -> 一年以上 | E32: 43601 | F32: 生产部 | G32: 吴昌松 | H32: 云南昆钢嘉华水泥建材有限公司 | I32: 云南昆钢嘉华水泥建材有限公司 | J32: 3000 | L32: 对公 | M32: 安全保证金 | N32: 3000 | O32: =J32-N32 -> 0 | P32: 44484 | Q32: =P32 -> 44484
A33: 20 | B33: BZJ-0031 | C33: 43586 | D33: =IF(TODAY()-E33<60,"2个月内",IF(TODAY()-E33<180,"3-6个月",IF(TODAY()-E33<360,"6个月-1年","一年以上"))) -> 一年以上 | E33: 43601 | F33: 生产部 | G33: 余茶林 | H33: 汉中尧柏水泥有限公司 | I33: 汉中尧柏水泥有限公司 | J33: 10000 | L33: 对公 | M33: 安全保证金 | N33: 10000 | O33: =J33-N33 -> 0 | P33: 43973 | Q33: =P33 -> 43973
A34: 21 | B34: BZJ-0032 | C34: 43617 | D34: =IF(TODAY()-E34<60,"2个月内",IF(TODAY()-E34<180,"3-6个月",IF(TODAY()-E34<360,"6个月-1年","一年以上"))) -> 一年以上 | E34: 43621 | F34: 生产部 | G34: 房延云 | H34: 鲁南中联水泥有限公司 | I34: 鲁南中联水泥有限公司 | J34: 2000 | L34: 个人 | M34: 安全保证金 | N34: 2000 | O34: =J34-N34 -> 0 | P34: 43676 | Q34: =P34 -> 43676
A35: 22 | B35: BZJ-0033 | C35: 43617 | D35: =IF(TODAY()-E35<60,"2个月内",IF(TODAY()-E35<180,"3-6个月",IF(TODAY()-E35<360,"6个月-1年","一年以上"))) -> 一年以上 | E35: 43628 | F35: 生产部 | G35: 王小勇 | H35: 莒县中联水泥有限公司 | I35: 莒县中联水泥有限公司 | J35: 5000 | L35: 对公 | M35: 安全保证金 | N35: 5000 | O35: =J35-N35 -> 0 | P35: 43641 | Q35: =P35 -> 43641
A36: 23 | B36: BZJ-0034 | C36: 43617 | D36: =IF(TODAY()-E36<60,"2个月内",IF(TODAY()-E36<180,"3-6个月",IF(TODAY()-E36<360,"6个月-1年","一年以上"))) -> 一年以上 | E36: 43635 | F36: 生产部 | G36: 程时勇 | H36: 贵州沿河西南水泥有限公司 | I36: 贵州沿河西南水泥有限公司 | J36: 2000 | L36: 对公 | M36: 安全保证金 | N36: 2000 | O36: =J36-N36 -> 0 | P36: 43644 | Q36: =P36 -> 43644
A37: 24 | B37: BZJ-0035 | C37: 43617 | D37: =IF(TODAY()-E37<60,"2个月内",IF(TODAY()-E37<180,"3-6个月",IF(TODAY()-E37<360,"6个月-1年","一年以上"))) -> 一年以上 | E37: 43644 | F37: 生产部 | G37: 李文池 | H37: 西安蓝田尧柏水泥有限公司 | I37: 西安蓝田尧柏水泥有限公司 | J37: 10000 | L37: 对公 | M37: 安全保证金 | N37: 10000 | O37: =J37-N37 -> 0 | P37: 43703 | Q37: =P37 -> 43703
A38: 25 | B38: BZJ-0036 | C38: 43647 | D38: =IF(TODAY()-E38<60,"2个月内",IF(TODAY()-E38<180,"3-6个月",IF(TODAY()-E38<360,"6个月-1年","一年以上"))) -> 一年以上 | E38: 43657 | F38: 生产部 | G38: 吴昌松 | H38: 会东利森水泥有限公司 | I38: 会东利森水泥有限公司 | J38: 3000 | L38: 对公 | M38: 安全保证金 | N38: 3000 | O38: =J38-N38 -> 0 | P38: 43703 | Q38: =P38 -> 43703
A39: 27 | B39: BZJ-0037 | C39: 43647 | D39: =IF(TODAY()-E39<60,"2个月内",IF(TODAY()-E39<180,"3-6个月",IF(TODAY()-E39<360,"6个月-1年","一年以上"))) -> 一年以上 | E39: 43657 | F39: 生产部 | G39: 熊军 | H39: 冀东水泥铜川有限公司 | I39: 冀东水泥铜川有限公司 | J39: 1000 | L39: 个人 | M39: 安全保证金 | N39: 1000 | O39: =J39-N39 -> 0 | P39: 43661 | Q39: =P39 -> 43661
A40: 26 | B40: BZJ-0038 | C40: 43647 | D40: =IF(TODAY()-E40<60,"2个月内",IF(TODAY()-E40<180,"3-6个月",IF(TODAY()-E40<360,"6个月-1年","一年以上"))) -> 一年以上 | E40: 43664 | F40: 生产部 | G40: 吴昌松 | H40: 四川省绵竹澳东水泥有限责任公司 | I40: 四川省绵竹澳东水泥有限责任公司 | J40: 3000 | L40: 对公 | M40: 安全保证金 | N40: 3000 | O40: =J40-N40 -> 0 | P40: 43794 | Q40: =P40 -> 43794
...

Sheet Sheet2
A1: 标书费 | B1: 12668
A2: 投标保证金 | B2: 257775
A3: 安全保证金 | B3: 5000
A4: 平台服务费 | B4: 12500
A5: 中标服务费 | B5: 4160
A6: 履约保证金 | B6: 50000
B8: =SUM(B1:B7) -> 342103

Sheet Sheet3-婷
A1: 支付日期 | B1: 公司名称2 | C1: 支付类型 | D1: 部门 | E1: 经办人 | F1: 求和项:未退余额
A2: 2024-06-25 | B2: 青海发投碱业有限公司 | C2: 履约保证金 | D2: 销售部 | E2: 陈纤 | F2: 6950
A3: 2024-06-26 | B3: 安徽恒泰新材料有限公司 | C3: 投标保证金 | D3: 商务部 | E3: 周奇 | F3: 2000
A4: 2024-06-27 | B4: 青海发投碱业有限公司 | C4: 安全保证金 | D4: 内勤组 | E4: 陈云 | F4: 7000
A5: 2024-06-27 | B5: 青海发投碱业有限公司 | C5: 农民工工资保证金 | D5: 内勤组 | E5: 陈云 | F5: 6950
A6: 2024-07-01 | B6: 新疆宜化化工有限公司 | C6: 投标保证金 | D6: 商务部 | E6: 周奇 | F6: 0
A7: 2024-07-19 | B7: 国家电投集团山西铝业有限公司 | C7: 投标保证金 | D7: 商务部 | E7: 周奇 | F7: 0
A8: 2024-07-24 | B8: 青海发投碱业有限公司 | C8: 投标保证金 | D8: 商务部 | E8: 周奇 | F8: 0
A9: 2024-07-26 | B9: 鞍山冀东水泥有限责任公司 | C9: 投标保证金 | D9: 商务部 | E9: 周奇 | F9: 0
A10: 42390 | B10: 亚泰集团伊通水泥有限公司 | C10: 投标保证金 | D10: (空白) | E10: 吴海波 | F10: 20000
A11: 42400 | B11: 江苏沙钢集团有限公司 | C11: 投标保证金 | D11: (空白) | E11: (空白) | F11: 10000
A12: 42887 | B12: 江苏沙钢集团有限公司 | C12: 安全保证金 | D12: (空白) | E12: (空白) | F12: 10000
A13: 43113 | B13: 永登祁连山水泥有限公司 | C13: 安全保证金 | D13: 生产部 | E13: 姜兵 | F13: 0
A14: 43124 | B14: 逸盛大化石化有限公司 | C14: 安全保证金 | D14: (空白) | E14: 丁俊 | F14: 7000
A15: 43255 | B15: 德州中联大坝水泥有限公司 | C15: 安全保证金 | D15: 生产一部 | E15: 汪勇刚 | F15: 0
A16: 43330 | B16: 四川西南水泥有限公司 | C16: 安全保证金 | D16: 生产部 | E16: 张子仪 | F16: 0
A17: 43393 | B17: 新安中联万基水泥有限公司 | C17: 安全保证金 | D17: 生产部 | E17: 刘西 | F17: 0
A18: 43404 | B18: 逸盛大化石化有限公司 | C18: 安全保证金 | D18: 生产部 | E18: 丁俊 | F18: 0
A19: 43414 | B19: 韩城尧柏阳山庄水泥有限公司 | C19: 安全保证金 | D19: 生产部 | E19: 丁俊 | F19: 0
A20: 43446 | B20: 民和祁连山水泥有限公司 | C20: 安全保证金 | D20: 生产部 | E20: 冯海雄 | F20: 0
A21: 43475 | B21: 江苏沙钢集团有限公司 | C21: 投标保证金 | D21: (空白) | E21: 汤勇华 | F21: 50000
... A318: 44609 | B318: 山东泰山钢铁集团有限公司 | C318: 安全保证金 | D318: 生产部 | E318: 汪勇刚 | F318: 0
A319: 44615 | B319: 0 | C319: 投标保证金 | D319: (空白) | E319: 周奇 | F319: 0
A320: 44615 | B320: 山西省中条山新型建材有限公司 | C320: 投标保证金 | D320: (空白) | E320: 周奇 | F320: 0
A321: 44617 | B321: 河南省兴豫电子商务有限公司 | C321: 投标保证金 | D321: (空白) | E321: 杨江 | F321: 0
A322: 44617 | B322: 河南省豫鹤同力水泥有限公司 | C322: 标书费 | D322: 商务部 | E322: 杨江 | F322: 0
A323: 44617 | B323: 新兴铸管股份有限公司 | C323: 安全保证金 | D323: 销售部 | E323: 陈远志 | F323: 2000
A324: 44617 | B324: 云南远东水泥有限公司 | C324: 安全保证金 | D324: 生产二部 | E324: 吴结 | F324: 0
A325: 44620 | B325: 会东利森水泥有限公司 | C325: 安全保证金 | D325: 生产部 | E325: 程时勇 | F325: 0
A326: 44622 | B326: 河南晋开化工投资控股集团有限责任公司 | C326: 安全保证金 | D326: 生产部 | E326: 肖辉军 | F326: 0
A327: 44623 | B327: 重庆长寿西南水泥有限公司 | C327: 安全保证金 | D327: 生产部 | E327: 程时勇 | F327: 0
A328: 44624 | B328: 江苏磊达股份有限公司 | C328: 投标保证金 | D328: (空白) | E328: 杨江 | F328: 0
A329: 44627 | B329: 仁寿县汪洋建宝水泥有限公司广石分公司 | C329: 投标保证金 | D329: (空白) | E329: 周奇 | F329: 0
A330: 44628 | B330: 江苏磊达股份有限公司 | C330: 标书费 | D330: 商务部 | E330: 杨江 | F330: 0
A331: 44630 | B331: 鹤岗鑫塔水泥有限责任公司 | C331: 标书费 | D331: 销售部 | E331: 殷坤鹏 | F331: 0
... A861: 45716 | B861: 青海发投碱业有限公司 | C861: 投标保证金 | D861: 商务部 | E861: 周奇 | F861: 20000
A862: (空白) | B862: 东方希望重庆水泥有限公司 | C862: 投标保证金 | D862: 商务部 | E862: 周奇 | F862: 0
A863: (空白) | B863: 湖北宜化松滋肥业有限公司 | C863: 投标保证金 | D863: 商务部 | E863: 周奇 | F863: 0
A864: (空白) | B864: 淮北众城水泥有限责任公司 | C864: 投标保证金 | D864: (空白) | E864: (空白) | F864: 3000
A865: (空白) | B865: 吉林亚泰集团物资贸易有限公司 | C865: 投标保证金 | D865: (空白) | E865: (空白) | F865: 3800
...

Sheet Sheet4-婷
A1: 支付日期 | B1: 公司名称2 | C1: 支付类型 | D1: 部门 | E1: 经办人 | F1: 求和项:未退余额
A2: 45468 | B2: 青海发投碱业有限公司 | C2: 履约保证金 | D2: 销售部 | E2: 陈纤 | F2: 6950
A3: 45469 | B3: 安徽恒泰新材料有限公司 | C3: 投标保证金 | D3: 商务部 | E3: 周奇 | F3: 2000
A4: 45470 | B4: 青海发投碱业有限公司 | C4: 安全保证金 | D4: 内勤组 | E4: 陈云 | F4: 7000
A5: 45470 | B5: 青海发投碱业有限公司 | C5: 农民工工资保证金 | D5: 内勤组 | E5: 陈云 | F5: 6950
A6: 45474 | B6: 新疆宜化化工有限公司 | C6: 投标保证金 | D6: 商务部 | E6: 周奇 | F6: 0
A7: 45492 | B7: 国家电投集团山西铝业有限公司 | C7: 投标保证金 | D7: 商务部 | E7: 周奇 | F7: 0
A8: 45497 | B8: 青海发投碱业有限公司 | C8: 投标保证金 | D8: 商务部 | E8: 周奇 | F8: 0
A9: 45499 | B9: 鞍山冀东水泥有限责任公司 | C9: 投标保证金 | D9: 商务部 | E9: 周奇 | F9: 0
A10: 42390 | B10: 亚泰集团伊通水泥有限公司 | C10: 投标保证金 | D10: (空白) | E10: 吴海波 | F10: 20000
A11: 42400 | B11: 江苏沙钢集团有限公司 | C11: 投标保证金 | D11: (空白) | E11: (空白) | F11: 10000
A12: 42887 | B12: 江苏沙钢集团有限公司 | C12: 安全保证金 | D12: (空白) | E12: (空白) | F12: 10000
A13: 43113 | B13: 永登祁连山水泥有限公司 | C13: 安全保证金 | D13: 生产部 | E13: 姜兵 | F13: 0
... A318: 44609 | B318: 山东泰山钢铁集团有限公司 | C318: 安全保证金 | D318: 生产部 | E318: 汪勇刚 | F318: 0
A319: 44615 | B319: 0 | C319: 投标保证金 | D319: (空白) | E319: 周奇 | F319: 0
A320: 44615 | B320: 山西省中条山新型建材有限公司 | C320: 投标保证金 | D320: (空白) | E320: 周奇 | F320: 0
A321: 44617 | B321: 河南省兴豫电子商务有限公司 | C321: 投标保证金 | D321: (空白) | E321: 杨江 | F321: 0
A322: 44617 | B322: 河南省豫鹤同力水泥有限公司 | C322: 标书费 | D322: 商务部 | E322: 杨江 | F322: 0
A323: 44617 | B323: 新兴铸管股份有限公司 | C323: 安全保证金 | D323: 销售部 | E323: 陈远志 | F323: 2000
A324: 44617 | B324: 云南远东水泥有限公司 | C324: 安全保证金 | D324: 生产二部 | E324: 吴结 | F324: 0
A325: 44620 | B325: 会东利森水泥有限公司 | C325: 安全保证金 | D325: 生产部 | E325: 程时勇 | F325: 0
A326: 44622 | B326: 河南晋开化工投资控股集团有限责任公司 | C326: 安全保证金 | D326: 生产部 | E326: 肖辉军 | F326: 0
A327: 44623 | B327: 重庆长寿西南水泥有限公司 | C327: 安全保证金 | D327: 生产部 | E327: 程时勇 | F327: 0
A328: 44624 | B328: 江苏磊达股份有限公司 | C328: 投标保证金 | D328: (空白) | E328: 杨江 | F328: 0
A329: 44627 | B329: 仁寿县汪洋建宝水泥有限公司广石分公司 | C329: 投标保证金 | D329: (空白) | E329: 周奇 | F329: 0
A330: 44628 | B330: 江苏磊达股份有限公司 | C330: 标书费 | D330: 商务部 | E330: 杨江 | F330: 0
A331: 44630 | B331: 鹤岗鑫塔水泥有限责任公司 | C331: 标书费 | D331: 销售部 | E331: 殷坤鹏 | F331: 0
... A861: 45716 | B861: 青海发投碱业有限公司 | C861: 投标保证金 | D861: 商务部 | E861: 周奇 | F861: 20000
A862: (空白) | B862: 东方希望重庆水泥有限公司 | C862: 投标保证金 | D862: 商务部 | E862: 周奇 | F862: 0
A863: (空白) | B863: 湖北宜化松滋肥业有限公司 | C863: 投标保证金 | D863: 商务部 | E863: 周奇 | F863: 0
A864: (空白) | B864: 淮北众城水泥有限责任公司 | C864: 投标保证金 | D864: (空白) | E864: (空白) | F864: 3000
A865: (空白) | B865: 吉林亚泰集团物资贸易有限公司 | C865: 投标保证金 | D865: (空白) | E865: (空白) | F865: 3800
A866: (空白) | B866: 江苏永钢集团物资贸易有限公司 | C866: 投标保证金 | D866: (空白) | E866: (空白) | F866: 20000
A867: (空白) | B867: 酒泉钢铁（集团）有限公司 | C867: 投标保证金 | D867: (空白) | E867: (空白) | F867: 0
A868: (空白) | B868: 三门峡腾跃同力水泥有限公司 | C868: 投标保证金 | D868: (空白) | E868: (空白) | F868: 1000
A869: (空白) | B869: 山东泰山钢铁集团有限公司 | C869: 安全保证金 | D869: 生产部 | E869: 陈云 | F869: 0
A870: (空白) | B870: 新疆宜化化工有限公司 | C870: 投标保证金 | D870: 商务部 | E870: 周奇 | F870: 0
A871: (空白) | B871: 云南西南水泥有限公司 | C871: 投标保证金 | D871: (空白) | E871: (空白) | F871: 0

Sheet Sheet5-婷
A3: 支付类型 | B3: 求和项:求和项:未退余额
A4: 安全保证金 | B4: 921725
A5: 标书费 | B5: 16568 | C5: 拿票来抵扣
A6: 履约保证金 | B6: 780430.69
A7: 农民工保证金 | B7: 6950
A8: 农民工工资保证金 | B8: 813179.37
A9: 平台服务费 | B9: 26800 | C9: 拿票来抵扣
A10: 其他 | B10: 14300
A11: 投标保证金 | B11: 681075
A12: 押金 | B12: 5000
A13: 中标服务费 | B13: 4160 | C13: 拿票来抵扣
A14: (空白)
A15: 总计 | B15: 3270188.1
A20: 质保金 | B20: 10%-5% | C20: 工程款里面

Sheet 编号对比
A1: 表格 | B1: 红圈 | C1: 表格 | D1: 红圈 | E1: 表格 | F1: 红圈 | G1: 表格 | H1: 红圈 | I1: 表格 | J1: 红圈 | K1: 表格 | L1: 红圈 | M1: 表格 | N1: 红圈 | O1: 表格
A2: BZJ-0001 | B2: 182 | C2: =_xlfn.XLOOKUP(A2,保证金登记!B:B,保证金登记!E:E) -> 0 | D2: {=_xlfn.XLOOKUP(B2,1*[2]保证金申请!$A:$A,[2]保证金申请!$C:$C)} | E2: =_xlfn.XLOOKUP(A2,保证金登记!B:B,保证金登记!I:I) -> 三门峡腾跃同力水泥有限公司 | F2: {=_xlfn.XLOOKUP(B2,1*[2]保证金申请!$A:$A,[2]保证金申请!$Q:$Q)} -> 三门峡腾跃同力水泥有限公司 | G2: =_xlfn.XLOOKUP(A2,保证金登记!B:B,保证金登记!J:J) -> 1000 | H2: {=_xlfn.XLOOKUP(B2,1*[2]保证金申请!$A:$A,[2]保证金申请!$K:$K)} -> 1000 | I2: =C2-D2 -> #VALUE! | J2: =G2-H2 -> 0 | K2: =EXACT(E2,F2) -> TRUE
A3: BZJ-0002 | B3: 183 | C3: =_xlfn.XLOOKUP(A3,保证金登记!B:B,保证金登记!E:E) -> 0 | D3: {=_xlfn.XLOOKUP(B3,1*[2]保证金申请!$A:$A,[2]保证金申请!$C:$C)} | E3: =_xlfn.XLOOKUP(A3,保证金登记!B:B,保证金登记!I:I) -> 云南西南水泥有限公司 | F3: {=_xlfn.XLOOKUP(B3,1*[2]保证金申请!$A:$A,[2]保证金申请!$Q:$Q)} -> 云南西南水泥有限公司 | G3: =_xlfn.XLOOKUP(A3,保证金登记!B:B,保证金登记!J:J) -> 50000 | H3: {=_xlfn.XLOOKUP(B3,1*[2]保证金申请!$A:$A,[2]保证金申请!$K:$K)} -> 50000 | I3: =C3-D3 -> #VALUE! | J3: =G3-H3 -> 0 | K3: =EXACT(E3,F3) -> TRUE
A4: BZJ-0003 | B4: 184 | C4: =_xlfn.XLOOKUP(A4,保证金登记!B:B,保证金登记!E:E) -> 0 | D4: {=_xlfn.XLOOKUP(B4,1*[2]保证金申请!$A:$A,[2]保证金申请!$C:$C)} | E4: =_xlfn.XLOOKUP(A4,保证金登记!B:B,保证金登记!I:I) -> 淮北众城水泥有限责任公司 | F4: {=_xlfn.XLOOKUP(B4,1*[2]保证金申请!$A:$A,[2]保证金申请!$Q:$Q)} -> 淮北众城水泥有限责任公司 | G4: =_xlfn.XLOOKUP(A4,保证金登记!B:B,保证金登记!J:J) -> 3000 | H4: {=_xlfn.XLOOKUP(B4,1*[2]保证金申请!$A:$A,[2]保证金申请!$K:$K)} -> 3000 | I4: =C4-D4 -> #VALUE! | J4: =G4-H4 -> 0 | K4: =EXACT(E4,F4) -> TRUE
A5: BZJ-0004 | B5: 186 | C5: =_xlfn.XLOOKUP(A5,保证金登记!B:B,保证金登记!E:E) -> 0 | D5: {=_xlfn.XLOOKUP(B5,1*[2]保证金申请!$A:$A,[2]保证金申请!$C:$C)} | E5: =_xlfn.XLOOKUP(A5,保证金登记!B:B,保证金登记!I:I) -> 吉林亚泰集团物资贸易有限公司 | F5: {=_xlfn.XLOOKUP(B5,1*[2]保证金申请!$A:$A,[2]保证金申请!$Q:$Q)} -> 吉林亚泰（集团）股份有限公司物资经销分公司 | G5: =_xlfn.XLOOKUP(A5,保证金登记!B:B,保证金登记!J:J) -> 3800 | H5: {=_xlfn.XLOOKUP(B5,1*[2]保证金申请!$A:$A,[2]保证金申请!$K:$K)} -> 3800 | I5: =C5-D5 -> #VALUE! | J5: =G5-H5 -> 0 | K5: =EXACT(E5,F5) -> FALSE
A6: BZJ-0005 | B6: 187 | C6: =_xlfn.XLOOKUP(A6,保证金登记!B:B,保证金登记!E:E) -> 0 | D6: {=_xlfn.XLOOKUP(B6,1*[2]保证金申请!$A:$A,[2]保证金申请!$C:$C)} | E6: =_xlfn.XLOOKUP(A6,保证金登记!B:B,保证金登记!I:I) -> 江苏永钢集团物资贸易有限公司 | F6: {=_xlfn.XLOOKUP(B6,1*[2]保证金申请!$A:$A,[2]保证金申请!$Q:$Q)} -> 江苏永钢集团物资贸易有限公司 | G6: =_xlfn.XLOOKUP(A6,保证金登记!B:B,保证金登记!J:J) -> 20000 | H6: {=_xlfn.XLOOKUP(B6,1*[2]保证金申请!$A:$A,[2]保证金申请!$K:$K)} -> 20000 | I6: =C6-D6 -> #VALUE! | J6: =G6-H6 -> 0 | K6: =EXACT(E6,F6) -> TRUE
A7: BZJ-0006 | B7: 188 | C7: =_xlfn.XLOOKUP(A7,保证金登记!B:B,保证金登记!E:E) -> 0 | D7: {=_xlfn.XLOOKUP(B7,1*[2]保证金申请!$A:$A,[2]保证金申请!$C:$C)} | E7: =_xlfn.XLOOKUP(A7,保证金登记!B:B,保证金登记!I:I) -> 酒泉钢铁（集团）有限公司 | F7: {=_xlfn.XLOOKUP(B7,1*[2]保证金申请!$A:$A,[2]保证金申请!$Q:$Q)} -> 酒泉钢铁（集团）有限公司 | G7: =_xlfn.XLOOKUP(A7,保证金登记!B:B,保证金登记!J:J) -> 300 | H7: {=_xlfn.XLOOKUP(B7,1*[2]保证金申请!$A:$A,[2]保证金申请!$K:$K)} -> 300 | I7: =C7-D7 -> #VALUE! | J7: =G7-H7 -> 0 | K7: =EXACT(E7,F7) -> TRUE
A8: BZJ-0007 | B8: 185 | C8: =_xlfn.XLOOKUP(A8,保证金登记!B:B,保证金登记!E:E) -> 42390 | D8: {=_xlfn.XLOOKUP(B8,1*[2]保证金申请!$A:$A,[2]保证金申请!$C:$C)} -> 2016-01-21 | E8: =_xlfn.XLOOKUP(A8,保证金登记!B:B,保证金登记!I:I) -> 亚泰集团伊通水泥有限公司 | F8: {=_xlfn.XLOOKUP(B8,1*[2]保证金申请!$A:$A,[2]保证金申请!$Q:$Q)} -> 亚泰伊通 | G8: =_xlfn.XLOOKUP(A8,保证金登记!B:B,保证金登记!J:J) -> 20000 | H8: {=_xlfn.XLOOKUP(B8,1*[2]保证金申请!$A:$A,[2]保证金申请!$K:$K)} -> 20000 | I8: =C8-D8 -> 0 | J8: =G8-H8 -> 0 | K8: =EXACT(E8,F8) -> FALSE
A9: BZJ-0008 | B9: 189 | C9: =_xlfn.XLOOKUP(A9,保证金登记!B:B,保证金登记!E:E) -> 42400 | D9: {=_xlfn.XLOOKUP(B9,1*[2]保证金申请!$A:$A,[2]保证金申请!$C:$C)} -> 2016-01-31 | E9: =_xlfn.XLOOKUP(A9,保证金登记!B:B,保证金登记!I:I) -> 江苏沙钢集团有限公司 | F9: {=_xlfn.XLOOKUP(B9,1*[2]保证金申请!$A:$A,[2]保证金申请!$Q:$Q)} -> 江苏沙钢集团有限公司 | G9: =_xlfn.XLOOKUP(A9,保证金登记!B:B,保证金登记!J:J) -> 10000 | H9: {=_xlfn.XLOOKUP(B9,1*[2]保证金申请!$A:$A,[2]保证金申请!$K:$K)} -> 10000 | I9: =C9-D9 -> 0 | J9: =G9-H9 -> 0 | K9: =EXACT(E9,F9) -> TRUE
A10: BZJ-0009 | B10: 1 | C10: =_xlfn.XLOOKUP(A10,保证金登记!B:B,保证金登记!E:E) -> 42887 | D10: {=_xlfn.XLOOKUP(B10,1*[2]保证金申请!$A:$A,[2]保证金申请!$C:$C)} -> 2017-06-01 | E10: =_xlfn.XLOOKUP(A10,保证金登记!B:B,保证金登记!I:I) -> 江苏沙钢集团有限公司 | F10: {=_xlfn.XLOOKUP(B10,1*[2]保证金申请!$A:$A,[2]保证金申请!$Q:$Q)} -> 江苏沙钢集团有限公司 | G10: =_xlfn.XLOOKUP(A10,保证金登记!B:B,保证金登记!J:J) -> 10000 | H10: {=_xlfn.XLOOKUP(B10,1*[2]保证金申请!$A:$A,[2]保证金申请!$K:$K)} -> 10000 | I10: =C10-D10 -> 0 | J10: =G10-H10 -> 0 | K10: =EXACT(E10,F10) -> TRUE
A11: BZJ-0010 | B11: 190 | C11: =_xlfn.XLOOKUP(A11,保证金登记!B:B,保证金登记!E:E) -> 43475 | D11: {=_xlfn.XLOOKUP(B11,1*[2]保证金申请!$A:$A,[2]保证金申请!$C:$C)} -> 2019-01-10 | E11: =_xlfn.XLOOKUP(A11,保证金登记!B:B,保证金登记!I:I) -> 江苏沙钢集团有限公司 | F11: {=_xlfn.XLOOKUP(B11,1*[2]保证金申请!$A:$A,[2]保证金申请!$Q:$Q)} -> 江苏沙钢集团有限公司 | G11: =_xlfn.XLOOKUP(A11,保证金登记!B:B,保证金登记!J:J) -> 50000 | H11: {=_xlfn.XLOOKUP(B11,1*[2]保证金申请!$A:$A,[2]保证金申请!$K:$K)} -> 50000 | I11: =C11-D11 -> 0 | J11: =G11-H11 -> 0 | K11: =EXACT(E11,F11) -> TRUE
A12: BZJ-0011 | B12: 5 | C12: =_xlfn.XLOOKUP(A12,保证金登记!B:B,保证金登记!E:E) -> 43113 | D12: {=_xlfn.XLOOKUP(B12,1*[2]保证金申请!$A:$A,[2]保证金申请!$C:$C)} -> 2018-01-13 | E12: =_xlfn.XLOOKUP(A12,保证金登记!B:B,保证金登记!I:I) -> 永登祁连山水泥有限公司 | F12: {=_xlfn.XLOOKUP(B12,1*[2]保证金申请!$A:$A,[2]保证金申请!$Q:$Q)} -> 永登祁连山水泥有限公司 | G12: =_xlfn.XLOOKUP(A12,保证金登记!B:B,保证金登记!J:J) -> 2000 | H12: {=_xlfn.XLOOKUP(B12,1*[2]保证金申请!$A:$A,[2]保证金申请!$K:$K)} -> 2000 | I12: =C12-D12 -> 0 | J12: =G12-H12 -> 0 | K12: =EXACT(E12,F12) -> TRUE
A13: BZJ-0012 | B13: 2 | C13: =_xlfn.XLOOKUP(A13,保证金登记!B:B,保证金登记!E:E) -> 43124 | D13: {=_xlfn.XLOOKUP(B13,1*[2]保证金申请!$A:$A,[2]保证金申请!$C:$C)} -> 2018-01-24 | E13: =_xlfn.XLOOKUP(A13,保证金登记!B:B,保证金登记!I:I) -> 逸盛大化石化有限公司 | F13: {=_xlfn.XLOOKUP(B13,1*[2]保证金申请!$A:$A,[2]保证金申请!$Q:$Q)} -> 逸盛大化石化有限公司 | G13: =_xlfn.XLOOKUP(A13,保证金登记!B:B,保证金登记!J:J) -> 7000 | H13: {=_xlfn.XLOOKUP(B13,1*[2]保证金申请!$A:$A,[2]保证金申请!$K:$K)} -> 7000 | I13: =C13-D13 -> 0 | J13: =G13-H13 -> 0 | K13: =EXACT(E13,F13) -> TRUE
... A506: BZJ-0655 | B506: 655 | C506: =_xlfn.XLOOKUP(A506,保证金登记!B:B,保证金登记!E:E) -> 45056 | D506: {=_xlfn.XLOOKUP(B506,1*[2]保证金申请!$A:$A,[2]保证金申请!$C:$C)} -> 2023-05-10 | E506: =_xlfn.XLOOKUP(A506,保证金登记!B:B,保证金登记!I:I) -> 青海发投碱业有限公司 | F506: {=_xlfn.XLOOKUP(B506,1*[2]保证金申请!$A:$A,[2]保证金申请!$Q:$Q)} -> 青海发投碱业有限公司 | G506: =_xlfn.XLOOKUP(A506,保证金登记!B:B,保证金登记!J:J) -> 7800 | H506: {=_xlfn.XLOOKUP(B506,1*[2]保证金申请!$A:$A,[2]保证金申请!$K:$K)} -> 7800 | I506: =C506-D506 -> 0 | J506: =G506-H506 -> 0 | K506: =EXACT(E506,F506) -> TRUE
