Workbook

Sheet 参数
A1: 分析参数
A3: 分析截止日 | B3: 46024
A8: 口径说明
A9: 1) 开工后开票间隔：开票日期 - 开工日期（若开工日期缺失则不统计）。
A10: 2) 开票后回款间隔：开票日期到该客户“最早一笔回款日期(>=开票日)”的间隔（客户维度匹配，未按发票金额逐张销账）。
A11: 3) 客户账龄：来自【账龄明细】的未回款金额（优先“按照合同未回款”，缺失则用“按照验收未回款”），账龄基准日=开票日(有则用)否则完工日否则合同日。

Sheet 结论_应收_穿透图
A3: 账龄分析 | B3: Sum of 未回款 | C3: Count of 客户
A4: 0-30 | B4: 911000 | C4: 4
A5: 山东圣川新材料科技股份有限公司 | B5: 60000 | C5: 1
A6: 池州恒鑫材料科技有限公司 | B6: 45000 | C6: 1
A7: 青海盐湖镁业有限公司 | B7: 806000 | C7: 2
A8: 181-365 | B8: 8660299.8 | C8: 34
A9: 31-60 | B9: 4265271.2 | C9: 4
A10: 兆山集团诸暨水泥有限公司 | B10: 28000 | C10: 1
A11: 富蕴天山水泥有限责任公司 | B11: 200000 | C11: 1
A12: 广安昌兴水泥有限公司 | B12: 228900 | C12: 1
A13: 新疆宜化化工有限公司 | B13: 3808371.2 | C13: 1
A14: 365+ | B14: 18158405 | C14: 400
A15: 61-90 | B15: 1462000 | C15: 5
... A21: Grand Total | B21: 39783585 | C21: 472

Sheet 账龄桶分析明细
A1: 客户 | B1: 应收余额 | C1: 0-30 | D1: 31-60 | E1: 61-90 | F1: 91-180 | G1: 181-365 | H1: 365+ | I1: 发票数 | J1: 有开工日期发票数 | K1: 开工后开票_自然日_平均 | L1: 开票后回款_自然日_平均
A2: 新疆宜化化工有限公司 | B2: 5036771.2 | D2: 3808371.2 | F2: 1180000 | H2: 48400 | I2: 18 | L2: 95.888889
A3: 青海发投碱业有限公司 | B3: 4667646.7 | F3: 739594.4 | G3: 2735061.5 | H3: 1192990.8 | I3: 109 | L3: 39.889908
A4: 日照钢铁有限公司 | B4: 4223441 | F4: 1263546 | G4: 673605 | H4: 2286290 | I4: 24 | J4: 1 | K4: 119 | L4: 248.82353
A5: 日照京华新型建材有限公司 | B5: 2934000 | E5: 1234000 | G5: 1700000 | I5: 10 | J5: 1 | K5: 299
A6: 新疆伊犁钢铁有限责任公司 | B6: 1391271.7 | G6: 477506.16 | H6: 913765.56 | I6: 44 | J6: 7 | K6: 156.85714 | L6: 78.454545
A7: 内蒙古君正能源化工集团股份有限公司 | B7: 1285166.1 | F7: 828400 | G7: 456766.11
A8: 内蒙古宜化化工有限公司 | B8: 1222456.8 | F8: 524456.8 | G8: 698000 | I8: 2 | L8: 18
A9: 贵州黔西中水发电有限公司 | B9: 1092150 | H9: 1092150 | I9: 8 | L9: 485
A10: 青海盐湖镁业有限公司 | B10: 925792 | C10: 806000 | H10: 119792 | I10: 9 | J10: 4 | K10: 92.5 | L10: 60
A11: 青海海西化工建材股份有限公司 | B11: 651283.2 | H11: 651283.2 | I11: 1 | L11: 455
A12: 莱芜钢铁集团银山型钢有限公司 | B12: 617999.99 | G12: 617999.99 | I12: 1
A13: 内蒙古松塔水泥有限责任公司 | B13: 580000 | H13: 580000
A14: 江西赣锋锂业集团股份有限公司（马洪分公司） | B14: 532730 | H14: 532730
A15: 富蕴天山水泥有限责任公司 | B15: 520000 | D15: 200000 | H15: 320000 | I15: 9 | L15: 216.22222
A16: 湖北京兰水泥集团有限公司（钱场分公司） | B16: 475848.19 | H16: 475848.19
A17: 安钢集团信阳钢铁有限责任公司 | B17: 390784.45 | H17: 390784.45 | I17: 4 | L17: 157.5
A18: 尼勒克县瑞祥焦化有限责任公司（属伊伊犁钢铁分公司） | B18: 374223.11 | H18: 374223.11
A19: 阜阳皖润电力有限公司 | B19: 354600 | F19: 354600 | I19: 1 | L19: 18
A20: 江西亚东水泥有限公司 | B20: 313725.2 | E20: 120000 | H20: 193725.2 | I20: 27 | J20: 4 | K20: 41 | L20: 127.03704
A21: 四川川威集团成渝钒钛科技有限公司 | B21: 305200 | F21: 305200
A22: 山东泰山钢铁集团有限公司 | B22: 300000 | H22: 300000 | I22: 1
A23: 逸盛大化石化有限公司 | B23: 297850 | H23: 297850
A24: 唐山中厚板材有限公司 | B24: 293800 | H24: 293800
A25: 新兴铸管股份有限公司 | B25: 292000 | G25: 292000
A26: 池州恒鑫材料科技有限公司 | B26: 259200 | C26: 45000 | F26: 214200
A27: 新洋丰农业科技股份有限公司 | B27: 245200 | F27: 175000 | G27: 70000 | H27: 200 | I27: 1 | L27: 458
A28: 华润水泥（永定）有限公司 | B28: 239693 | H28: 239693 | I28: 2
A29: 联峰钢铁（张家港）有限公司（江苏永钢） | B29: 230601 | G29: 190001 | H29: 40600 | I29: 1 | J29: 1 | K29: 169
A30: 江苏永钢集团物资贸易有限公司 | B30: 230000 | G30: 230000
A31: 广安昌兴水泥有限公司 | B31: 228900 | D31: 228900 | I31: 1 | L31: 45
A32: 包头冀东水泥有限公司 | B32: 214501.77 | H32: 214501.77 | I32: 28 | J32: 1 | K32: 104 | L32: 213.46429
A33: 贵州金久水泥有限公司 | B33: 201263.29 | H33: 201263.29
A34: 湖南金山环保建材有限公司 | B34: 199757.85 | H34: 199757.85 | I34: 2 | J34: 1 | K34: 75 | L34: 289
A35: 河源市金杰环保建材有限公司 | B35: 196213.49 | H35: 196213.49
A36: 江西玉山万年青水泥有限公司 | B36: 195000 | F36: 195000 | I36: 7 | J36: 2 | K36: 139 | L36: 109
A37: 河钢股份有限公司邯郸分公司 | B37: 194330 | H37: 194330 | I37: 1 | L37: 335
A38: 宁都县赣锋锂业有限公司 | B38: 188000 | H38: 188000 | I38: 1
A39: 湖南韶峰南方水泥有限公司 | B39: 172800 | H39: 172800
A40: 芜湖新兴铸管有限责任公司 | B40: 170600 | F40: 155000 | H40: 15600 | I40: 2 | L40: 309.5
...

Sheet 明细_开票
A1: 客户 | B1: 销售合同号 | C1: 公司 | D1: 开工日期 | E1: 完工日期 | F1: 开票日期 | G1: 含税合计 | H1: 金额 | I1: 税额 | J1: 首次回款日期 | K1: 工期 | L1: 完工后开票_自然日 | M1: 开票后回款_自然日 | N1: 异常标记
A2: 华润水泥（永定）有限公司 | B2: KMX200807-180-XF | C2: 武汉 | F2: 44931 | G2: 23693 | H2: 20967.26 | I2: 2725.74 | K2: =IF(OR($D2="", $F2=""),"", $E2-$D2) | L2: =IF(OR($D2="", $F2=""),"", $F2-$E2) | M2: =IF(OR($F2="", $J2=""),"", $J2-$F2) | N2: 无回款匹配
A3: 北京堂海科技有限公司 | B3: KMX221228-450-XF | C3: 武汉 | F3: 44931 | G3: 53000 | H3: 50000 | I3: 3000 | K3: =IF(OR($D3="", $F3=""),"", $E3-$D3) | L3: =IF(OR($D3="", $F3=""),"", $F3-$E3) | M3: =IF(OR($F3="", $J3=""),"", $J3-$F3) | N3: 无回款匹配
A4: 青州中联水泥有限公司 | B4: KMX220305-128-XF | C4: 武汉 | D4: 44635 | E4: 44660 | F4: 44932 | G4: 76000 | H4: 67256.64 | I4: 8743.36 | J4: 45524 | K4: =IF(OR($D4="", $F4=""),"", $E4-$D4) -> 25 | L4: =IF(OR($D4="", $F4=""),"", $F4-$E4) -> 272 | M4: =IF(OR($F4="", $J4=""),"", $J4-$F4) -> 592
A5: 青州中联水泥有限公司 | B5: KMX220305-128-XF | C5: 武汉 | D5: 44635 | E5: 44660 | F5: 44932 | G5: 76000 | H5: 67256.64 | I5: 8743.36 | J5: 45524 | K5: =IF(OR($D5="", $F5=""),"", $E5-$D5) -> 25 | L5: =IF(OR($D5="", $F5=""),"", $F5-$E5) -> 272 | M5: =IF(OR($F5="", $J5=""),"", $J5-$F5) -> 592
A6: 湖南浏阳南方水泥有限公司 | B6: KMX220426-180-XF | C6: 武汉 | F6: 44932 | G6: 40000 | H6: 35398.23 | I6: 4601.77 | J6: 45322 | K6: =IF(OR($D6="", $F6=""),"", $E6-$D6) | L6: =IF(OR($D6="", $F6=""),"", $F6-$E6) | M6: =IF(OR($F6="", $J6=""),"", $J6-$F6) -> 390
A7: 四川峨胜水泥集团股份有限公司 | B7: KMX220930-364-XF | C7: 武汉 | D7: 44843 | E7: 44867 | F7: 44932 | G7: 8000 | H7: 7079.65 | I7: 920.35 | J7: 45365 | K7: =IF(OR($D7="", $F7=""),"", $E7-$D7) -> 24 | L7: =IF(OR($D7="", $F7=""),"", $F7-$E7) -> 65 | M7: =IF(OR($F7="", $J7=""),"", $J7-$F7) -> 433
A8: 四川峨胜水泥集团股份有限公司 | B8: KMX220930-364-XF | C8: 武汉 | D8: 44843 | E8: 44867 | F8: 44932 | G8: 22000 | H8: 19469.03 | I8: 2530.97 | J8: 45365 | K8: =IF(OR($D8="", $F8=""),"", $E8-$D8) -> 24 | L8: =IF(OR($D8="", $F8=""),"", $F8-$E8) -> 65 | M8: =IF(OR($F8="", $J8=""),"", $J8-$F8) -> 433
A9: 四川峨胜水泥集团股份有限公司 | B9: KMX220930-364-XF | C9: 武汉 | D9: 44843 | E9: 44867 | F9: 44932 | G9: 38000 | H9: 33628.32 | I9: 4371.68 | J9: 45365 | K9: =IF(OR($D9="", $F9=""),"", $E9-$D9) -> 24 | L9: =IF(OR($D9="", $F9=""),"", $F9-$E9) -> 65 | M9: =IF(OR($F9="", $J9=""),"", $J9-$F9) -> 433
A10: 卫辉市天瑞水泥有限公司 | B10: KMX221130-420-XF | C10: 湖北 | D10: 44915 | E10: 44922 | F10: 44933 | G10: 3.86 | H10: 3.42 | I10: 0.44 | J10: 45593 | K10: =IF(OR($D10="", $F10=""),"", $E10-$D10) -> 7 | L10: =IF(OR($D10="", $F10=""),"", $F10-$E10) -> 11 | M10: =IF(OR($F10="", $J10=""),"", $J10-$F10) -> 660
A11: 昌江华盛天涯水泥有限公司 | B11: KMX221028-388-XF | C11: 武汉 | D11: 44866 | E11: 44868 | F11: 44935 | G11: 68000 | H11: 64150.94 | I11: 3849.06 | K11: =IF(OR($D11="", $F11=""),"", $E11-$D11) -> 2 | L11: =IF(OR($D11="", $F11=""),"", $F11-$E11) -> 67 | M11: =IF(OR($F11="", $J11=""),"", $J11-$F11) | N11: 无回款匹配
A12: 湖南华菱湘潭钢铁有限公司 | B12: KMX200424-073-XF | C12: 武汉 | F12: 44935 | G12: 101700 | H12: 90000 | I12: 11700 | J12: 45315 | K12: =IF(OR($D12="", $F12=""),"", $E12-$D12) | L12: =IF(OR($D12="", $F12=""),"", $F12-$E12) | M12: =IF(OR($F12="", $J12=""),"", $J12-$F12) -> 380
A13: 北京堂海科技有限公司 | B13: KMX221228-450-XF | C13: 武汉 | F13: 44936 | G13: 53000 | H13: 50000 | I13: 3000 | K13: =IF(OR($D13="", $F13=""),"", $E13-$D13) | L13: =IF(OR($D13="", $F13=""),"", $F13-$E13) | M13: =IF(OR($F13="", $J13=""),"", $J13-$F13) | N13: 无回款匹配
A14: 北京金隅琉水环保科技有限公司 | B14: KMX220510-190-XF | C14: 湖北 | D14: 44822 | E14: 44839 | F14: 44937 | G14: -108000 | H14: -95575.22 | I14: -12424.78 | J14: 45564 | K14: =IF(OR($D14="", $F14=""),"", $E14-$D14) -> 17 | L14: =IF(OR($D14="", $F14=""),"", $F14-$E14) -> 98 | M14: =IF(OR($F14="", $J14=""),"", $J14-$F14) -> 627
A15: 北京金隅琉水环保科技有限公司 | B15: KMX220510-190-XF | C15: 湖北 | F15: 44937 | G15: -108000 | H15: -95575.22 | I15: -12424.78 | J15: 45564 | K15: =IF(OR($D15="", $F15=""),"", $E15-$D15) | L15: =IF(OR($D15="", $F15=""),"", $F15-$E15) | M15: =IF(OR($F15="", $J15=""),"", $J15-$F15) -> 627
A16: 联峰钢铁（张家港）有限公司（江苏永钢） | B16: KMX220720-289-XF | C16: 武汉 | D16: 44773 | E16: 44779 | F16: 44942 | G16: 65000 | H16: 59633.03 | I16: 5366.97 | K16: =IF(OR($D16="", $F16=""),"", $E16-$D16) -> 6 | L16: =IF(OR($D16="", $F16=""),"", $F16-$E16) -> 163 | M16: =IF(OR($F16="", $J16=""),"", $J16-$F16) | N16: 无回款匹配
A17: 海南逸盛石化有限公司 | B17: KMX221208-431-XF | C17: 武汉 | D17: 44905 | E17: 44910 | F17: 44954 | G17: 100000 | H17: 88495.58 | I17: 11504.42 | J17: 45461 | K17: =IF(OR($D17="", $F17=""),"", $E17-$D17) -> 5 | L17: =IF(OR($D17="", $F17=""),"", $F17-$E17) -> 44 | M17: =IF(OR($F17="", $J17=""),"", $J17-$F17) -> 507
A18: 海南逸盛石化有限公司 | B18: KMX221127-418-XF | C18: 武汉 | D18: 44891 | E18: 44895 | F18: 44954 | G18: 65000 | H18: 57522.12 | I18: 7477.88 | J18: 45461 | K18: =IF(OR($D18="", $F18=""),"", $E18-$D18) -> 4 | L18: =IF(OR($D18="", $F18=""),"", $F18-$E18) -> 59 | M18: =IF(OR($F18="", $J18=""),"", $J18-$F18) -> 507
A19: 广西北港新材料有限公司 | B19: KMX220516-206-XF | C19: 武汉 | F19: 44956 | G19: 82720 | H19: 75889.91 | I19: 6830.09 | J19: 45320 | K19: =IF(OR($D19="", $F19=""),"", $E19-$D19) | L19: =IF(OR($D19="", $F19=""),"", $F19-$E19) | M19: =IF(OR($F19="", $J19=""),"", $J19-$F19) -> 364
A20: 广西北港新材料有限公司 | B20: KMX220516-206-XF | C20: 武汉 | F20: 44956 | G20: 82720 | H20: 75889.91 | I20: 6830.09 | J20: 45320 | K20: =IF(OR($D20="", $F20=""),"", $E20-$D20) | L20: =IF(OR($D20="", $F20=""),"", $F20-$E20) | M20: =IF(OR($F20="", $J20=""),"", $J20-$F20) -> 364
A21: 新疆伊犁钢铁有限责任公司 | B21: KMX211021-394-XF | C21: 武汉 | D21: 44529 | E21: 44575 | F21: 44957 | G21: 90754.31 | H21: 83260.83 | I21: 7493.48 | J21: 45314 | K21: =IF(OR($D21="", $F21=""),"", $E21-$D21) -> 46 | L21: =IF(OR($D21="", $F21=""),"", $F21-$E21) -> 382 | M21: =IF(OR($F21="", $J21=""),"", $J21-$F21) -> 357
A22: 新疆伊犁钢铁有限责任公司 | B22: KMX211021-394-XF | C22: 武汉 | D22: 44529 | E22: 44575 | F22: 44957 | G22: 38894.7 | H22: 35683.21 | I22: 3211.49 | J22: 45314 | K22: =IF(OR($D22="", $F22=""),"", $E22-$D22) -> 46 | L22: =IF(OR($D22="", $F22=""),"", $F22-$E22) -> 382 | M22: =IF(OR($F22="", $J22=""),"", $J22-$F22) -> 357
A23: 崇阳县昌华实业有限公司 | B23: KMX230101-001-XF | C23: 武汉 | F23: 44959 | G23: 97 | H23: 85.84 | I23: 11.16 | J23: 45679 | K23: =IF(OR($D23="", $F23=""),"", $E23-$D23) | L23: =IF(OR($D23="", $F23=""),"", $F23-$E23) | M23: =IF(OR($F23="", $J23=""),"", $J23-$F23) -> 720
A24: 崇阳县昌华实业有限公司 | B24: KMX230104-009-XF | C24: 武汉 | F24: 44959 | G24: 12000 | H24: 10619.47 | I24: 1380.53 | J24: 45679 | K24: =IF(OR($D24="", $F24=""),"", $E24-$D24) | L24: =IF(OR($D24="", $F24=""),"", $F24-$E24) | M24: =IF(OR($F24="", $J24=""),"", $J24-$F24) -> 720
A25: 赞皇金隅水泥有限公司 | B25: KMX221111-404-XF | C25: 湖北 | F25: 44966 | G25: 110000 | H25: 97345.13 | I25: 12654.87 | J25: 45593 | K25: =IF(OR($D25="", $F25=""),"", $E25-$D25) | L25: =IF(OR($D25="", $F25=""),"", $F25-$E25) | M25: =IF(OR($F25="", $J25=""),"", $J25-$F25) -> 627
A26: 日照京华新型建材有限公司 | B26: KMX220329-153-XF | C26: 武汉 | D26: 44668 | E26: 44675 | F26: 44967 | G26: 117809.74 | H26: 110619.47 | I26: 7190.27 | K26: =IF(OR($D26="", $F26=""),"", $E26-$D26) -> 7 | L26: =IF(OR($D26="", $F26=""),"", $F26-$E26) -> 292 | M26: =IF(OR($F26="", $J26=""),"", $J26-$F26) | N26: 无回款匹配
A27: 日照京华新型建材有限公司 | B27: KMX220329-153-XF | C27: 武汉 | F27: 44967 | G27: 117809.74 | H27: 110619.47 | I27: 7190.27 | K27: =IF(OR($D27="", $F27=""),"", $E27-$D27) | L27: =IF(OR($D27="", $F27=""),"", $F27-$E27) | M27: =IF(OR($F27="", $J27=""),"", $J27-$F27) | N27: 无回款匹配
A28: 宁波钢铁有限公司 | B28: KMX221121-411-XF | C28: 武汉 | D28: 44885 | E28: 44887 | F28: 44971 | G28: 55700 | H28: 49292.04 | I28: 6407.96 | J28: 45371 | K28: =IF(OR($D28="", $F28=""),"", $E28-$D28) -> 2 | L28: =IF(OR($D28="", $F28=""),"", $F28-$E28) -> 84 | M28: =IF(OR($F28="", $J28=""),"", $J28-$F28) -> 400
A29: 宁波钢铁有限公司 | B29: KMX220601-228-XF | C29: 武汉 | D29: 44882 | E29: 44884 | F29: 44971 | G29: 64000 | H29: 56637.17 | I29: 7362.83 | J29: 45371 | K29: =IF(OR($D29="", $F29=""),"", $E29-$D29) -> 2 | L29: =IF(OR($D29="", $F29=""),"", $F29-$E29) -> 87 | M29: =IF(OR($F29="", $J29=""),"", $J29-$F29) -> 400
A30: 铜陵上峰水泥股份有限公司 | B30: KMX220218-100-XF | C30: 武汉 | F30: 44971 | G30: 105000 | H30: 92920.35 | I30: 12079.65 | J30: 45596 | K30: =IF(OR($D30="", $F30=""),"", $E30-$D30) | L30: =IF(OR($D30="", $F30=""),"", $F30-$E30) | M30: =IF(OR($F30="", $J30=""),"", $J30-$F30) -> 625
A31: 铜陵上峰水泥股份有限公司 | B31: KMX220218-100-XF | C31: 武汉 | D31: 44695 | E31: 44701 | F31: 44971 | G31: 47000 | H31: 41592.92 | I31: 5407.08 | J31: 45596 | K31: =IF(OR($D31="", $F31=""),"", $E31-$D31) -> 6 | L31: =IF(OR($D31="", $F31=""),"", $F31-$E31) -> 270 | M31: =IF(OR($F31="", $J31=""),"", $J31-$F31) -> 625
A32: 铜陵上峰水泥股份有限公司 | B32: KMX220218-100-XF | C32: 武汉 | D32: 44724 | E32: 44862 | F32: 44971 | G32: 18000 | H32: 15929.2 | I32: 2070.8 | J32: 45596 | K32: =IF(OR($D32="", $F32=""),"", $E32-$D32) -> 138 | L32: =IF(OR($D32="", $F32=""),"", $F32-$E32) -> 109 | M32: =IF(OR($F32="", $J32=""),"", $J32-$F32) -> 625
A33: 铜陵上峰水泥股份有限公司 | B33: KMX220218-100-XF | C33: 武汉 | D33: 44724 | E33: 44862 | F33: 44971 | G33: 4900 | H33: 4336.28 | I33: 563.72 | J33: 45596 | K33: =IF(OR($D33="", $F33=""),"", $E33-$D33) -> 138 | L33: =IF(OR($D33="", $F33=""),"", $F33-$E33) -> 109 | M33: =IF(OR($F33="", $J33=""),"", $J33-$F33) -> 625
A34: 铜陵上峰水泥股份有限公司 | B34: KMX220218-100-XF | C34: 武汉 | D34: 44758 | E34: 44772 | F34: 44971 | G34: 40000 | H34: 35398.23 | I34: 4601.77 | J34: 45596 | K34: =IF(OR($D34="", $F34=""),"", $E34-$D34) -> 14 | L34: =IF(OR($D34="", $F34=""),"", $F34-$E34) -> 199 | M34: =IF(OR($F34="", $J34=""),"", $J34-$F34) -> 625
A35: 涞水金隅冀东环保科技有限公司 | B35: KMX221127-419-XF | C35: 湖北 | D35: 44912 | E35: 44924 | F35: 44972 | G35: 58000 | H35: 51327.43 | I35: 6672.57 | J35: 45586 | K35: =IF(OR($D35="", $F35=""),"", $E35-$D35) -> 12 | L35: =IF(OR($D35="", $F35=""),"", $F35-$E35) -> 48 | M35: =IF(OR($F35="", $J35=""),"", $J35-$F35) -> 614
A36: 重庆九鑫水泥（集团）有限公司 | B36: KMX230103-008-XF | C36: 武汉 | F36: 44973 | G36: 52920 | H36: 46831.86 | I36: 6088.14 | K36: =IF(OR($D36="", $F36=""),"", $E36-$D36) | L36: =IF(OR($D36="", $F36=""),"", $F36-$E36) | M36: =IF(OR($F36="", $J36=""),"", $J36-$F36) | N36: 无回款匹配
A37: 江油嘉鸿机电工程有限公司 | B37: KMX230215-052-XF | C37: 武汉 | D37: 44943 | E37: 44943 | F37: 44975 | G37: 14000 | H37: 13207.55 | I37: 792.45 | K37: =IF(OR($D37="", $F37=""),"", $E37-$D37) -> 0 | L37: =IF(OR($D37="", $F37=""),"", $F37-$E37) -> 32 | M37: =IF(OR($F37="", $J37=""),"", $J37-$F37) | N37: 无回款匹配
A38: 北京金隅北水环保科技有限公司 | B38: KMX211221-506-XF | C38: 湖北 | D38: 44648 | E38: 44660 | F38: 44975 | G38: 112892 | H38: 99904.42 | I38: 12987.58 | K38: =IF(OR($D38="", $F38=""),"", $E38-$D38) -> 12 | L38: =IF(OR($D38="", $F38=""),"", $F38-$E38) -> 315 | M38: =IF(OR($F38="", $J38=""),"", $J38-$F38) | N38: 无回款匹配
A39: 北京金隅北水环保科技有限公司 | B39: KMX211221-506-XF | C39: 湖北 | D39: 44648 | E39: 44660 | F39: 44975 | G39: 112554 | H39: 99605.31 | I39: 12948.69 | K39: =IF(OR($D39="", $F39=""),"", $E39-$D39) -> 12 | L39: =IF(OR($D39="", $F39=""),"", $F39-$E39) -> 315 | M39: =IF(OR($F39="", $J39=""),"", $J39-$F39) | N39: 无回款匹配
A40: 北京金隅北水环保科技有限公司 | B40: KMX211221-506-XF | C40: 湖北 | D40: 44648 | E40: 44660 | F40: 44975 | G40: 112554 | H40: 99605.31 | I40: 12948.69 | K40: =IF(OR($D40="", $F40=""),"", $E40-$D40) -> 12 | L40: =IF(OR($D40="", $F40=""),"", $F40-$E40) -> 315 | M40: =IF(OR($F40="", $J40=""),"", $J40-$F40) | N40: 无回款匹配
...

Sheet 明细_应收
A1: 合同号 | B1: 客户 | C1: 合同日期 | D1: 完工日期 | E1: 工期 | F1: 开票日期 | G1: 完工后开票 | H1: 账龄基准日 | I1: 账龄天数 | J1: 账龄桶 | K1: 未回款 | L1: 未开票金额
A2: KMX071008-197 | B2: 新疆阿克苏青松建化公司 | C2: 39363 | D2: 39453 | E2: =IF(OR($C2="", $D2=""),"", $D2-$C2) -> 90 | G2: =IF(OR($C2="", $D2="",$F2=""),"", $F2-$D2) | H2: 39453 | I2: =IF($H2="", "", 参数!$B$3-$H2) -> 6571 | J2: 365+ | K2: 35460
A3: KMX080909-077 | B3: 四会市骏马水泥有限公司 | C3: 39700 | D3: 39717 | E3: =IF(OR($C3="", $D3=""),"", $D3-$C3) -> 17 | F3: 39717 | G3: =IF(OR($C3="", $D3="",$F3=""),"", $F3-$D3) -> 0 | H3: 39717 | I3: =IF($H3="", "", 参数!$B$3-$H3) -> 6307 | J3: 365+ | K3: 5900
A4: KMX081010-085 | B4: 山东康达水泥有限公司 | C4: 39731 | D4: 39749 | E4: =IF(OR($C4="", $D4=""),"", $D4-$C4) -> 18 | F4: 39749 | G4: =IF(OR($C4="", $D4="",$F4=""),"", $F4-$D4) -> 0 | H4: 39749 | I4: =IF($H4="", "", 参数!$B$3-$H4) -> 6275 | J4: 365+ | K4: 7500
A5: KMX080807-176 | B5: 湖北金龙新材料股份有限公司 | C5: 40032 | D5: 40122 | E5: =IF(OR($C5="", $D5=""),"", $D5-$C5) -> 90 | G5: =IF(OR($C5="", $D5="",$F5=""),"", $F5-$D5) | H5: 40122 | I5: =IF($H5="", "", 参数!$B$3-$H5) -> 5902 | J5: 365+ | K5: 26400
A6: KMX091120-177 | B6: 哈尔滨金山实业集团有限公司 | C6: 40137 | D6: 40227 | E6: =IF(OR($C6="", $D6=""),"", $D6-$C6) -> 90 | G6: =IF(OR($C6="", $D6="",$F6=""),"", $F6-$D6) | H6: 40227 | I6: =IF($H6="", "", 参数!$B$3-$H6) -> 5797 | J6: 365+ | K6: 27000
A7: KMX091123-151 | B7: 南阳市天泰水泥有限公司 | C7: 40140 | D7: 40170 | E7: =IF(OR($C7="", $D7=""),"", $D7-$C7) -> 30 | F7: 40170 | G7: =IF(OR($C7="", $D7="",$F7=""),"", $F7-$D7) -> 0 | H7: 40170 | I7: =IF($H7="", "", 参数!$B$3-$H7) -> 5854 | J7: 365+ | K7: 18000
A8: KMX100612-029 | B8: 四会市骏马水泥有限公司 | C8: 40341 | D8: 40431 | E8: =IF(OR($C8="", $D8=""),"", $D8-$C8) -> 90 | G8: =IF(OR($C8="", $D8="",$F8=""),"", $F8-$D8) | H8: 40431 | I8: =IF($H8="", "", 参数!$B$3-$H8) -> 5593 | J8: 365+ | K8: 2400
A9: KMX101027-079 | B9: 山东金塔王股份有限公司 | C9: 40478 | D9: 40479 | E9: =IF(OR($C9="", $D9=""),"", $D9-$C9) -> 1 | F9: 40479 | G9: =IF(OR($C9="", $D9="",$F9=""),"", $F9-$D9) -> 0 | H9: 40479 | I9: =IF($H9="", "", 参数!$B$3-$H9) -> 5545 | J9: 365+ | K9: 6000
A10: KMX101223-006 | B10: 普定明达水泥有限公司 | C10: 40535 | D10: 40549 | E10: =IF(OR($C10="", $D10=""),"", $D10-$C10) -> 14 | F10: 40549 | G10: =IF(OR($C10="", $D10="",$F10=""),"", $F10-$D10) -> 0 | H10: 40549 | I10: =IF($H10="", "", 参数!$B$3-$H10) -> 5475 | J10: 365+ | K10: 740
A11: KMX110106-090 | B11: 江西玉山南方水泥有限公司 | C11: 40549 | D11: 40563 | E11: =IF(OR($C11="", $D11=""),"", $D11-$C11) -> 14 | F11: 40563 | G11: =IF(OR($C11="", $D11="",$F11=""),"", $F11-$D11) -> 0 | H11: 40563 | I11: =IF($H11="", "", 参数!$B$3-$H11) -> 5461 | J11: 365+ | K11: 7800
A12: KMX110209-162 | B12: 天瑞集团汝州水泥有限公司 | C12: 40583 | D12: 40732 | E12: =IF(OR($C12="", $D12=""),"", $D12-$C12) -> 149 | F12: 40732 | G12: =IF(OR($C12="", $D12="",$F12=""),"", $F12-$D12) -> 0 | H12: 40732 | I12: =IF($H12="", "", 参数!$B$3-$H12) -> 5292 | J12: 365+ | K12: 19000
A13: KMX110530-153 | B13: 南阳市天泰水泥有限公司 | C13: 40693 | D13: 40792 | E13: =IF(OR($C13="", $D13=""),"", $D13-$C13) -> 99 | F13: 40792 | G13: =IF(OR($C13="", $D13="",$F13=""),"", $F13-$D13) -> 0 | H13: 40792 | I13: =IF($H13="", "", 参数!$B$3-$H13) -> 5232 | J13: 365+ | K13: 18000
A14: KMX110818-258 | B14: 河南省安阳湖波水泥有限责任公司 | C14: 40773 | D14: 41234 | E14: =IF(OR($C14="", $D14=""),"", $D14-$C14) -> 461 | G14: =IF(OR($C14="", $D14="",$F14=""),"", $F14-$D14) | H14: 41234 | I14: =IF($H14="", "", 参数!$B$3-$H14) -> 4790 | J14: 365+ | K14: 46000
A15: KMX110905-069 | B15: 大唐华银金竹山火力发电分公司 | C15: 40791 | D15: 40881 | E15: =IF(OR($C15="", $D15=""),"", $D15-$C15) -> 90 | G15: =IF(OR($C15="", $D15="",$F15=""),"", $F15-$D15) | H15: 40881 | I15: =IF($H15="", "", 参数!$B$3-$H15) -> 5143 | J15: 365+ | K15: 5100
A16: KMX110922-076 | B16: 江西泰和南方水泥有限公司 | C16: 40808 | D16: 40898 | E16: =IF(OR($C16="", $D16=""),"", $D16-$C16) -> 90 | G16: =IF(OR($C16="", $D16="",$F16=""),"", $F16-$D16) | H16: 40898 | I16: =IF($H16="", "", 参数!$B$3-$H16) -> 5126 | J16: 365+ | K16: 5800
A17: KMX111025-047 | B17: 益阳市东方水泥有限公司 | C17: 40841 | D17: 40931 | E17: =IF(OR($C17="", $D17=""),"", $D17-$C17) -> 90 | G17: =IF(OR($C17="", $D17="",$F17=""),"", $F17-$D17) | H17: 40931 | I17: =IF($H17="", "", 参数!$B$3-$H17) -> 5093 | J17: 365+ | K17: 3400
A18: KMX111025-244 | B18: 云南红塔滇西水泥股份有限公司 | C18: 40841 | D18: 40931 | E18: =IF(OR($C18="", $D18=""),"", $D18-$C18) -> 90 | G18: =IF(OR($C18="", $D18="",$F18=""),"", $F18-$D18) | H18: 40931 | I18: =IF($H18="", "", 参数!$B$3-$H18) -> 5093 | J18: 365+ | K18: 37600
A19: KMX111101-237-《1》 | B19: 朝阳兰凌水泥有限公司 | C19: 40877 | D19: 40967 | E19: =IF(OR($C19="", $D19=""),"", $D19-$C19) -> 90 | G19: =IF(OR($C19="", $D19="",$F19=""),"", $F19-$D19) | H19: 40967 | I19: =IF($H19="", "", 参数!$B$3-$H19) -> 5057 | J19: 365+ | K19: 10000
A20: KMX120116-022 | B20: 南阳市天泰水泥有限公司 | C20: 40922 | D20: 40963 | E20: =IF(OR($C20="", $D20=""),"", $D20-$C20) -> 41 | F20: 40963 | G20: =IF(OR($C20="", $D20="",$F20=""),"", $F20-$D20) -> 0 | H20: 40963 | I20: =IF($H20="", "", 参数!$B$3-$H20) -> 5061 | J20: 365+ | K20: 2800
A21: KMX120408-061 | B21: 朝阳兰凌水泥有限公司 | C21: 41008 | D21: 41098 | E21: =IF(OR($C21="", $D21=""),"", $D21-$C21) -> 90 | G21: =IF(OR($C21="", $D21="",$F21=""),"", $F21-$D21) | H21: 41098 | I21: =IF($H21="", "", 参数!$B$3-$H21) -> 4926 | J21: 365+ | K21: 800
A22: KMX120429-071 | B22: 大同市云中有水泥限责任公司 | C22: 41028 | D22: 41118 | E22: =IF(OR($C22="", $D22=""),"", $D22-$C22) -> 90 | G22: =IF(OR($C22="", $D22="",$F22=""),"", $F22-$D22) | H22: 41118 | I22: =IF($H22="", "", 参数!$B$3-$H22) -> 4906 | J22: 365+ | K22: 36000
A23: KMX120512-085 | B23: 普定明达水泥有限公司 | C23: 41041 | D23: 41047 | E23: =IF(OR($C23="", $D23=""),"", $D23-$C23) -> 6 | F23: 41047 | G23: =IF(OR($C23="", $D23="",$F23=""),"", $F23-$D23) -> 0 | H23: 41047 | I23: =IF($H23="", "", 参数!$B$3-$H23) -> 4977 | J23: 365+ | K23: 2000
A24: KMX120621-118 | B24: 河南省安阳湖波水泥有限责任公司 | C24: 41094 | D24: 41184 | E24: =IF(OR($C24="", $D24=""),"", $D24-$C24) -> 90 | G24: =IF(OR($C24="", $D24="",$F24=""),"", $F24-$D24) | H24: 41184 | I24: =IF($H24="", "", 参数!$B$3-$H24) -> 4840 | J24: 365+ | K24: 27800
A25: KMX130224-048 | B25: 库车天山水泥有限责任公司 | C25: 41331 | D25: 41411 | E25: =IF(OR($C25="", $D25=""),"", $D25-$C25) -> 80 | F25: 41411 | G25: =IF(OR($C25="", $D25="",$F25=""),"", $F25-$D25) -> 0 | H25: 41411 | I25: =IF($H25="", "", 参数!$B$3-$H25) -> 4613 | J25: 365+ | K25: 20000
A26: KMX130224-050 | B26: 天瑞集团汝州水泥有限公司 | C26: 41335 | D26: 41591 | E26: =IF(OR($C26="", $D26=""),"", $D26-$C26) -> 256 | F26: 41591 | G26: =IF(OR($C26="", $D26="",$F26=""),"", $F26-$D26) -> 0 | H26: 41591 | I26: =IF($H26="", "", 参数!$B$3-$H26) -> 4433 | J26: 365+ | K26: 6500
A27: KMX130305-056 | B27: 湖北宜化集团楚星化工股份有限公司（更名为：湖北大江化工集团有限公司） | C27: 41338 | D27: 41410 | E27: =IF(OR($C27="", $D27=""),"", $D27-$C27) -> 72 | F27: 41410 | G27: =IF(OR($C27="", $D27="",$F27=""),"", $F27-$D27) -> 0 | H27: 41410 | I27: =IF($H27="", "", 参数!$B$3-$H27) -> 4614 | J27: 365+ | K27: 6160
A28: KMX131205-255 | B28: 重庆拉法基水泥有限公司 | C28: 41613 | D28: 41764 | E28: =IF(OR($C28="", $D28=""),"", $D28-$C28) -> 151 | F28: 41764 | G28: =IF(OR($C28="", $D28="",$F28=""),"", $F28-$D28) -> 0 | H28: 41764 | I28: =IF($H28="", "", 参数!$B$3-$H28) -> 4260 | J28: 365+ | K28: 15800
A29: KMX140111-011 | B29: 四川泸定山盛水泥有限公司 | C29: 41650 | D29: 41774 | E29: =IF(OR($C29="", $D29=""),"", $D29-$C29) -> 124 | F29: 41774 | G29: =IF(OR($C29="", $D29="",$F29=""),"", $F29-$D29) -> 0 | H29: 41774 | I29: =IF($H29="", "", 参数!$B$3-$H29) -> 4250 | J29: 365+ | K29: 6514
A30: KMX140122-028 | B30: 河南隆鑫水泥有限责任公司 | C30: 41678 | D30: 41837 | E30: =IF(OR($C30="", $D30=""),"", $D30-$C30) -> 159 | F30: 41837 | G30: =IF(OR($C30="", $D30="",$F30=""),"", $F30-$D30) -> 0 | H30: 41837 | I30: =IF($H30="", "", 参数!$B$3-$H30) -> 4187 | J30: 365+ | K30: 60000
A31: KMX140327-066 | B31: 宁波科环新型建材股份有限公司 | C31: 41725 | D31: 41801 | E31: =IF(OR($C31="", $D31=""),"", $D31-$C31) -> 76 | F31: 41801 | G31: =IF(OR($C31="", $D31="",$F31=""),"", $F31-$D31) -> 0 | H31: 41801 | I31: =IF($H31="", "", 参数!$B$3-$H31) -> 4223 | J31: 365+ | K31: 6000
A32: KMX140422-084 | B32: 登电集团水泥有限公司 | C32: 41754 | D32: 41844 | E32: =IF(OR($C32="", $D32=""),"", $D32-$C32) -> 90 | G32: =IF(OR($C32="", $D32="",$F32=""),"", $F32-$D32) | H32: 41844 | I32: =IF($H32="", "", 参数!$B$3-$H32) -> 4180 | J32: 365+ | K32: 100
A33: KMX140518-098 | B33: 四川泸定山盛水泥有限公司 | C33: 41777 | D33: 41867 | E33: =IF(OR($C33="", $D33=""),"", $D33-$C33) -> 90 | G33: =IF(OR($C33="", $D33="",$F33=""),"", $F33-$D33) | H33: 41867 | I33: =IF($H33="", "", 参数!$B$3-$H33) -> 4157 | J33: 365+ | K33: 600
A34: KMX140815-169 | B34: 四川洪雅西南水泥有限公司 | C34: 41866 | D34: 41936 | E34: =IF(OR($C34="", $D34=""),"", $D34-$C34) -> 70 | F34: 41936 | G34: =IF(OR($C34="", $D34="",$F34=""),"", $F34-$D34) -> 0 | H34: 41936 | I34: =IF($H34="", "", 参数!$B$3-$H34) -> 4088 | J34: 365+ | K34: 3660
A35: KMX141117-220 | B35: 四川泸定山盛水泥有限公司 | C35: 41960 | D35: 41961 | E35: =IF(OR($C35="", $D35=""),"", $D35-$C35) -> 1 | F35: 41961 | G35: =IF(OR($C35="", $D35="",$F35=""),"", $F35-$D35) -> 0 | H35: 41961 | I35: =IF($H35="", "", 参数!$B$3-$H35) -> 4063 | J35: 365+ | K35: 1280
A36: KMX150127-030 | B36: 台泥(怀化)水泥有限公司（原名湖南金大地材料股份有限公司） | C36: 42031 | D36: 42031 | E36: =IF(OR($C36="", $D36=""),"", $D36-$C36) -> 0 | F36: 42031 | G36: =IF(OR($C36="", $D36="",$F36=""),"", $F36-$D36) -> 0 | H36: 42031 | I36: =IF($H36="", "", 参数!$B$3-$H36) -> 3993 | J36: 365+ | K36: 4000
A37: KMX150202-034 | B37: 芒市西南水泥有限公司 | C37: 42037 | D37: 42063 | E37: =IF(OR($C37="", $D37=""),"", $D37-$C37) -> 26 | F37: 42074 | G37: =IF(OR($C37="", $D37="",$F37=""),"", $F37-$D37) -> 11 | H37: 42074 | I37: =IF($H37="", "", 参数!$B$3-$H37) -> 3950 | J37: 365+ | K37: 4800
A38: KMX150321-076-XF | B38: 湖南印山实业集团印山台水泥有限公司 | C38: 42084 | D38: 42137 | E38: =IF(OR($C38="", $D38=""),"", $D38-$C38) -> 53 | F38: 42137 | G38: =IF(OR($C38="", $D38="",$F38=""),"", $F38-$D38) -> 0 | H38: 42137 | I38: =IF($H38="", "", 参数!$B$3-$H38) -> 3887 | J38: 365+ | K38: 14800
A39: KMX150602-118-CL | B39: 莱芜市双盛机械制造有限公司 | C39: 42157 | D39: 42242 | E39: =IF(OR($C39="", $D39=""),"", $D39-$C39) -> 85 | F39: 42235 | G39: =IF(OR($C39="", $D39="",$F39=""),"", $F39-$D39) -> -7 | H39: 42235 | I39: =IF($H39="", "", 参数!$B$3-$H39) -> 3789 | J39: 365+ | K39: 16000
A40: KMX150901-167-XF | B40: 锦州三鸽水泥制造有限公司 | C40: 42248 | D40: 42260 | E40: =IF(OR($C40="", $D40=""),"", $D40-$C40) -> 12 | F40: 42390 | G40: =IF(OR($C40="", $D40="",$F40=""),"", $F40-$D40) -> 130 | H40: 42390 | I40: =IF($H40="", "", 参数!$B$3-$H40) -> 3634 | J40: 365+ | K40: 100000
...
